Workbook

Sheet Read me
A1: Valuation date | B1: 18 September 2026; USD millions except per-share data and explicit percentages.
A2: Inputs | B2: Blue cells are analyst assumptions. Financial facts are linked by accession and tag in Financial audit.
A3: Historical TTM | B3: FY2025 + H1 2026 - H1 2025. Reported cutoffs create a 371-day trailing period. Interim shares weighted by day count.
A4: Value-added sales | B4: 2021 and 2022 use the comparable recast figures disclosed in the FY2023 10-K. These differ from originally published VA sales.
A5: FCF | B5: Operating cash flow less PPE spending AND separately reported mine-development spending. Excludes acquisitions. Annual mining outflows: zero separately reported in 2021-22, $9.326m in 2023, $12.159m in 2024, $26.288m in 2025.
A6: Adjusted EBITDA | B6: Company-reported non-GAAP metric; 2021-22 from 2023 investor deck; 2023 from Q4 deck; 2024-25 from FY2025 release; TTM 237.2 from Q2 2026 slide 16.
A7: DCF periods | B7: Five prospective 12-month years ending September 18, 2027-2031; year-end discounting; terminal reinvestment reset to terminal growth.
A8: Balance-sheet bridge | B8: Debt principal + estimated finance leases + retirement liability - cash. Operating lease expense remains in operating forecasts.
A9: Share count | B9: 20.834m latest balance-sheet common shares for market cap; 21.15m prospective diluted shares for DCF and earnings scenarios.
A10: Capital spending | B10: Q2 deck: $75m PPE plus $25m mine development. Q2 10-Q prose says $100m PPE. Disclosure discrepancy retained in report; $100m total base anchor and $125m downside cash sensitivity.
A11: Model status | B11: Formulas include cached numerical values verified against Python; formulas recalculate when changed in Excel. Scenario and DCF assumptions are analyst estimates.
A12: Options | B12: Saved real Cboe quotes; no strategies or calculated Greeks because liquidity screen failed. Vendor Greeks remain identified as vendor values.
... A14: Rebuild | B14: Run python MTRN/code/run_analysis.py from repository root after installing MTRN/code/requirements.txt.

Sheet Historical
A1: period | B1: start | C1: end | D1: revenue | E1: gross_profit | F1: operating_income | G1: net_income | H1: tax | I1: interest | J1: cfo | K1: ppe_capex | L1: mine_capex | M1: da | N1: amortization | O1: sbc | P1: rnd | Q1: dividends | R1: repurchases | S1: diluted_shares | T1: basic_shares | U1: eps | V1: cash | W1: assets | X1: current_assets | Y1: liabilities | Z1: current_liabilities | AA1: equity | AB1: debt_current | AC1: debt_noncurrent | AD1: debt_face | AE1: goodwill | AF1: intangibles | AG1: receivables | AH1: inventory | AI1: payables | AJ1: shares_issued | AK1: treasury_shares | AL1: finance_lease_current | AM1: finance_lease_noncurrent | AN1: va_sales | AO1: adjusted_ebitda | AP1: capex | AQ1: fcf | AR1: debt | AS1: net_debt | AT1: ebitda | AU1: operating_ebitda | AV1: gross_margin | AW1: gross_margin_va | AX1: operating_margin | AY1: net_margin | AZ1: fcf_margin | BA1: sbc_revenue | BB1: current_ratio | BC1: debt_equity | BD1: actual_shares | BE1: interest_cover | BF1: fcf_per_share | BG1: fcf_conversion | BH1: adjusted_ebitda_margin_va
A2: 2021 | B2: 2021-01-01 | C2: 2021-12-31 | D2: 1510.644 | E2: 283.762 | F2: 77.111 | G2: 72.474 | H2: 4.851 | I2: 4.901 | J2: 90.241 | K2: 102.91 | L2: 0 | M2: 44.137 | N2: 5.973 | O2: 6.517 | P2: 26.575 | Q2: 9.697 | R2: 0 | S2: 20.689 | T2: 20.422 | U2: 3.5 | V2: 14.462 | W2: 1607.479 | X2: 627.252 | Y2: 887.039 | Z2: 204.509 | AA2: 720.44 | AB2: 15.359 | AC2: 434.388 | AD2: 454.548 | AE2: 318.62 | AF2: 156.736 | AG2: 213.819 | AH2: 361.115 | AI2: 86.243 | AJ2: 27.148 | AK2: 6.7 | AL2: 2.8 | AM2: 16.327 | AN2: 829.572 | AO2: 143.6 | AP2: =K2+L2 -> 102.91 | AQ2: =J2-AP2 -> -12.669 | AR2: =AB2+AC2 -> 449.747 | AS2: =AR2-V2 -> 435.285 | AT2: =G2+H2+I2+M2 -> 126.363 | AU2: =F2+M2 -> 121.248 | AV2: =E2/D2 -> 0.18784174 | AW2: =E2/AN2 -> 0.34205831 | AX2: =F2/D2 -> 0.051045117 | AY2: =G2/D2 -> 0.047975565 | AZ2: =AQ2/D2 -> -0.0083864895 | BA2: =O2/D2 -> 0.0043140541 | BB2: =X2/Z2 -> 3.067112 | BC2: =AR2/AA2 -> 0.62426711 | BD2: =AJ2-AK2 -> 20.448 | BE2: =F2/I2 -> 15.733728 | BF2: =AQ2/S2 -> -0.61235439 | BG2: =AQ2/G2 -> -0.17480752 | BH2: =AO2/AN2 -> 0.17310131
A3: 2022 | B3: 2022-01-01 | C3: 2022-12-31 | D3: 1757.109 | E3: 343.88 | F3: 119.755 | G3: 85.99 | H3: 17.11 | I3: 21.905 | J3: 115.958 | K3: 77.608 | L3: 0 | M3: 53.436 | N3: 12.4 | O3: 8.813 | P3: 28.977 | Q3: 10.16 | R3: 0 | S3: 20.76 | T3: 20.511 | U3: 4.14 | V3: 13.101 | W3: 1691.979 | X3: 690.448 | Y3: 891.989 | Z3: 238.964 | AA3: 799.99 | AB3: 21.105 | AC3: 410.876 | AD3: 435.791 | AE3: 319.498 | AF3: 139.601 | AG3: 215.211 | AH3: 423.08 | AI3: 107.899 | AJ3: 27.148 | AK3: 6.605 | AL3: 1.485 | AM3: 13.876 | AN3: 1114.411 | AO3: 196 | AP3: =K3+L3 -> 77.608 | AQ3: =J3-AP3 -> 38.35 | AR3: =AB3+AC3 -> 431.981 | AS3: =AR3-V3 -> 418.88 | AT3: =G3+H3+I3+M3 -> 178.441 | AU3: =F3+M3 -> 173.191 | AV3: =E3/D3 -> 0.19570784 | AW3: =E3/AN3 -> 0.30857556 | AX3: =F3/D3 -> 0.068154565 | AY3: =G3/D3 -> 0.048938341 | AZ3: =AQ3/D3 -> 0.021825624 | BA3: =O3/D3 -> 0.0050156251 | BB3: =X3/Z3 -> 2.889339 | BC3: =AR3/AA3 -> 0.539983 | BD3: =AJ3-AK3 -> 20.543 | BE3: =F3/I3 -> 5.4670167 | BF3: =AQ3/S3 -> 1.8473025 | BG3: =AQ3/G3 -> 0.44598209 | BH3: =AO3/AN3 -> 0.17587766
A4: 2023 | B4: 2023-01-01 | C4: 2023-12-31 | D4: 1665.187 | E4: 349.042 | F4: 136.444 | G4: 95.702 | H4: 12.129 | I4: 31.323 | J4: 144.414 | K4: 110.55 | L4: 9.326 | M4: 61.644 | N4: 12.876 | O4: 10.092 | P4: 27.54 | Q4: 10.621 | R4: 0 | S4: 20.911 | T4: 20.619 | U4: 4.58 | V4: 13.294 | W4: 1762.726 | X4: 709.382 | Y4: 877.673 | Z4: 254.995 | AA4: 885.053 | AB4: 38.597 | AC4: 387.576 | AD4: 428.993 | AE4: 320.873 | AF4: 133.571 | AG4: 192.747 | AH4: 441.597 | AI4: 125.663 | AJ4: 27.148 | AK4: 6.502 | AL4: 0.626 | AM4: 13.744 | AN4: 1127.071 | AO4: 217.7 | AP4: =K4+L4 -> 119.876 | AQ4: =J4-AP4 -> 24.538 | AR4: =AB4+AC4 -> 426.173 | AS4: =AR4-V4 -> 412.879 | AT4: =G4+H4+I4+M4 -> 200.798 | AU4: =F4+M4 -> 198.088 | AV4: =E4/D4 -> 0.20961129 | AW4: =E4/AN4 -> 0.30968945 | AX4: =F4/D4 -> 0.081939146 | AY4: =G4/D4 -> 0.057472224 | AZ4: =AQ4/D4 -> 0.014735883 | BA4: =O4/D4 -> 0.0060605806 | BB4: =X4/Z4 -> 2.7819447 | BC4: =AR4/AA4 -> 0.48152258 | BD4: =AJ4-AK4 -> 20.646 | BE4: =F4/I4 -> 4.3560323 | BF4: =AQ4/S4 -> 1.1734494 | BG4: =AQ4/G4 -> 0.25640008 | BH4: =AO4/AN4 -> 0.19315553
A5: 2024 | B5: 2024-01-01 | C5: 2024-12-31 | D5: 1684.739 | E5: 325.985 | F5: 47.223 | G5: 5.888 | H5: 9.014 | I5: 34.764 | J5: 87.817 | K5: 68.649 | L5: 12.159 | M5: 68.676 | N5: 12.134 | O5: 10.56 | P5: 29.028 | Q5: 11.087 | R5: 0 | S5: 20.928 | T5: 20.732 | U5: 0.28 | V5: 16.713 | W5: 1697.632 | X5: 724.224 | Y5: 828.751 | Z5: 226.734 | AA5: 868.881 | AB5: 34.274 | AC5: 407.734 | AD5: 443.899 | AE5: 263.738 | AF5: 109.312 | AG5: 193.793 | AH5: 441.299 | AI5: 105.901 | AJ5: 27.148 | AK5: 6.384 | AL5: 0.552 | AM5: 12.404 | AN5: 1097.577 | AO5: 221.2 | AP5: =K5+L5 -> 80.808 | AQ5: =J5-AP5 -> 7.009 | AR5: =AB5+AC5 -> 442.008 | AS5: =AR5-V5 -> 425.295 | AT5: =G5+H5+I5+M5 -> 118.342 | AU5: =F5+M5 -> 115.899 | AV5: =E5/D5 -> 0.19349288 | AW5: =E5/AN5 -> 0.29700422 | AX5: =F5/D5 -> 0.028029861 | AY5: =G5/D5 -> 0.0034949034 | AZ5: =AQ5/D5 -> 0.0041602883 | BA5: =O5/D5 -> 0.0062680332 | BB5: =X5/Z5 -> 3.194157 | BC5: =AR5/AA5 -> 0.50870948 | BD5: =AJ5-AK5 -> 20.764 | BE5: =F5/I5 -> 1.358388 | BF5: =AQ5/S5 -> 0.33491017 | BG5: =AQ5/G5 -> 1.1903872 | BH5: =AO5/AN5 -> 0.20153484
A6: 2025 | B6: 2025-01-01 | C6: 2025-12-31 | D6: 1786.55 | E6: 308.626 | F6: 109.796 | G6: 74.823 | H6: 6.718 | I6: 30.692 | J6: 103.243 | K6: 53.279 | L6: 26.288 | M6: 69.074 | N6: 11.013 | O6: 10.925 | P6: 25.941 | Q6: 11.51 | R6: 7.843 | S6: 20.912 | T6: 20.755 | U6: 3.58 | V6: 13.681 | W6: 1802.801 | X6: 789.52 | Y6: 859.524 | Z6: 253.583 | AA6: 943.277 | AB6: 22.445 | AC6: 436.348 | AD6: 460.642 | AE6: 280.657 | AF6: 105.874 | AG6: 222.916 | AH6: 461.231 | AI6: 148.642 | AJ6: 27.148 | AK6: 6.413 | AL6: 0.622 | AM6: 13.384 | AN6: 1046.194 | AO6: 217 | AP6: =K6+L6 -> 79.567 | AQ6: =J6-AP6 -> 23.676 | AR6: =AB6+AC6 -> 458.793 | AS6: =AR6-V6 -> 445.112 | AT6: =G6+H6+I6+M6 -> 181.307 | AU6: =F6+M6 -> 178.87 | AV6: =E6/D6 -> 0.17274971 | AW6: =E6/AN6 -> 0.29499882 | AX6: =F6/D6 -> 0.061456998 | AY6: =G6/D6 -> 0.04188128 | AZ6: =AQ6/D6 -> 0.013252358 | BA6: =O6/D6 -> 0.0061151381 | BB6: =X6/Z6 -> 3.1134579 | BC6: =AR6/AA6 -> 0.48638205 | BD6: =AJ6-AK6 -> 20.735 | BE6: =F6/I6 -> 3.5773491 | BF6: =AQ6/S6 -> 1.1321729 | BG6: =AQ6/G6 -> 0.31642677 | BH6: =AO6/AN6 -> 0.20741851
A7: H1 2025 | B7: 2025-01-01 | C7: 2025-06-27 | D7: 851.988 | E7: 158.837 | F7: 64.014 | G7: 42.838 | H7: 7.262 | I7: 15.147 | J7: 65.442 | K7: 25.003 | L7: 10.175 | M7: 34.047 | N7: 5.695 | O7: 5.437 | P7: 12.918 | Q7: 5.705 | R7: 7.843 | S7: 20.874 | T7: 20.779 | U7: 2.05 | V7: 12.591 | W7: 1741.207 | X7: 735.113 | Y7: 830.562 | Z7: 231.901 | AA7: 910.645 | AB7: 19.88 | AC7: 405.697 | AD7: 427.604 | AE7: 265.695 | AF7: 107.627 | AG7: 198.377 | AH7: 444.637 | AI7: 132.338 | AJ7: 27.148 | AK7: 6.421 | AL7: Data unavailable | AM7: 13.612 | AN7: 528.316 | AO7: 104.5 | AP7: =K7+L7 -> 35.178 | AQ7: =J7-AP7 -> 30.264 | AR7: =AB7+AC7 -> 425.577 | AS7: =AR7-V7 -> 412.986 | AT7: =G7+H7+I7+M7 -> 99.294 | AU7: =F7+M7 -> 98.061 | AV7: =E7/D7 -> 0.18643103 | AW7: =E7/AN7 -> 0.30064772 | AX7: =F7/D7 -> 0.075134861 | AY7: =G7/D7 -> 0.050280051 | AZ7: =AQ7/D7 -> 0.035521627 | BA7: =O7/D7 -> 0.0063815453 | BB7: =X7/Z7 -> 3.1699432 | BC7: =AR7/AA7 -> 0.46733579 | BD7: =AJ7-AK7 -> 20.727 | BE7: =F7/I7 -> 4.2261834 | BF7: =AQ7/S7 -> 1.4498419 | BG7: =AQ7/G7 -> 0.70647556 | BH7: =AO7/AN7 -> 0.19779829
A8: H1 2026 | B8: 2026-01-01 | C8: 2026-07-03 | D8: 1163.73 | E8: 186.177 | F8: 79.886 | G8: 58.132 | H8: 7.277 | I8: 15.104 | J8: 70.506 | K8: 29.818 | L8: 1.661 | M8: 37.614 | N8: 5.205 | O8: 8.635 | P8: 12.719 | Q8: 5.926 | R8: 0 | S8: 21.048 | T8: 20.791 | U8: 2.76 | V8: 19.987 | W8: 1870.697 | X8: 869.956 | Y8: 875.83 | Z8: 295.792 | AA8: 994.867 | AB8: 17.478 | AC8: 423.21 | AD8: 442.332 | AE8: 280.186 | AF8: 99.893 | AG8: 260.779 | AH8: 487.444 | AI8: 192.292 | AJ8: 27.148 | AK8: 6.314 | AL8: Data unavailable | AM8: 12.671 | AN8: 569.978 | AO8: 124.8 | AP8: =K8+L8 -> 31.479 | AQ8: =J8-AP8 -> 39.027 | AR8: =AB8+AC8 -> 440.688 | AS8: =AR8-V8 -> 420.701 | AT8: =G8+H8+I8+M8 -> 118.127 | AU8: =F8+M8 -> 117.5 | AV8: =E8/D8 -> 0.15998299 | AW8: =E8/AN8 -> 0.32663892 | AX8: =F8/D8 -> 0.068646507 | AY8: =G8/D8 -> 0.049953168 | AZ8: =AQ8/D8 -> 0.03353613 | BA8: =O8/D8 -> 0.007420106 | BB8: =X8/Z8 -> 2.9411073 | BC8: =AR8/AA8 -> 0.44296172 | BD8: =AJ8-AK8 -> 20.834 | BE8: =F8/I8 -> 5.2890625 | BF8: =AQ8/S8 -> 1.8541904 | BG8: =AQ8/G8 -> 0.67135141 | BH8: =AO8/AN8 -> 0.21895582
A9: TTM | B9: 2025-06-28 | C9: 2026-07-03 | D9: 2098.292 | E9: 335.966 | F9: 125.668 | G9: 90.117 | H9: 6.733 | I9: 30.649 | J9: 108.307 | K9: 58.094 | L9: 17.774 | M9: 72.641 | N9: 10.523 | O9: 14.123 | P9: 25.742 | Q9: 11.731 | R9: 0 | S9: 20.997682 | T9: 20.76134 | U9: 4.29 | V9: 19.987 | W9: 1870.697 | X9: 869.956 | Y9: 875.83 | Z9: 295.792 | AA9: 994.867 | AB9: 17.478 | AC9: 423.21 | AD9: 442.332 | AE9: 280.186 | AF9: 99.893 | AG9: 260.779 | AH9: 487.444 | AI9: 192.292 | AJ9: 27.148 | AK9: 6.314 | AL9: Data unavailable | AM9: 12.671 | AN9: 1087.856 | AO9: 237.2 | AP9: =K9+L9 -> 75.868 | AQ9: =J9-AP9 -> 32.439 | AR9: =AB9+AC9 -> 440.688 | AS9: =AR9-V9 -> 420.701 | AT9: =G9+H9+I9+M9 -> 200.14 | AU9: =F9+M9 -> 198.309 | AV9: =E9/D9 -> 0.16011404 | AW9: =E9/AN9 -> 0.30883315 | AX9: =F9/D9 -> 0.059890616 | AY9: =G9/D9 -> 0.042947788 | AZ9: =AQ9/D9 -> 0.015459717 | BA9: =O9/D9 -> 0.0067307124 | BB9: =X9/Z9 -> 2.9411073 | BC9: =AR9/AA9 -> 0.44296172 | BD9: =AJ9-AK9 -> 20.834 | BE9: =F9/I9 -> 4.1002317 | BF9: =AQ9/S9 -> 1.5448848 | BG9: =AQ9/G9 -> 0.35996538 | BH9: =AO9/AN9 -> 0.21804356

Sheet DCF Downside
A1: Prospective DCF — Downside
A2: FY2026 VA anchor | B2: 1203.1231
A4: Prospective year | B4: 1 | C4: 2 | D4: 3 | E4: 4 | F4: 5
A5: VA sales growth | B5: 0 | C5: 0.03 | D5: 0.04 | E5: 0.04 | F5: 0.04
A6: Value-added sales | B6: =$B$2*(1+B5) -> 1203.1231 | C6: =B6*(1+C5) -> 1239.2168 | D6: =C6*(1+D5) -> 1288.7855 | E6: =D6*(1+E5) -> 1340.3369 | F6: =E6*(1+F5) -> 1393.9504
A7: EBITDA / VA sales | B7: 0.205 | C7: 0.21 | D7: 0.215 | E7: 0.22 | F7: 0.22
A8: EBITDA | B8: =B6*B7 -> 246.64024 | C8: =C6*C7 -> 260.23553 | D8: =D6*D7 -> 277.08887 | E8: =E6*E7 -> 294.87411 | F8: =F6*F7 -> 306.66908
A9: D&A / VA sales | B9: 0.067 | C9: 0.067 | D9: 0.067 | E9: 0.067 | F9: 0.067
A10: D&A | B10: =B6*B9 -> 80.609248 | C10: =C6*C9 -> 83.027525 | D10: =D6*D9 -> 86.348626 | E10: =E6*E9 -> 89.802571 | F10: =F6*F9 -> 93.394674
A11: EBIT | B11: =B8-B10 -> 166.03099 | C11: =C8-C10 -> 177.208 | D11: =D8-D10 -> 190.74025 | E11: =E8-E10 -> 205.07154 | F11: =F8-F10 -> 213.2744
A12: Tax rate | B12: 0.18 | C12: 0.19 | D12: 0.2 | E12: 0.21 | F12: 0.21
A13: NOPAT | B13: =B11*(1-B12) -> 136.14541 | C13: =C11*(1-C12) -> 143.53848 | D13: =D11*(1-D12) -> 152.5922 | E13: =E11*(1-E12) -> 162.00652 | F13: =F11*(1-F12) -> 168.48678
A14: Capex / VA sales | B14: 0.085 | C14: 0.085 | D14: 0.085 | E14: 0.085 | F14: 0.085
A15: Capex incl. mining | B15: =B6*B14 -> 102.26546 | C15: =C6*C14 -> 105.33343 | D15: =D6*D14 -> 109.54676 | E15: =E6*E14 -> 113.92864 | F15: =F6*F14 -> 118.48578
A16: NWC / incremental VA | B16: 0.35 | C16: 0.35 | D16: 0.35 | E16: 0.35 | F16: 0.35
A17: Change in NWC | B17: =(B6-$B$2)*B16 -> 0 | C17: =(C6-B6)*C16 -> 12.632793 | D17: =(D6-C6)*D16 -> 17.349035 | E17: =(E6-D6)*E16 -> 18.042997 | F17: =(F6-E6)*F16 -> 18.764716
A18: FCFF | B18: =B13+B10-B15-B17 -> 114.48919 | C18: =C13+C10-C15-C17 -> 108.59979 | D18: =D13+D10-D15-D17 -> 112.04503 | E18: =E13+E10-E15-E17 -> 119.83746 | F18: =F13+F10-F15-F17 -> 124.63096
A19: Present value of FCFF | B19: =B18/(1+$B$21)^B4 -> 102.22249 | C19: =C18/(1+$B$21)^C4 -> 86.575085 | D19: =D18/(1+$B$21)^D4 -> 79.751436 | E19: =E18/(1+$B$21)^E4 -> 76.158871 | F19: =F18/(1+$B$21)^F4 -> 70.718952
A21: WACC | B21: 0.12
A22: Terminal growth | B22: 0.02
A23: Diluted shares | B23: 21.15
A24: Net claims | B24: 458.8
A26: Terminal VA sales | B26: =F6*(1+B22) -> 1421.8294
A27: Terminal EBITDA | B27: =B26*F7 -> 312.80246
A28: Terminal D&A | B28: =B26*F9 -> 95.262568
A29: Terminal EBIT | B29: =B27-B28 -> 217.53989
A30: Terminal capex | B30: =B26*F14 -> 120.8555
A31: Terminal change NWC | B31: =F6*B22*F16 -> 9.7576525
A32: Terminal FCFF | B32: =B29*(1-F12)+B28-B30-B31 -> 136.50593
A33: Terminal value | B33: =B32/(B21-B22) -> 1365.0593
A34: PV of terminal value | B34: =B33/(1+B21)^F4 -> 774.57133
A35: PV explicit cash flows | B35: =SUM(B19:F19) -> 415.42684
A36: Enterprise value | B36: =B34+B35 -> 1189.9982
A37: Equity value | B37: =B36-B24 -> 731.19817
A38: Per-share value | B38: =B37/B23 -> 34.572018
A39: Terminal share of EV | B39: =B34/B36 -> 0.65090128
A41: Terminal capex and working capital are recalculated at terminal growth; SBC remains an expense.

Sheet DCF Base
A1: Prospective DCF — Base
A2: FY2026 VA anchor | B2: 1203.1231
A4: Prospective year | B4: 1 | C4: 2 | D4: 3 | E4: 4 | F4: 5
A5: VA sales growth | B5: 0.075 | C5: 0.12 | D5: 0.1 | E5: 0.08 | F5: 0.06
A6: Value-added sales | B6: =$B$2*(1+B5) -> 1293.3573 | C6: =B6*(1+C5) -> 1448.5602 | D6: =C6*(1+D5) -> 1593.4162 | E6: =D6*(1+E5) -> 1720.8895 | F6: =E6*(1+F5) -> 1824.1429
A7: EBITDA / VA sales | B7: 0.235 | C7: 0.24 | D7: 0.245 | E7: 0.25 | F7: 0.25
A8: EBITDA | B8: =B6*B7 -> 303.93897 | C8: =C6*C7 -> 347.65445 | D8: =D6*D7 -> 390.38698 | E8: =E6*E7 -> 430.22238 | F8: =F6*F7 -> 456.03573
A9: D&A / VA sales | B9: 0.062 | C9: 0.062 | D9: 0.062 | E9: 0.062 | F9: 0.062
A10: D&A | B10: =B6*B9 -> 80.188155 | C10: =C6*C9 -> 89.810733 | D10: =D6*D9 -> 98.791806 | E10: =E6*E9 -> 106.69515 | F10: =F6*F9 -> 113.09686
A11: EBIT | B11: =B8-B10 -> 223.75082 | C11: =C8-C10 -> 257.84372 | D11: =D8-D10 -> 291.59517 | E11: =E8-E10 -> 323.52723 | F11: =F8-F10 -> 342.93887
A12: Tax rate | B12: 0.17 | C12: 0.18 | D12: 0.19 | E12: 0.2 | F12: 0.2
A13: NOPAT | B13: =B11*(1-B12) -> 185.71318 | C13: =C11*(1-C12) -> 211.43185 | D13: =D11*(1-D12) -> 236.19209 | E13: =E11*(1-E12) -> 258.82179 | F13: =F11*(1-F12) -> 274.35109
A14: Capex / VA sales | B14: 0.078 | C14: 0.078 | D14: 0.078 | E14: 0.078 | F14: 0.078
A15: Capex incl. mining | B15: =B6*B14 -> 100.88187 | C15: =C6*C14 -> 112.9877 | D15: =D6*D14 -> 124.28647 | E15: =E6*E14 -> 134.22938 | F15: =F6*F14 -> 142.28315
A16: NWC / incremental VA | B16: 0.3 | C16: 0.3 | D16: 0.3 | E16: 0.3 | F16: 0.3
A17: Change in NWC | B17: =(B6-$B$2)*B16 -> 27.07027 | C17: =(C6-B6)*C16 -> 46.560864 | D17: =(D6-C6)*D16 -> 43.456806 | E17: =(E6-D6)*E16 -> 38.24199 | F17: =(F6-E6)*F16 -> 30.976012
A18: FCFF | B18: =B13+B10-B15-B17 -> 137.94919 | C18: =C13+C10-C15-C17 -> 141.69402 | D18: =D13+D10-D15-D17 -> 167.24062 | E18: =E13+E10-E15-E17 -> 193.04556 | F18: =F13+F10-F15-F17 -> 214.18879
A19: Present value of FCFF | B19: =B18/(1+$B$21)^B4 -> 124.8409 | C19: =C18/(1+$B$21)^C4 -> 116.04514 | D19: =D18/(1+$B$21)^D4 -> 123.9524 | E19: =E18/(1+$B$21)^E4 -> 129.48239 | F19: =F18/(1+$B$21)^F4 -> 130.01257
A21: WACC | B21: 0.105
A22: Terminal growth | B22: 0.03
A23: Diluted shares | B23: 21.15
A24: Net claims | B24: 458.8
A26: Terminal VA sales | B26: =F6*(1+B22) -> 1878.8672
A27: Terminal EBITDA | B27: =B26*F7 -> 469.7168
A28: Terminal D&A | B28: =B26*F9 -> 116.48977
A29: Terminal EBIT | B29: =B27-B28 -> 353.22703
A30: Terminal capex | B30: =B26*F14 -> 146.55164
A31: Terminal change NWC | B31: =F6*B22*F16 -> 16.417286
A32: Terminal FCFF | B32: =B29*(1-F12)+B28-B30-B31 -> 236.10246
A33: Terminal value | B33: =B32/(B21-B22) -> 3148.0329
A34: PV of terminal value | B34: =B33/(1+B21)^F4 -> 1910.8556
A35: PV explicit cash flows | B35: =SUM(B19:F19) -> 624.33341
A36: Enterprise value | B36: =B34+B35 -> 2535.189
A37: Equity value | B37: =B36-B24 -> 2076.389
A38: Per-share value | B38: =B37/B23 -> 98.174421
A39: Terminal share of EV | B39: =B34/B36 -> 0.75373299
A41: Terminal capex and working capital are recalculated at terminal growth; SBC remains an expense.

Sheet DCF Upside
A1: Prospective DCF — Upside
A2: FY2026 VA anchor | B2: 1203.1231
A4: Prospective year | B4: 1 | C4: 2 | D4: 3 | E4: 4 | F4: 5
A5: VA sales growth | B5: 0.15 | C5: 0.2 | D5: 0.18 | E5: 0.15 | F5: 0.12
A6: Value-added sales | B6: =$B$2*(1+B5) -> 1383.5916 | C6: =B6*(1+C5) -> 1660.3099 | D6: =C6*(1+D5) -> 1959.1657 | E6: =D6*(1+E5) -> 2253.0405 | F6: =E6*(1+F5) -> 2523.4054
A7: EBITDA / VA sales | B7: 0.25 | C7: 0.265 | D7: 0.275 | E7: 0.28 | F7: 0.28
A8: EBITDA | B8: =B6*B7 -> 345.89789 | C8: =C6*C7 -> 439.98212 | D8: =D6*D7 -> 538.77056 | E8: =E6*E7 -> 630.85134 | F8: =F6*F7 -> 706.5535
A9: D&A / VA sales | B9: 0.06 | C9: 0.06 | D9: 0.06 | E9: 0.06 | F9: 0.06
A10: D&A | B10: =B6*B9 -> 83.015494 | C10: =C6*C9 -> 99.618593 | D10: =D6*D9 -> 117.54994 | E10: =E6*E9 -> 135.18243 | F10: =F6*F9 -> 151.40432
A11: EBIT | B11: =B8-B10 -> 262.8824 | C11: =C8-C10 -> 340.36352 | D11: =D8-D10 -> 421.22062 | E11: =E8-E10 -> 495.66891 | F11: =F8-F10 -> 555.14918
A12: Tax rate | B12: 0.16 | C12: 0.17 | D12: 0.18 | E12: 0.18 | F12: 0.18
A13: NOPAT | B13: =B11*(1-B12) -> 220.82121 | C13: =C11*(1-C12) -> 282.50173 | D13: =D11*(1-D12) -> 345.40091 | E13: =E11*(1-E12) -> 406.44851 | F13: =F11*(1-F12) -> 455.22233
A14: Capex / VA sales | B14: 0.08 | C14: 0.08 | D14: 0.08 | E14: 0.08 | F14: 0.08
A15: Capex incl. mining | B15: =B6*B14 -> 110.68733 | C15: =C6*C14 -> 132.82479 | D15: =D6*D14 -> 156.73325 | E15: =E6*E14 -> 180.24324 | F15: =F6*F14 -> 201.87243
A16: NWC / incremental VA | B16: 0.28 | C16: 0.28 | D16: 0.28 | E16: 0.28 | F16: 0.28
A17: Change in NWC | B17: =(B6-$B$2)*B16 -> 50.53117 | C17: =(C6-B6)*C16 -> 77.481128 | D17: =(D6-C6)*D16 -> 83.679618 | E17: =(E6-D6)*E16 -> 82.284958 | F17: =(F6-E6)*F16 -> 75.702161
A18: FCFF | B18: =B13+B10-B15-B17 -> 142.61821 | C18: =C13+C10-C15-C17 -> 171.8144 | D18: =D13+D10-D15-D17 -> 222.53797 | E18: =E13+E10-E15-E17 -> 279.10274 | F18: =F13+F10-F15-F17 -> 329.05206
A19: Present value of FCFF | B19: =B18/(1+$B$21)^B4 -> 130.24494 | C19: =C18/(1+$B$21)^C4 -> 143.29509 | D19: =D18/(1+$B$21)^D4 -> 169.49691 | E19: =E18/(1+$B$21)^E4 -> 194.13669 | F19: =F18/(1+$B$21)^F4 -> 209.02297
A21: WACC | B21: 0.095
A22: Terminal growth | B22: 0.035
A23: Diluted shares | B23: 21.15
A24: Net claims | B24: 458.8
A26: Terminal VA sales | B26: =F6*(1+B22) -> 2611.7246
A27: Terminal EBITDA | B27: =B26*F7 -> 731.28287
A28: Terminal D&A | B28: =B26*F9 -> 156.70347
A29: Terminal EBIT | B29: =B27-B28 -> 574.5794
A30: Terminal capex | B30: =B26*F14 -> 208.93796
A31: Terminal change NWC | B31: =F6*B22*F16 -> 24.729373
A32: Terminal FCFF | B32: =B29*(1-F12)+B28-B30-B31 -> 394.19125
A33: Terminal value | B33: =B32/(B21-B22) -> 6569.8541
A34: PV of terminal value | B34: =B33/(1+B21)^F4 -> 4173.3531
A35: PV explicit cash flows | B35: =SUM(B19:F19) -> 846.1966
A36: Enterprise value | B36: =B34+B35 -> 5019.5497
A37: Equity value | B37: =B36-B24 -> 4560.7497
A38: Per-share value | B38: =B37/B23 -> 215.63828
A39: Terminal share of EV | B39: =B34/B36 -> 0.83141982
A41: Terminal capex and working capital are recalculated at terminal growth; SBC remains an expense.

Sheet DCF summary
A1: scenario | B1: pv_explicit | C1: pv_terminal | D1: enterprise | E1: equity | F1: per_share | G1: terminal_share | H1: terminal_fcff | I1: wacc | J1: g | K1: return_vs_price | L1: initial_va
A2: Downside | B2: ='DCF Downside'!B35 -> 415.42684 | C2: ='DCF Downside'!B34 -> 774.57133 | D2: ='DCF Downside'!B36 -> 1189.9982 | E2: ='DCF Downside'!B37 -> 731.19817 | F2: ='DCF Downside'!B38 -> 34.572018 | G2: 0.65090128 | H2: 136.50593 | I2: 0.12 | J2: 0.02 | K2: -0.8625531 | L2: 1203.1231
A3: Base | B3: ='DCF Base'!B35 -> 624.33341 | C3: ='DCF Base'!B34 -> 1910.8556 | D3: ='DCF Base'!B36 -> 2535.189 | E3: ='DCF Base'!B37 -> 2076.389 | F3: ='DCF Base'!B38 -> 98.174421 | G3: 0.75373299 | H3: 236.10246 | I3: 0.105 | J3: 0.03 | K3: -0.60969101 | L3: 1203.1231
A4: Upside | B4: ='DCF Upside'!B35 -> 846.1966 | C4: ='DCF Upside'!B34 -> 4173.3531 | D4: ='DCF Upside'!B36 -> 5019.5497 | E4: ='DCF Upside'!B37 -> 4560.7497 | F4: ='DCF Upside'!B38 -> 215.63828 | G4: 0.83141982 | H4: 394.19125 | I4: 0.095 | J4: 0.035 | K4: -0.14269358 | L4: 1203.1231

Sheet Sensitivity
A1: WACC / terminal g | B1: 0.02 | C1: 0.025 | D1: 0.03 | E1: 0.035 | F1: 0.04
A2: 0.085 | B2: =('DCF Base'!B18/(1+$A2)^1+'DCF Base'!C18/(1+$A2)^2+'DCF Base'!D18/(1+$A2)^3+'DCF Base'!E18/(1+$A2)^4+'DCF Base'!F18/(1+$A2)^5+('DCF Base'!F6*(1+B$1)*(('DCF Base'!F7-'DCF Base'!F9)*(1-'DCF Base'!F12)+'DCF Base'!F9-'DCF Base'!F14)-'DCF Base'!F6*B$1*'DCF Base'!F16)/($A2-B$1)/(1+$A2)^5-'DCF Base'!B24)/'DCF Base'!B23 -> 125.19918 | C2: =('DCF Base'!B18/(1+$A2)^1+'DCF Base'!C18/(1+$A2)^2+'DCF Base'!D18/(1+$A2)^3+'DCF Base'!E18/(1+$A2)^4+'DCF Base'!F18/(1+$A2)^5+('DCF Base'!F6*(1+C$1)*(('DCF Base'!F7-'DCF Base'!F9)*(1-'DCF Base'!F12)+'DCF Base'!F9-'DCF Base'!F14)-'DCF Base'!F6*C$1*'DCF Base'!F16)/($A2-C$1)/(1+$A2)^5-'DCF Base'!B24)/'DCF Base'!B23 -> 134.04743 | D2: =('DCF Base'!B18/(1+$A2)^1+'DCF Base'!C18/(1+$A2)^2+'DCF Base'!D18/(1+$A2)^3+'DCF Base'!E18/(1+$A2)^4+'DCF Base'!F18/(1+$A2)^5+('DCF Base'!F6*(1+D$1)*(('DCF Base'!F7-'DCF Base'!F9)*(1-'DCF Base'!F12)+'DCF Base'!F9-'DCF Base'!F14)-'DCF Base'!F6*D$1*'DCF Base'!F16)/($A2-D$1)/(1+$A2)^5-'DCF Base'!B24)/'DCF Base'!B23 -> 144.50446 | E2: =('DCF Base'!B18/(1+$A2)^1+'DCF Base'!C18/(1+$A2)^2+'DCF Base'!D18/(1+$A2)^3+'DCF Base'!E18/(1+$A2)^4+'DCF Base'!F18/(1+$A2)^5+('DCF Base'!F6*(1+E$1)*(('DCF Base'!F7-'DCF Base'!F9)*(1-'DCF Base'!F12)+'DCF Base'!F9-'DCF Base'!F14)-'DCF Base'!F6*E$1*'DCF Base'!F16)/($A2-E$1)/(1+$A2)^5-'DCF Base'!B24)/'DCF Base'!B23 -> 157.05289 | F2: =('DCF Base'!B18/(1+$A2)^1+'DCF Base'!C18/(1+$A2)^2+'DCF Base'!D18/(1+$A2)^3+'DCF Base'!E18/(1+$A2)^4+'DCF Base'!F18/(1+$A2)^5+('DCF Base'!F6*(1+F$1)*(('DCF Base'!F7-'DCF Base'!F9)*(1-'DCF Base'!F12)+'DCF Base'!F9-'DCF Base'!F14)-'DCF Base'!F6*F$1*'DCF Base'!F16)/($A2-F$1)/(1+$A2)^5-'DCF Base'!B24)/'DCF Base'!B23 -> 172.38986
A3: 0.095 | B3: =('DCF Base'!B18/(1+$A3)^1+'DCF Base'!C18/(1+$A3)^2+'DCF Base'!D18/(1+$A3)^3+'DCF Base'!E18/(1+$A3)^4+'DCF Base'!F18/(1+$A3)^5+('DCF Base'!F6*(1+B$1)*(('DCF Base'!F7-'DCF Base'!F9)*(1-'DCF Base'!F12)+'DCF Base'!F9-'DCF Base'!F14)-'DCF Base'!F6*B$1*'DCF Base'!F16)/($A3-B$1)/(1+$A3)^5-'DCF Base'!B24)/'DCF Base'!B23 -> 104.41483 | C3: =('DCF Base'!B18/(1+$A3)^1+'DCF Base'!C18/(1+$A3)^2+'DCF Base'!D18/(1+$A3)^3+'DCF Base'!E18/(1+$A3)^4+'DCF Base'!F18/(1+$A3)^5+('DCF Base'!F6*(1+C$1)*(('DCF Base'!F7-'DCF Base'!F9)*(1-'DCF Base'!F12)+'DCF Base'!F9-'DCF Base'!F14)-'DCF Base'!F6*C$1*'DCF Base'!F16)/($A3-C$1)/(1+$A3)^5-'DCF Base'!B24)/'DCF Base'!B23 -> 110.60671 | D3: =('DCF Base'!B18/(1+$A3)^1+'DCF Base'!C18/(1+$A3)^2+'DCF Base'!D18/(1+$A3)^3+'DCF Base'!E18/(1+$A3)^4+'DCF Base'!F18/(1+$A3)^5+('DCF Base'!F6*(1+D$1)*(('DCF Base'!F7-'DCF Base'!F9)*(1-'DCF Base'!F12)+'DCF Base'!F9-'DCF Base'!F14)-'DCF Base'!F6*D$1*'DCF Base'!F16)/($A3-D$1)/(1+$A3)^5-'DCF Base'!B24)/'DCF Base'!B23 -> 117.75118 | E3: =('DCF Base'!B18/(1+$A3)^1+'DCF Base'!C18/(1+$A3)^2+'DCF Base'!D18/(1+$A3)^3+'DCF Base'!E18/(1+$A3)^4+'DCF Base'!F18/(1+$A3)^5+('DCF Base'!F6*(1+E$1)*(('DCF Base'!F7-'DCF Base'!F9)*(1-'DCF Base'!F12)+'DCF Base'!F9-'DCF Base'!F14)-'DCF Base'!F6*E$1*'DCF Base'!F16)/($A3-E$1)/(1+$A3)^5-'DCF Base'!B24)/'DCF Base'!B23 -> 126.0864 | F3: =('DCF Base'!B18/(1+$A3)^1+'DCF Base'!C18/(1+$A3)^2+'DCF Base'!D18/(1+$A3)^3+'DCF Base'!E18/(1+$A3)^4+'DCF Base'!F18/(1+$A3)^5+('DCF Base'!F6*(1+F$1)*(('DCF Base'!F7-'DCF Base'!F9)*(1-'DCF Base'!F12)+'DCF Base'!F9-'DCF Base'!F14)-'DCF Base'!F6*F$1*'DCF Base'!F16)/($A3-F$1)/(1+$A3)^5-'DCF Base'!B24)/'DCF Base'!B23 -> 135.93711
A4: 0.105 | B4: =('DCF Base'!B18/(1+$A4)^1+'DCF Base'!C18/(1+$A4)^2+'DCF Base'!D18/(1+$A4)^3+'DCF Base'!E18/(1+$A4)^4+'DCF Base'!F18/(1+$A4)^5+('DCF Base'!F6*(1+B$1)*(('DCF Base'!F7-'DCF Base'!F9)*(1-'DCF Base'!F12)+'DCF Base'!F9-'DCF Base'!F14)-'DCF Base'!F6*B$1*'DCF Base'!F16)/($A4-B$1)/(1+$A4)^5-'DCF Base'!B24)/'DCF Base'!B23 -> 88.565219 | C4: =('DCF Base'!B18/(1+$A4)^1+'DCF Base'!C18/(1+$A4)^2+'DCF Base'!D18/(1+$A4)^3+'DCF Base'!E18/(1+$A4)^4+'DCF Base'!F18/(1+$A4)^5+('DCF Base'!F6*(1+C$1)*(('DCF Base'!F7-'DCF Base'!F9)*(1-'DCF Base'!F12)+'DCF Base'!F9-'DCF Base'!F14)-'DCF Base'!F6*C$1*'DCF Base'!F16)/($A4-C$1)/(1+$A4)^5-'DCF Base'!B24)/'DCF Base'!B23 -> 93.069532 | D4: =('DCF Base'!B18/(1+$A4)^1+'DCF Base'!C18/(1+$A4)^2+'DCF Base'!D18/(1+$A4)^3+'DCF Base'!E18/(1+$A4)^4+'DCF Base'!F18/(1+$A4)^5+('DCF Base'!F6*(1+D$1)*(('DCF Base'!F7-'DCF Base'!F9)*(1-'DCF Base'!F12)+'DCF Base'!F9-'DCF Base'!F14)-'DCF Base'!F6*D$1*'DCF Base'!F16)/($A4-D$1)/(1+$A4)^5-'DCF Base'!B24)/'DCF Base'!B23 -> 98.174421 | E4: =('DCF Base'!B18/(1+$A4)^1+'DCF Base'!C18/(1+$A4)^2+'DCF Base'!D18/(1+$A4)^3+'DCF Base'!E18/(1+$A4)^4+'DCF Base'!F18/(1+$A4)^5+('DCF Base'!F6*(1+E$1)*(('DCF Base'!F7-'DCF Base'!F9)*(1-'DCF Base'!F12)+'DCF Base'!F9-'DCF Base'!F14)-'DCF Base'!F6*E$1*'DCF Base'!F16)/($A4-E$1)/(1+$A4)^5-'DCF Base'!B24)/'DCF Base'!B23 -> 104.00858 | F4: =('DCF Base'!B18/(1+$A4)^1+'DCF Base'!C18/(1+$A4)^2+'DCF Base'!D18/(1+$A4)^3+'DCF Base'!E18/(1+$A4)^4+'DCF Base'!F18/(1+$A4)^5+('DCF Base'!F6*(1+F$1)*(('DCF Base'!F7-'DCF Base'!F9)*(1-'DCF Base'!F12)+'DCF Base'!F9-'DCF Base'!F14)-'DCF Base'!F6*F$1*'DCF Base'!F16)/($A4-F$1)/(1+$A4)^5-'DCF Base'!B24)/'DCF Base'!B23 -> 110.7403
A5: 0.115 | B5: =('DCF Base'!B18/(1+$A5)^1+'DCF Base'!C18/(1+$A5)^2+'DCF Base'!D18/(1+$A5)^3+'DCF Base'!E18/(1+$A5)^4+'DCF Base'!F18/(1+$A5)^5+('DCF Base'!F6*(1+B$1)*(('DCF Base'!F7-'DCF Base'!F9)*(1-'DCF Base'!F12)+'DCF Base'!F9-'DCF Base'!F14)-'DCF Base'!F6*B$1*'DCF Base'!F16)/($A5-B$1)/(1+$A5)^5-'DCF Base'!B24)/'DCF Base'!B23 -> 76.08992 | C5: =('DCF Base'!B18/(1+$A5)^1+'DCF Base'!C18/(1+$A5)^2+'DCF Base'!D18/(1+$A5)^3+'DCF Base'!E18/(1+$A5)^4+'DCF Base'!F18/(1+$A5)^5+('DCF Base'!F6*(1+C$1)*(('DCF Base'!F7-'DCF Base'!F9)*(1-'DCF Base'!F12)+'DCF Base'!F9-'DCF Base'!F14)-'DCF Base'!F6*C$1*'DCF Base'!F16)/($A5-C$1)/(1+$A5)^5-'DCF Base'!B24)/'DCF Base'!B23 -> 79.466043 | D5: =('DCF Base'!B18/(1+$A5)^1+'DCF Base'!C18/(1+$A5)^2+'DCF Base'!D18/(1+$A5)^3+'DCF Base'!E18/(1+$A5)^4+'DCF Base'!F18/(1+$A5)^5+('DCF Base'!F6*(1+D$1)*(('DCF Base'!F7-'DCF Base'!F9)*(1-'DCF Base'!F12)+'DCF Base'!F9-'DCF Base'!F14)-'DCF Base'!F6*D$1*'DCF Base'!F16)/($A5-D$1)/(1+$A5)^5-'DCF Base'!B24)/'DCF Base'!B23 -> 83.239356 | E5: =('DCF Base'!B18/(1+$A5)^1+'DCF Base'!C18/(1+$A5)^2+'DCF Base'!D18/(1+$A5)^3+'DCF Base'!E18/(1+$A5)^4+'DCF Base'!F18/(1+$A5)^5+('DCF Base'!F6*(1+E$1)*(('DCF Base'!F7-'DCF Base'!F9)*(1-'DCF Base'!F12)+'DCF Base'!F9-'DCF Base'!F14)-'DCF Base'!F6*E$1*'DCF Base'!F16)/($A5-E$1)/(1+$A5)^5-'DCF Base'!B24)/'DCF Base'!B23 -> 87.484334 | F5: =('DCF Base'!B18/(1+$A5)^1+'DCF Base'!C18/(1+$A5)^2+'DCF Base'!D18/(1+$A5)^3+'DCF Base'!E18/(1+$A5)^4+'DCF Base'!F18/(1+$A5)^5+('DCF Base'!F6*(1+F$1)*(('DCF Base'!F7-'DCF Base'!F9)*(1-'DCF Base'!F12)+'DCF Base'!F9-'DCF Base'!F14)-'DCF Base'!F6*F$1*'DCF Base'!F16)/($A5-F$1)/(1+$A5)^5-'DCF Base'!B24)/'DCF Base'!B23 -> 92.295309
A6: 0.125 | B6: =('DCF Base'!B18/(1+$A6)^1+'DCF Base'!C18/(1+$A6)^2+'DCF Base'!D18/(1+$A6)^3+'DCF Base'!E18/(1+$A6)^4+'DCF Base'!F18/(1+$A6)^5+('DCF Base'!F6*(1+B$1)*(('DCF Base'!F7-'DCF Base'!F9)*(1-'DCF Base'!F12)+'DCF Base'!F9-'DCF Base'!F14)-'DCF Base'!F6*B$1*'DCF Base'!F16)/($A6-B$1)/(1+$A6)^5-'DCF Base'!B24)/'DCF Base'!B23 -> 66.023075 | C6: =('DCF Base'!B18/(1+$A6)^1+'DCF Base'!C18/(1+$A6)^2+'DCF Base'!D18/(1+$A6)^3+'DCF Base'!E18/(1+$A6)^4+'DCF Base'!F18/(1+$A6)^5+('DCF Base'!F6*(1+C$1)*(('DCF Base'!F7-'DCF Base'!F9)*(1-'DCF Base'!F12)+'DCF Base'!F9-'DCF Base'!F14)-'DCF Base'!F6*C$1*'DCF Base'!F16)/($A6-C$1)/(1+$A6)^5-'DCF Base'!B24)/'DCF Base'!B23 -> 68.61443 | D6: =('DCF Base'!B18/(1+$A6)^1+'DCF Base'!C18/(1+$A6)^2+'DCF Base'!D18/(1+$A6)^3+'DCF Base'!E18/(1+$A6)^4+'DCF Base'!F18/(1+$A6)^5+('DCF Base'!F6*(1+D$1)*(('DCF Base'!F7-'DCF Base'!F9)*(1-'DCF Base'!F12)+'DCF Base'!F9-'DCF Base'!F14)-'DCF Base'!F6*D$1*'DCF Base'!F16)/($A6-D$1)/(1+$A6)^5-'DCF Base'!B24)/'DCF Base'!B23 -> 71.478561 | E6: =('DCF Base'!B18/(1+$A6)^1+'DCF Base'!C18/(1+$A6)^2+'DCF Base'!D18/(1+$A6)^3+'DCF Base'!E18/(1+$A6)^4+'DCF Base'!F18/(1+$A6)^5+('DCF Base'!F6*(1+E$1)*(('DCF Base'!F7-'DCF Base'!F9)*(1-'DCF Base'!F12)+'DCF Base'!F9-'DCF Base'!F14)-'DCF Base'!F6*E$1*'DCF Base'!F16)/($A6-E$1)/(1+$A6)^5-'DCF Base'!B24)/'DCF Base'!B23 -> 74.660927 | F6: =('DCF Base'!B18/(1+$A6)^1+'DCF Base'!C18/(1+$A6)^2+'DCF Base'!D18/(1+$A6)^3+'DCF Base'!E18/(1+$A6)^4+'DCF Base'!F18/(1+$A6)^5+('DCF Base'!F6*(1+F$1)*(('DCF Base'!F7-'DCF Base'!F9)*(1-'DCF Base'!F12)+'DCF Base'!F9-'DCF Base'!F14)-'DCF Base'!F6*F$1*'DCF Base'!F16)/($A6-F$1)/(1+$A6)^5-'DCF Base'!B24)/'DCF Base'!B23 -> 78.21769

Sheet Earnings scenarios
A1: scenario | B1: fy2026_va_anchor | C1: fy2027_va | D1: growth | E1: gross_margin_va | F1: gross_profit | G1: revenue | H1: gross_margin_gaap | I1: ebitda_margin_va | J1: ebitda | K1: da | L1: ebit | M1: operating_margin_gaap | N1: tax | O1: interest | P1: acquisition_amortization_addback | Q1: adjusted_net_income | R1: eps | S1: capex | T1: nwc_ratio | U1: change_nwc | V1: fcff | W1: normalized_equity_fcf | X1: assumed_pe | Y1: price | Z1: price_return
A2: Downside | B2: 1203.1231 | C2: =B2*(1+D2) -> 1203.1231 | D2: 0 | E2: 0.31 | F2: =C2*E2 -> 372.96816 | G2: =C2/0.55 -> 2187.4965 | H2: =E2*0.55 -> 0.1705 | I2: 0.2 | J2: =C2*I2 -> 240.62462 | K2: 80 | L2: =J2-K2 -> 160.62462 | M2: =L2/G2 -> 0.073428514 | N2: 0.18 | O2: 30 | P2: 10 | Q2: =(L2+P2-O2)*(1-N2) -> 115.31219 | R2: =Q2/21.15 -> 5.4521129 | S2: 100 | T2: 0.3 | U2: =(C2-B2)*T2 -> 0 | V2: =L2*(1-N2)+K2-S2-U2 -> 111.71219 | W2: =V2-O2*(1-N2) -> 87.112188 | X2: 20 | Y2: =R2*X2 -> 109.04226 | Z2: =Y2/251.53-1 -> -0.56648408
A3: Base | B3: 1203.1231 | C3: =B3*(1+D3) -> 1323.4354 | D3: 0.1 | E3: 0.36 | F3: =C3*E3 -> 476.43675 | G3: =C3/0.55 -> 2406.2462 | H3: =E3*0.55 -> 0.198 | I3: 0.24 | J3: =C3*I3 -> 317.6245 | K3: 82 | L3: =J3-K3 -> 235.6245 | M3: =L3/G3 -> 0.097922024 | N3: 0.17 | O3: 28 | P3: 10 | Q3: =(L3+P3-O3)*(1-N3) -> 180.62833 | R3: =Q3/21.15 -> 8.5403467 | S3: 110 | T3: 0.3 | U3: =(C3-B3)*T3 -> 36.093693 | V3: =L3*(1-N3)+K3-S3-U3 -> 131.47464 | W3: =V3-O3*(1-N3) -> 108.23464 | X3: 24 | Y3: =R3*X3 -> 204.96832 | Z3: =Y3/251.53-1 -> -0.18511382
A4: Upside | B4: 1203.1231 | C4: =B4*(1+D4) -> 1467.8102 | D4: 0.22 | E4: 0.4 | F4: =C4*E4 -> 587.12407 | G4: =C4/0.55 -> 2668.7458 | H4: =E4*0.55 -> 0.22 | I4: 0.27 | J4: =C4*I4 -> 396.30875 | K4: 88 | L4: =J4-K4 -> 308.30875 | M4: =L4/G4 -> 0.11552571 | N4: 0.16 | O4: 26 | P4: 10 | Q4: =(L4+P4-O4)*(1-N4) -> 245.53935 | R4: =Q4/21.15 -> 11.609425 | S4: 150 | T4: 0.28 | U4: =(C4-B4)*T4 -> 74.112383 | V4: =L4*(1-N4)+K4-S4-U4 -> 122.86697 | W4: =V4-O4*(1-N4) -> 101.02697 | X4: 28 | Y4: =R4*X4 -> 325.06391 | Z4: =Y4/251.53-1 -> 0.2923465

Sheet Peers
A1: ticker | B1: period_end | C1: revenue | D1: net_income | E1: operating_income | F1: gross_profit | G1: cfo | H1: capex | I1: cash | J1: debt | K1: equity | L1: da | M1: ebitda_operating | N1: adjusted_ebitda | O1: shares | P1: price | Q1: market_cap_diluted | R1: ev | S1: fcf | T1: net_debt | U1: pe | V1: ps | W1: pb | X1: ev_revenue | Y1: ev_ebitda_operating | Z1: ev_adjusted_ebitda | AA1: fcf_yield | AB1: operating_margin | AC1: gross_margin
A2: ENTG | B2: 2026-06-27 | C2: 3326.1 | D2: 305.5 | E2: 533.7 | F2: 1512.7 | G2: 780.7 | H2: 205.5 | I2: 353.6 | J2: 3456 | K2: 4156.2 | L2: 357.3 | M2: 891 | N2: 925.6 | O2: 153.4 | P2: 142.25 | Q2: 21821.15 | R2: 24923.55 | S2: 575.2 | T2: 3102.4 | U2: 71.42766 | V2: 6.5605815 | W2: 5.2502647 | X2: 7.4933255 | Y2: 27.972559 | Z2: 26.926912 | AA2: 0.026359747 | AB2: 0.16045819 | AC2: 0.45479691
A3: CRS | B3: 2026-06-30 | C3: 3124.2 | D3: 529.8 | E3: 702 | F3: 955.5 | G3: 605 | H3: 242.7 | I3: 393.3 | J3: 690.7 | K3: 2227.6 | L3: 147.1 | M3: 849.1 | N3: Data unavailable | O3: 50.4 | P3: 408.12 | Q3: 20569.248 | R3: 20866.648 | S3: 362.3 | T3: 297.4 | U3: 38.824552 | V3: 6.5838447 | W3: 9.2338157 | X3: 6.6790371 | Y3: 24.575018 | Z3: Data unavailable | AA3: 0.017613673 | AB3: 0.22469752 | AC3: 0.30583829
A4: ATI | B4: 2026-06-28 | C4: 4715.2 | D4: 475.8 | E4: 716.8 | F4: 1101.4 | G4: 805.3 | H4: 279 | I4: 783 | J4: 2192 | K4: 1876.7 | L4: 174.7 | M4: 891.5 | N4: Data unavailable | O4: 138.5 | P4: 191.63 | Q4: 26540.756 | R4: 27949.756 | S4: 526.3 | T4: 1409 | U4: 55.781328 | V4: 5.6287656 | W4: 14.142247 | X4: 5.9275865 | Y4: 31.35138 | Z4: Data unavailable | AA4: 0.01982988 | AB4: 0.152019 | AC4: 0.233585

Sheet Stock returns
A1: ticker | B1: first_date | C1: close | D1: 1M | E1: 3M | F1: YTD | G1: 1Y | H1: 3Y | I1: 5Y | J1: 5Y_vol | K1: 5Y_max_drawdown
A2: MTRN | B2: 1980-03-17 | C2: 251.53 | D2: -0.046779441 | E2: -0.084737769 | F2: 1.0276204 | G2: 1.0665648 | H2: 1.4228029 | I2: 2.6221877 | J2: 0.45564237 | K2: -0.47844143
A3: SPY | B3: 1993-01-29 | C3: 761.69 | D3: -0.0050408383 | E3: 0.022553314 | F3: 0.12570291 | G3: 0.16576898 | H3: 0.78032474 | I3: 0.84498932 | J3: 0.17195166 | K3: -0.24496406
A4: IWM | B4: 2000-05-26 | C4: 284.10001 | D4: -0.051254088 | E4: -0.036361173 | F4: 0.16195676 | G4: 0.17213881 | H4: 0.61794986 | I4: 0.36251806 | J4: 0.22411414 | K4: -0.31911651
A5: XLB | B5: 1998-12-22 | C5: 49.990002 | D5: -0.034569277 | E5: -0.031520601 | F5: 0.11135753 | G5: 0.12029576 | H5: 0.30162507 | I5: 0.35732146 | J5: 0.19114016 | K5: -0.24716337
A6: ENTG | B6: 2000-07-11 | C6: 142.25 | D6: -0.053370627 | E6: -0.20361088 | F6: 0.69243155 | G6: 0.48737094 | H6: 0.55023057 | I6: 0.098193437 | J6: 0.55190773 | K6: -0.59319559
A7: CRS | B7: 1973-02-21 | C7: 408.12 | D7: -0.23247772 | E7: -0.30381576 | F7: 0.29817188 | G7: 0.65783759 | H7: 5.1315988 | I7: 12.69372 | J7: 0.4657014 | K7: -0.41858335
A8: ATI | B8: 1999-11-29 | C8: 191.63 | D8: -0.153802 | E8: -0.048226838 | F8: 0.66983271 | G8: 1.3810884 | H8: 3.3701257 | I8: 10.433771 | J8: 0.42914323 | K8: -0.38015062
A9: VNP.TO | B9: 2007-12-20 | C9: 26.389999 | D9: -0.099931799 | E9: -0.35743853 | F9: 0.48927768 | G9: 0.7091969 | H9: 6.6051871 | I9: 7.8557044 | J9: 0.54308177 | K9: -0.65273309

Sheet Events
A1: date | B1: event | C1: evidence | D1: return_1d | E1: excess_spy_1d | F1: return_3d | G1: excess_spy_3d | H1: return_5d | I1: excess_spy_5d | J1: next_day
A2: 2007-02-12 | B2: Large historical move; specific catalyst unverified | C2: unverified | D2: 0.33322694 | E2: 0.33663093 | F2: 0.44037002 | G2: 0.4287683 | H2: 0.45153058 | I2: 0.43909456 | J2: 0.049270757
A3: 2020-03-16 | B3: Pandemic market selloff; macro association | C3: context | D3: -0.15865889 | E3: -0.049235174 | F3: -0.29329461 | G3: -0.18442789 | H3: -0.18690604 | I3: -0.041448721 | J3: 0.042987187
A4: 2022-11-02 | B4: Q3 2022 earnings | C4: company earnings | D4: -0.21513393 | E4: -0.19003783 | F4: -0.16076826 | G4: -0.13952091 | H4: -0.11222346 | I4: -0.10566981 | J4: 0.035152902
A5: 2023-02-16 | B5: FY2022 earnings and 2023 outlook | C5: company earnings | D5: 0.24122751 | E5: 0.25499627 | F5: 0.21381013 | G5: 0.24977825 | H5: 0.22369406 | I5: 0.25586978 | J5: 0.017543867
A6: 2024-02-15 | B6: FY2023 earnings and 2024 outlook | C6: company earnings | D6: 0.10489533 | E6: 0.097995537 | F6: 0.056828217 | G6: 0.060458495 | H6: 0.064069541 | I6: 0.046158237 | J6: 0.0015276409
A7: 2025-07-30 | B7: Q2 2025 earnings; China and tariff uncertainty | C7: company earnings | D7: 0.10373679 | E7: 0.10499607 | F7: 0.14132087 | G7: 0.1626351 | H7: 0.17923108 | I7: 0.19070681 | J7: 0.036315461
A8: 2025-10-29 | B8: Q3 2025 earnings date listed on IR calendar | C8: company event | D8: -0.13272093 | E8: -0.13320133 | F8: -0.14384946 | G8: -0.13657213 | H8: -0.16722677 | I8: -0.15002302 | J8: -0.0052531107
A9: 2026-02-12 | B9: FY2025 earnings; $65m defense customer investment | C9: company earnings | D9: 0.012029803 | E9: 0.027478711 | F9: -0.024186818 | G9: -0.01102127 | H9: -0.038965851 | I9: -0.028155847 | J9: 0.0042765999
A10: 2026-04-29 | B10: Q1 2026 results; improved outlook | C10: company earnings | D10: -0.026737347 | E10: -0.026582713 | F10: 0.06171038 | G10: 0.049120692 | H10: 0.11078521 | I10: 0.093811543 | J10: 0.065318194
A11: 2026-07-28 | B11: Large decline; specific catalyst unverified | C11: unverified | D11: -0.13282609 | E11: -0.13522086 | F11: -0.13940119 | G11: -0.14291896 | H11: -0.1161608 | I11: -0.14129976 | J11: -0.097091084
A12: 2026-07-29 | B12: Second consecutive large decline; catalyst unverified | C12: unverified | D12: -0.097091084 | E12: -0.081703639 | F12: 0.0054363476 | G12: -0.0028919045 | H12: 0.082975743 | I12: 0.041847855 | J12: 0.099133886
A13: 2026-07-30 | B13: Rebound; company-specific catalyst unverified | C13: unverified | D13: 0.099133886 | E13: 0.082368142 | F13: 0.1288159 | G13: 0.09014352 | H13: 0.56902922 | I13: 0.51374183 | J13: 0.013118026
A14: 2026-08-05 | B14: Record Q2 2026; raised outlook | C14: company earnings | D14: 0.30814608 | E14: 0.31014264 | F14: 0.27719053 | G14: 0.27468834 | H14: 0.23645968 | I14: 0.23745792 | J14: -0.063349827
A15: 2026-09-16 | B15: FOMC raises rates 25bp; coincidence does not establish causality | C15: macro event | D15: 0.036871563 | E15: 0.041281444 | F15: 0.050317368 | G15: 0.042142685 | H15: Data unavailable | I15: Data unavailable | J15: 0.0086988187

Sheet Options snapshot
A1: contract | B1: expiration | C1: type | D1: strike | E1: spot | F1: bid | G1: ask | H1: last | I1: volume | J1: open_interest | K1: iv | L1: vendor_delta | M1: vendor_gamma | N1: vendor_theta | O1: vendor_vega | P1: quote_timestamp | Q1: last_trade_timestamp | R1: underlying_last_trade_timestamp | S1: multiplier | T1: midpoint | U1: spread_pct | V1: days_to_expiration | W1: moneyness | X1: same_session | Y1: trade_age_days | Z1: usable | AA1: liquidity_screen
A2: MTRN261016C00230000 | B2: 2026-10-16 | C2: call | D2: 230 | E2: 251.53 | F2: 25.7 | G2: 29 | H2: 0 | I2: 0 | J2: 0 | K2: 0.4956 | L2: 0.7632 | M2: 0.0084 | N2: -0.201 | O2: 0.2158 | P2: 2026-09-19 01:47:18 | Q2: Data unavailable | R2: 2026-09-18T15:59:59 | S2: 100 | T2: 27.35 | U2: 0.12065814 | V2: 28 | W2: 1.0936087 | X2: 1 | Y2: Data unavailable | Z2: 0 | AA2: 0
A3: MTRN261016P00230000 | B3: 2026-10-16 | C3: put | D3: 230 | E3: 251.53 | F3: 3 | G3: 7.3 | H3: 0 | I3: 0 | J3: 0 | K3: 0.5084 | L3: -0.2382 | M3: 0.0085 | N3: -0.2023 | O3: 0.2165 | P3: 2026-09-19 01:47:18 | Q3: Data unavailable | R3: 2026-09-18T15:59:59 | S3: 100 | T3: 5.15 | U3: 0.83495146 | V3: 28 | W3: 1.0936087 | X3: 1 | Y3: Data unavailable | Z3: 0 | AA3: 0
A4: MTRN261016C00240000 | B4: 2026-10-16 | C4: call | D4: 240 | E4: 251.53 | F4: 19.5 | G4: 22.9 | H4: 27.51 | I4: 0 | J4: 2 | K4: 0.5185 | L4: 0.6657 | M4: 0.0101 | N4: -0.2346 | O4: 0.2542 | P4: 2026-09-19 01:47:18 | Q4: 2026-09-09T10:01:39 | R4: 2026-09-18T15:59:59 | S4: 100 | T4: 21.2 | U4: 0.16037736 | V4: 28 | W4: 1.0480417 | X4: 1 | Y4: 9 | Z4: 0 | AA4: 0
A5: MTRN261016P00240000 | B5: 2026-10-16 | C5: put | D5: 240 | E5: 251.53 | F5: 6.4 | G5: 10.5 | H5: 0 | I5: 0 | J5: 0 | K5: 0.508 | L5: -0.3364 | M5: 0.0102 | N5: -0.2364 | O5: 0.2545 | P5: 2026-09-19 01:47:18 | Q5: Data unavailable | R5: 2026-09-18T15:59:59 | S5: 100 | T5: 8.45 | U5: 0.4852071 | V5: 28 | W5: 1.0480417 | X5: 1 | Y5: Data unavailable | Z5: 0 | AA5: 0
A6: MTRN261016C00250000 | B6: 2026-10-16 | C6: call | D6: 250 | E6: 251.53 | F6: 13.5 | G6: 17.5 | H6: 0 | I6: 0 | J6: 0 | K6: 0.5126 | L6: 0.5572 | M6: 0.011 | N6: -0.2542 | O6: 0.2755 | P6: 2026-09-19 01:47:18 | Q6: Data unavailable | R6: 2026-09-18T15:59:59 | S6: 100 | T6: 15.5 | U6: 0.25806452 | V6: 28 | W6: 1.00612 | X6: 1 | Y6: Data unavailable | Z6: 0 | AA6: 0
A7: MTRN261016P00250000 | B7: 2026-10-16 | C7: put | D7: 250 | E7: 251.53 | F7: 11.2 | G7: 15 | H7: 0 | I7: 0 | J7: 0 | K7: 0.5158 | L7: -0.4458 | M7: 0.0111 | N7: -0.2565 | O7: 0.2755 | P7: 2026-09-19 01:47:18 | Q7: Data unavailable | R7: 2026-09-18T15:59:59 | S7: 100 | T7: 13.1 | U7: 0.29007634 | V7: 28 | W7: 1.00612 | X7: 1 | Y7: Data unavailable | Z7: 0 | AA7: 0
A8: MTRN261016C00260000 | B8: 2026-10-16 | C8: call | D8: 260 | E8: 251.53 | F8: 9.4 | G8: 13 | H8: 16.65 | I8: 0 | J8: 2 | K8: 0.5176 | L8: 0.4492 | M8: 0.0109 | N8: -0.2566 | O8: 0.276 | P8: 2026-09-19 01:47:18 | Q8: 2026-09-08T11:51:36 | R8: 2026-09-18T15:59:59 | S8: 100 | T8: 11.2 | U8: 0.32142857 | V8: 28 | W8: 0.96742308 | X8: 1 | Y8: 10 | Z8: 0 | AA8: 0
A9: MTRN261016P00260000 | B9: 2026-10-16 | C9: put | D9: 260 | E9: 251.53 | F9: 17.2 | G9: 20.5 | H9: 39.56 | I9: 0 | J9: 1 | K9: 0.5226 | L9: -0.5549 | M9: 0.011 | N9: -0.2595 | O9: 0.2753 | P9: 2026-09-19 01:47:18 | Q9: 2026-08-24T09:59:09 | R9: 2026-09-18T15:59:59 | S9: 100 | T9: 18.85 | U9: 0.17506631 | V9: 28 | W9: 0.96742308 | X9: 1 | Y9: 25 | Z9: 0 | AA9: 0
A10: MTRN261016C00270000 | B10: 2026-10-16 | C10: call | D10: 270 | E10: 251.53 | F10: 6.5 | G10: 9.8 | H10: 7.9 | I10: 1 | J10: 1 | K10: 0.5318 | L10: 0.3517 | M10: 0.0101 | N10: -0.2438 | O10: 0.259 | P10: 2026-09-19 01:47:18 | Q10: 2026-09-18T09:44:57 | R10: 2026-09-18T15:59:59 | S10: 100 | T10: 8.15 | U10: 0.40490798 | V10: 28 | W10: 0.93159259 | X10: 1 | Y10: 0 | Z10: 0 | AA10: 0
A11: MTRN261016P00270000 | B11: 2026-10-16 | C11: put | D11: 270 | E11: 251.53 | F11: 24.2 | G11: 27.5 | H11: 0 | I11: 0 | J11: 0 | K11: 0.5386 | L11: -0.6536 | M11: 0.0102 | N11: -0.2474 | O11: 0.2566 | P11: 2026-09-19 01:47:18 | Q11: Data unavailable | R11: 2026-09-18T15:59:59 | S11: 100 | T11: 25.85 | U11: 0.12765957 | V11: 28 | W11: 0.93159259 | X11: 1 | Y11: Data unavailable | Z11: 0 | AA11: 0
A12: MTRN261016C00280000 | B12: 2026-10-16 | C12: call | D12: 280 | E12: 251.53 | F12: 3.8 | G12: 7.5 | H12: 5.5 | I12: 3 | J12: 1 | K12: 0.5351 | L12: 0.27 | M12: 0.0088 | N12: -0.2211 | O12: 0.231 | P12: 2026-09-19 01:47:18 | Q12: 2026-09-18T11:03:12 | R12: 2026-09-18T15:59:59 | S12: 100 | T12: 5.65 | U12: 0.65486726 | V12: 28 | W12: 0.89832143 | X12: 1 | Y12: 0 | Z12: 0 | AA12: 0
A13: MTRN261016P00280000 | B13: 2026-10-16 | C13: put | D13: 280 | E13: 251.53 | F13: 31.9 | G13: 35 | H13: 0 | I13: 0 | J13: 0 | K13: 0.546 | L13: -0.7365 | M13: 0.009 | N13: -0.2253 | O13: 0.2276 | P13: 2026-09-19 01:47:18 | Q13: Data unavailable | R13: 2026-09-18T15:59:59 | S13: 100 | T13: 33.45 | U13: 0.092675635 | V13: 28 | W13: 0.89832143 | X13: 1 | Y13: Data unavailable | Z13: 0 | AA13: 0
A14: MTRN261120C00230000 | B14: 2026-11-20 | C14: call | D14: 230 | E14: 251.53 | F14: 34 | G14: 37.7 | H14: 0 | I14: 0 | J14: 0 | K14: 0.5602 | L14: 0.7035 | M14: 0.0059 | N14: -0.1612 | O14: 0.3621 | P14: 2026-09-19 01:47:18 | Q14: Data unavailable | R14: 2026-09-18T15:59:59 | S14: 100 | T14: 35.85 | U14: 0.10320781 | V14: 63 | W14: 1.0936087 | X14: 1 | Y14: Data unavailable | Z14: 0 | AA14: 0
A15: MTRN261120P00230000 | B15: 2026-11-20 | C15: put | D15: 230 | E15: 251.53 | F15: 10.5 | G15: 14.4 | H15: 0 | I15: 0 | J15: 0 | K15: 0.5582 | L15: -0.2986 | M15: 0.0059 | N15: -0.1627 | O15: 0.3629 | P15: 2026-09-19 01:47:18 | Q15: Data unavailable | R15: 2026-09-18T15:59:59 | S15: 100 | T15: 12.45 | U15: 0.31325301 | V15: 63 | W15: 1.0936087 | X15: 1 | Y15: Data unavailable | Z15: 0 | AA15: 0
A16: MTRN261120C00240000 | B16: 2026-11-20 | C16: call | D16: 240 | E16: 251.53 | F16: 28.2 | G16: 32.4 | H16: 0 | I16: 0 | J16: 0 | K16: 0.5662 | L16: 0.6378 | M16: 0.0063 | N16: -0.1756 | O16: 0.3923 | P16: 2026-09-19 01:47:18 | Q16: Data unavailable | R16: 2026-09-18T15:59:59 | S16: 100 | T16: 30.3 | U16: 0.13861386 | V16: 63 | W16: 1.0480417 | X16: 1 | Y16: Data unavailable | Z16: 0 | AA16: 0
A17: MTRN261120P00240000 | B17: 2026-11-20 | C17: put | D17: 240 | E17: 251.53 | F17: 14.9 | G17: 19 | H17: 0 | I17: 0 | J17: 0 | K17: 0.5669 | L17: -0.3649 | M17: 0.0064 | N17: -0.1775 | O17: 0.393 | P17: 2026-09-19 01:47:18 | Q17: Data unavailable | R17: 2026-09-18T15:59:59 | S17: 100 | T17: 16.95 | U17: 0.24188791 | V17: 63 | W17: 1.0480417 | X17: 1 | Y17: Data unavailable | Z17: 0 | AA17: 0
A18: MTRN261120C00250000 | B18: 2026-11-20 | C18: call | D18: 250 | E18: 251.53 | F18: 23.5 | G18: 27.5 | H18: 0 | I18: 0 | J18: 0 | K18: 0.5729 | L18: 0.5713 | M18: 0.0066 | N18: -0.185 | O18: 0.4107 | P18: 2026-09-19 01:47:18 | Q18: Data unavailable | R18: 2026-09-18T15:59:59 | S18: 100 | T18: 25.5 | U18: 0.15686275 | V18: 63 | W18: 1.00612 | X18: 1 | Y18: Data unavailable | Z18: 0 | AA18: 0
A19: MTRN261120P00250000 | B19: 2026-11-20 | C19: put | D19: 250 | E19: 251.53 | F19: 20 | G19: 24.2 | H19: 0 | I19: 0 | J19: 0 | K19: 0.5734 | L19: -0.4322 | M19: 0.0067 | N19: -0.1875 | O19: 0.4108 | P19: 2026-09-19 01:47:18 | Q19: Data unavailable | R19: 2026-09-18T15:59:59 | S19: 100 | T19: 22.1 | U19: 0.19004525 | V19: 63 | W19: 1.00612 | X19: 1 | Y19: Data unavailable | Z19: 0 | AA19: 0
A20: MTRN261120C00260000 | B20: 2026-11-20 | C20: call | D20: 260 | E20: 251.53 | F20: 19.2 | G20: 23.3 | H20: 0 | I20: 0 | J20: 0 | K20: 0.5765 | L20: 0.5065 | M20: 0.0066 | N20: -0.1895 | O20: 0.4173 | P20: 2026-09-19 01:47:18 | Q20: Data unavailable | R20: 2026-09-18T15:59:59 | S20: 100 | T20: 21.25 | U20: 0.19294118 | V20: 63 | W20: 0.96742308 | X20: 1 | Y20: Data unavailable | Z20: 0 | AA20: 0
A21: MTRN261120P00260000 | B21: 2026-11-20 | C21: put | D21: 260 | E21: 251.53 | F21: 25.7 | G21: 29.5 | H21: 0 | I21: 0 | J21: 0 | K21: 0.5718 | L21: -0.498 | M21: 0.0068 | N21: -0.1925 | O21: 0.4165 | P21: 2026-09-19 01:47:18 | Q21: Data unavailable | R21: 2026-09-18T15:59:59 | S21: 100 | T21: 27.6 | U21: 0.13768116 | V21: 63 | W21: 0.96742308 | X21: 1 | Y21: Data unavailable | Z21: 0 | AA21: 0
A22: MTRN261120C00270000 | B22: 2026-11-20 | C22: call | D22: 270 | E22: 251.53 | F22: 15.8 | G22: 19.5 | H22: 0 | I22: 0 | J22: 0 | K22: 0.5808 | L22: 0.4452 | M22: 0.0065 | N22: -0.1894 | O22: 0.4133 | P22: 2026-09-19 01:47:18 | Q22: Data unavailable | R22: 2026-09-18T15:59:59 | S22: 100 | T22: 17.65 | U22: 0.20963173 | V22: 63 | W22: 0.93159259 | X22: 1 | Y22: Data unavailable | Z22: 0 | AA22: 0
A23: MTRN261120P00270000 | B23: 2026-11-20 | C23: put | D23: 270 | E23: 251.53 | F23: 32.2 | G23: 36 | H23: 0 | I23: 0 | J23: 0 | K23: 0.5791 | L23: -0.5604 | M23: 0.0066 | N23: -0.1931 | O23: 0.4117 | P23: 2026-09-19 01:47:18 | Q23: Data unavailable | R23: 2026-09-18T15:59:59 | S23: 100 | T23: 34.1 | U23: 0.11143695 | V23: 63 | W23: 0.93159259 | X23: 1 | Y23: Data unavailable | Z23: 0 | AA23: 0
A24: MTRN261120C00280000 | B24: 2026-11-20 | C24: call | D24: 280 | E24: 251.53 | F24: 12.8 | G24: 16 | H24: 0 | I24: 0 | J24: 0 | K24: 0.58 | L24: 0.3886 | M24: 0.0063 | N24: -0.1855 | O24: 0.4009 | P24: 2026-09-19 01:47:18 | Q24: Data unavailable | R24: 2026-09-18T15:59:59 | S24: 100 | T24: 14.4 | U24: 0.22222222 | V24: 63 | W24: 0.89832143 | X24: 1 | Y24: Data unavailable | Z24: 0 | AA24: 0
A25: MTRN261120P00280000 | B25: 2026-11-20 | C25: put | D25: 280 | E25: 251.53 | F25: 39.5 | G25: 43 | H25: 0 | I25: 0 | J25: 0 | K25: 0.5886 | L25: -0.6182 | M25: 0.0064 | N25: -0.1898 | O25: 0.3979 | P25: 2026-09-19 01:47:18 | Q25: Data unavailable | R25: 2026-09-18T15:59:59 | S25: 100 | T25: 41.25 | U25: 0.084848485 | V25: 63 | W25: 0.89832143 | X25: 1 | Y25: Data unavailable | Z25: 0 | AA25: 0
A26: MTRN261218C00230000 | B26: 2026-12-18 | C26: call | D26: 230 | E26: 251.53 | F26: 38.5 | G26: 42 | H26: 39 | I26: 0 | J26: 38 | K26: 0.5616 | L26: 0.6922 | M26: 0.005 | N26: -0.1354 | O26: 0.4424 | P26: 2026-09-19 01:47:18 | Q26: 2026-09-08T09:34:51 | R26: 2026-09-18T15:59:59 | S26: 100 | T26: 40.25 | U26: 0.086956522 | V26: 91 | W26: 1.0936087 | X26: 1 | Y26: 10 | Z26: 0 | AA26: 1
A27: MTRN261218P00230000 | B27: 2026-12-18 | C27: put | D27: 230 | E27: 251.53 | F27: 14.4 | G27: 18.5 | H27: 16.9 | I27: 0 | J27: 2 | K27: 0.5614 | L27: -0.3109 | M27: 0.0051 | N27: -0.1374 | O27: 0.4441 | P27: 2026-09-19 01:47:18 | Q27: 2026-08-18T13:06:35 | R27: 2026-09-18T15:59:59 | S27: 100 | T27: 16.45 | U27: 0.24924012 | V27: 91 | W27: 1.0936087 | X27: 1 | Y27: 31 | Z27: 0 | AA27: 0
A28: MTRN261218C00240000 | B28: 2026-12-18 | C28: call | D28: 240 | E28: 251.53 | F28: 33.2 | G28: 36.5 | H28: 32.6 | I28: 0 | J28: 25 | K28: 0.5638 | L28: 0.6368 | M28: 0.0053 | N28: -0.1448 | O28: 0.4718 | P28: 2026-09-19 01:47:18 | Q28: 2026-09-10T10:18:06 | R28: 2026-09-18T15:59:59 | S28: 100 | T28: 34.85 | U28: 0.094691535 | V28: 91 | W28: 1.0480417 | X28: 1 | Y28: 8 | Z28: 0 | AA28: 1
A29: MTRN261218P00240000 | B29: 2026-12-18 | C29: put | D29: 240 | E29: 251.53 | F29: 19.3 | G29: 23 | H29: 34.86 | I29: 0 | J29: 1 | K29: 0.5672 | L29: -0.3671 | M29: 0.0054 | N29: -0.1471 | O29: 0.4727 | P29: 2026-09-19 01:47:18 | Q29: 2026-06-11T13:10:47 | R29: 2026-09-18T15:59:59 | S29: 100 | T29: 21.15 | U29: 0.1749409 | V29: 91 | W29: 1.0480417 | X29: 1 | Y29: 99 | Z29: 0 | AA29: 0
A30: MTRN261218C00250000 | B30: 2026-12-18 | C30: call | D30: 250 | E30: 251.53 | F30: 28.2 | G30: 32 | H30: 25.5 | I30: 0 | J30: 17 | K30: 0.5621 | L30: 0.581 | M30: 0.0055 | N30: -0.1511 | O30: 0.4911 | P30: 2026-09-19 01:47:18 | Q30: 2026-08-26T12:53:22 | R30: 2026-09-18T15:59:59 | S30: 100 | T30: 30.1 | U30: 0.12624585 | V30: 91 | W30: 1.00612 | X30: 1 | Y30: 23 | Z30: 0 | AA30: 0
A31: MTRN261218P00250000 | B31: 2026-12-18 | C31: put | D31: 250 | E31: 251.53 | F31: 24.3 | G31: 28 | H31: 26.6 | I31: 0 | J31: 10 | K31: 0.5666 | L31: -0.4239 | M31: 0.0056 | N31: -0.1539 | O31: 0.4913 | P31: 2026-09-19 01:47:18 | Q31: 2026-09-14T09:30:02 | R31: 2026-09-18T15:59:59 | S31: 100 | T31: 26.15 | U31: 0.1414914 | V31: 91 | W31: 1.00612 | X31: 1 | Y31: 4 | Z31: 0 | AA31: 0
A32: MTRN261218C00260000 | B32: 2026-12-18 | C32: call | D32: 260 | E32: 251.53 | F32: 23.5 | G32: 27.5 | H32: 30.2 | I32: 0 | J32: 11 | K32: 0.5573 | L32: 0.5262 | M32: 0.0056 | N32: -0.1544 | O32: 0.5003 | P32: 2026-09-19 01:47:18 | Q32: 2026-09-08T11:21:50 | R32: 2026-09-18T15:59:59 | S32: 100 | T32: 25.5 | U32: 0.15686275 | V32: 91 | W32: 0.96742308 | X32: 1 | Y32: 10 | Z32: 0 | AA32: 0
A33: MTRN261218P00260000 | B33: 2026-12-18 | C33: put | D33: 260 | E33: 251.53 | F33: 29.6 | G33: 33.5 | H33: 25 | I33: 0 | J33: 1 | K33: 0.5628 | L33: -0.4798 | M33: 0.0058 | N33: -0.1577 | O33: 0.4996 | P33: 2026-09-19 01:47:18 | Q33: 2026-08-11T10:28:17 | R33: 2026-09-18T15:59:59 | S33: 100 | T33: 31.55 | U33: 0.12361331 | V33: 91 | W33: 0.96742308 | X33: 1 | Y33: 38 | Z33: 0 | AA33: 0
A34: MTRN261218C00270000 | B34: 2026-12-18 | C34: call | D34: 270 | E34: 251.53 | F34: 19.7 | G34: 23.5 | H34: 17 | I34: 0 | J34: 3 | K34: 0.5611 | L34: 0.4733 | M34: 0.0056 | N34: -0.1549 | O34: 0.5002 | P34: 2026-09-19 01:47:18 | Q34: 2026-08-21T13:04:14 | R34: 2026-09-18T15:59:59 | S34: 100 | T34: 21.6 | U34: 0.17592593 | V34: 91 | W34: 0.93159259 | X34: 1 | Y34: 28 | Z34: 0 | AA34: 0
A35: MTRN261218P00270000 | B35: 2026-12-18 | C35: put | D35: 270 | E35: 251.53 | F35: 35.6 | G35: 39.5 | H35: 28.84 | I35: 0 | J35: 2 | K35: 0.5602 | L35: -0.5339 | M35: 0.0057 | N35: -0.1587 | O35: 0.498 | P35: 2026-09-19 01:47:18 | Q35: 2026-08-05T13:07:14 | R35: 2026-09-18T15:59:59 | S35: 100 | T35: 37.55 | U35: 0.10386152 | V35: 91 | W35: 0.93159259 | X35: 1 | Y35: 44 | Z35: 0 | AA35: 0
A36: MTRN261218C00280000 | B36: 2026-12-18 | C36: call | D36: 280 | E36: 251.53 | F36: 16.5 | G36: 20 | H36: 14.54 | I36: 0 | J36: 8 | K36: 0.5559 | L36: 0.4233 | M36: 0.0055 | N36: -0.1529 | O36: 0.4921 | P36: 2026-09-19 01:47:18 | Q36: 2026-09-03T10:14:53 | R36: 2026-09-18T15:59:59 | S36: 100 | T36: 18.25 | U36: 0.19178082 | V36: 91 | W36: 0.89832143 | X36: 1 | Y36: 15 | Z36: 0 | AA36: 0
A37: MTRN261218P00280000 | B37: 2026-12-18 | C37: put | D37: 280 | E37: 251.53 | F37: 42.4 | G37: 46.5 | H37: 35 | I37: 0 | J37: 52 | K37: 0.5659 | L37: -0.5853 | M37: 0.0056 | N37: -0.1572 | O37: 0.4877 | P37: 2026-09-19 01:47:18 | Q37: 2026-08-10T10:05:43 | R37: 2026-09-18T15:59:59 | S37: 100 | T37: 44.45 | U37: 0.09223847 | V37: 91 | W37: 0.89832143 | X37: 1 | Y37: 39 | Z37: 0 | AA37: 1
A38: MTRN270319C00230000 | B38: 2027-03-19 | C38: call | D38: 230 | E38: 251.53 | F38: 49.6 | G38: 54 | H38: 48 | I38: 0 | J38: 9 | K38: 0.5558 | L38: 0.6871 | M38: 0.0036 | N38: -0.0945 | O38: 0.6307 | P38: 2026-09-19 01:47:18 | Q38: 2026-09-04T10:50:25 | R38: 2026-09-18T15:59:59 | S38: 100 | T38: 51.8 | U38: 0.084942085 | V38: 182 | W38: 1.0936087 | X38: 1 | Y38: 14 | Z38: 0 | AA38: 0
A39: MTRN270319P00230000 | B39: 2027-03-19 | C39: put | D39: 230 | E39: 251.53 | F39: 23.5 | G39: 27.8 | H39: 0 | I39: 0 | J39: 0 | K39: 0.5597 | L39: -0.3192 | M39: 0.0037 | N39: -0.0983 | O39: 0.6334 | P39: 2026-09-19 01:47:18 | Q39: Data unavailable | R39: 2026-09-18T15:59:59 | S39: 100 | T39: 25.65 | U39: 0.16764133 | V39: 182 | W39: 1.0936087 | X39: 1 | Y39: Data unavailable | Z39: 0 | AA39: 0
A40: MTRN270319C00240000 | B40: 2027-03-19 | C40: call | D40: 240 | E40: 251.53 | F40: 44.7 | G40: 49.2 | H40: 36.6 | I40: 0 | J40: 4 | K40: 0.5578 | L40: 0.6481 | M40: 0.0037 | N40: -0.0995 | O40: 0.6605 | P40: 2026-09-19 01:47:18 | Q40: 2026-09-03T10:42:43 | R40: 2026-09-18T15:59:59 | S40: 100 | T40: 46.95 | U40: 0.095846645 | V40: 182 | W40: 1.0480417 | X40: 1 | Y40: 15 | Z40: 0 | AA40: 0
...

Sheet Options summary
A1: expiration | B1: contracts | C1: usable | D1: call_volume | E1: put_volume | F1: call_oi | G1: put_oi | H1: put_call_volume | I1: put_call_oi | J1: median_spread | K1: atm_strike | L1: atm_iv | M1: days
A2: 2026-09-18 | B2: 98 | C2: 0 | D2: 12 | E2: 2 | F2: 965 | G2: 120 | H2: 0.16666667 | I2: 0.12435233 | J2: 1.8604651 | K2: 250 | L2: 1.2817 | M2: 0
A3: 2026-10-16 | B3: 42 | C3: 0 | D3: 8 | E3: 0 | F3: 32 | G3: 33 | H3: 0 | I3: 1.03125 | J3: 0.27407043 | K3: 250 | L3: 0.5142 | M3: 28
A4: 2026-11-20 | B4: 34 | C4: 0 | D4: 0 | E4: 3 | F4: 0 | G4: 0 | H4: Data unavailable | I4: Data unavailable | J4: 0.173454 | K4: 250 | L4: 0.57315 | M4: 63
A5: 2026-12-18 | B5: 92 | C5: 0 | D5: 0 | E5: 3 | F5: 371 | G5: 197 | H5: Data unavailable | I5: 0.5309973 | J5: 0.13386862 | K5: 250 | L5: 0.56435 | M5: 91
A6: 2027-03-19 | B6: 86 | C6: 0 | D6: 0 | E6: 4 | F6: 86 | G6: 36 | H6: Data unavailable | I6: 0.41860465 | J6: 0.1054363 | K6: 250 | L6: 0.564 | M6: 182

Sheet Financial audit
A1: metric | B1: tag | C1: namespace | D1: unit | E1: start | F1: end | G1: val | H1: accn | I1: fy | J1: fp | K1: form | L1: filed | M1: frame
A2: revenue | B2: RevenueFromContractWithCustomerExcludingAssessedTax | C2: us-gaap | D2: USD | E2: 2021-01-01 | F2: 2021-12-31 | G2: 1510644000 | H2: 0001104657-24-000019 | I2: 2023 | J2: FY | K2: 10-K | L2: 2024-02-15 | M2: CY2021
A3: gross_profit | B3: GrossProfit | C3: us-gaap | D3: USD | E3: 2021-01-01 | F3: 2021-12-31 | G3: 283762000 | H3: 0001104657-24-000019 | I3: 2023 | J3: FY | K3: 10-K | L3: 2024-02-15 | M3: CY2021
A4: operating_income | B4: OperatingIncomeLoss | C4: us-gaap | D4: USD | E4: 2021-01-01 | F4: 2021-12-31 | G4: 77111000 | H4: 0001104657-24-000019 | I4: 2023 | J4: FY | K4: 10-K | L4: 2024-02-15 | M4: CY2021
A5: net_income | B5: NetIncomeLoss | C5: us-gaap | D5: USD | E5: 2021-01-01 | F5: 2021-12-31 | G5: 72474000 | H5: 0001104657-24-000019 | I5: 2023 | J5: FY | K5: 10-K | L5: 2024-02-15 | M5: CY2021
A6: tax | B6: IncomeTaxExpenseBenefit | C6: us-gaap | D6: USD | E6: 2021-01-01 | F6: 2021-12-31 | G6: 4851000 | H6: 0001104657-24-000019 | I6: 2023 | J6: FY | K6: 10-K | L6: 2024-02-15 | M6: CY2021
A7: interest | B7: MISSING | C7: Data unavailable | D7: USD | E7: 2021-01-01 | F7: 2021-12-31 | G7: Data unavailable | H7: Data unavailable | I7: Data unavailable | J7: Data unavailable | K7: Data unavailable | L7: Data unavailable | M7: Data unavailable
A8: cfo | B8: NetCashProvidedByUsedInOperatingActivities | C8: us-gaap | D8: USD | E8: 2021-01-01 | F8: 2021-12-31 | G8: 90241000 | H8: 0001104657-24-000019 | I8: 2023 | J8: FY | K8: 10-K | L8: 2024-02-15 | M8: CY2021
A9: ppe_capex | B9: PaymentsToAcquirePropertyPlantAndEquipment | C9: us-gaap | D9: USD | E9: 2021-01-01 | F9: 2021-12-31 | G9: 102910000 | H9: 0001104657-24-000019 | I9: 2023 | J9: FY | K9: 10-K | L9: 2024-02-15 | M9: CY2021
A10: mine_capex | B10: MISSING | C10: Data unavailable | D10: USD | E10: 2021-01-01 | F10: 2021-12-31 | G10: Data unavailable | H10: Data unavailable | I10: Data unavailable | J10: Data unavailable | K10: Data unavailable | L10: Data unavailable | M10: Data unavailable
A11: da | B11: DepreciationDepletionAndAmortization | C11: us-gaap | D11: USD | E11: 2021-01-01 | F11: 2021-12-31 | G11: 44137000 | H11: 0001104657-24-000019 | I11: 2023 | J11: FY | K11: 10-K | L11: 2024-02-15 | M11: CY2021
A12: amortization | B12: AmortizationOfIntangibleAssets | C12: us-gaap | D12: USD | E12: 2021-01-01 | F12: 2021-12-31 | G12: 5973000 | H12: 0001104657-24-000019 | I12: 2023 | J12: FY | K12: 10-K | L12: 2024-02-15 | M12: CY2021
A13: sbc | B13: ShareBasedCompensation | C13: us-gaap | D13: USD | E13: 2021-01-01 | F13: 2021-12-31 | G13: 6517000 | H13: 0001104657-24-000019 | I13: 2023 | J13: FY | K13: 10-K | L13: 2024-02-15 | M13: CY2021
A14: rnd | B14: ResearchAndDevelopmentExpense | C14: us-gaap | D14: USD | E14: 2021-01-01 | F14: 2021-12-31 | G14: 26575000 | H14: 0001104657-24-000019 | I14: 2023 | J14: FY | K14: 10-K | L14: 2024-02-15 | M14: CY2021
A15: dividends | B15: PaymentsOfDividendsCommonStock | C15: us-gaap | D15: USD | E15: 2021-01-01 | F15: 2021-12-31 | G15: 9697000 | H15: 0001104657-24-000019 | I15: 2023 | J15: FY | K15: 10-K | L15: 2024-02-15 | M15: CY2021
A16: repurchases | B16: PaymentsForRepurchaseOfCommonStock | C16: us-gaap | D16: USD | E16: 2021-01-01 | F16: 2021-12-31 | G16: 0 | H16: 0001104657-23-000019 | I16: 2022 | J16: FY | K16: 10-K | L16: 2023-02-16 | M16: CY2021
A17: diluted_shares | B17: WeightedAverageNumberOfDilutedSharesOutstanding | C17: us-gaap | D17: shares | E17: 2021-01-01 | F17: 2021-12-31 | G17: 20689000 | H17: 0001104657-24-000019 | I17: 2023 | J17: FY | K17: 10-K | L17: 2024-02-15 | M17: CY2021
