Workbook

Sheet README
A1: HPE — historical financial analysis
A2: Bona Fide Student Investment Society · prepared 14-Sep-2026
A4: Source: consolidated statements parsed from HPE 10-K FY2020–FY2025 and 10-Q Q3 FY26 (code/parse_statements.py).
A5: Fiscal years end 31 October. TTM Q3 FY26 = FY2025 + 9M FY2026 − 9M FY2025; balance sheet at 31-Jul-2026.
A6: Each fiscal year uses the most recent 10-K presenting that year. Values cross-checked to SEC XBRL (Checks sheet).
A7: Non-GAAP figures are company-reported (Q4 earnings releases, 8-K Ex-99.1). Adjusted metrics marked 'analyst' are Bona Fide definitions.
A8: Ratios sheet uses live formulas referencing the statement sheets. $ millions unless stated.

Sheet Income statement
A1: HPE — income statement ($ millions)
A2: Parsed from SEC filings; see README for conventions
A4: Line item | B4: FY2020 | C4: FY2021 | D4: FY2022 | E4: FY2023 | F4: FY2024 | G4: FY2025 | H4: TTM Q3 FY26
A5: revenue | B5: 26982 | C5: 27784 | D5: 28496 | E5: 29135 | F5: 30127 | G5: 34296 | H5: 41871
A6: rev_products | B6: 16264 | C6: 17011 | D6: 17794 | E6: 18100 | F6: 18587 | G6: 21956 | H6: 27979
A7: rev_services | B7: 10249 | C7: 10279 | D7: 10219 | E7: 10488 | F7: 10872 | G7: 11573 | H7: 13113
A8: rev_financing | B8: 469 | C8: 494 | D8: 483 | E8: 547 | F8: 668 | G8: 767 | H8: 779
A9: cost_of_sales | B9: 18513 | C9: 18408 | D9: 18990 | E9: 18896 | F9: 20249 | G9: 23919 | H9: 26491
A10: gross_profit | B10: 8469 | C10: 9376 | D10: 9506 | E10: 10239 | F10: 9878 | G10: 10377 | H10: 15380
A11: rd | B11: 1874 | C11: 1979 | D11: 2045 | E11: 2349 | F11: 2246 | G11: 2518 | H11: 3705
A12: sga | B12: 4624 | C12: 4929 | D12: 4941 | E12: 5160 | F12: 4871 | G12: 5704 | H12: 7132
A13: amortization | B13: 379 | C13: 354 | D13: 293 | E13: 288 | F13: 267 | G13: 511 | H13: 1259
A14: impairment | B14: 865 | C14: 0 | D14: 905 | E14: 0 | F14: 0 | G14: 1621 | H14: 260
A15: transformation | B15: 950 | C15: 930 | D15: 473 | E15: 283 | F15: 93 | G15: 2
A16: disaster | B16: 26 | C16: 16 | D16: 48 | E16: 1 | F16: 7
A17: acq_dispo | B17: 80 | C17: 36 | D17: 19 | E17: 70 | F17: 211 | G17: 458 | H17: 420
A18: operating_income | B18: -329 | C18: 1132 | D18: 782 | E18: 2089 | F18: 2190 | G18: -437 | H18: 2602
A19: pretax_income | B19: -442 | C19: 3587 | D19: 876 | E19: 2230 | F19: 2953 | G19: -285 | H19: 2633
A20: net_income | B20: -322 | C20: 3427 | D20: 868 | E20: 2025 | F20: 2579 | G20: 57 | H20: 2791
A21: preferred_dividends | D21: 0 | E21: 0 | F21: -25 | G21: -116 | H21: -116
A22: eps_diluted | B22: -0.25 | C22: 2.58 | D22: 0.66 | E22: 1.54 | F22: 1.93 | G22: -0.04
A23: shares_basic | B23: 1294 | C23: 1309 | D23: 1303 | E23: 1299 | F23: 1309 | G23: 1324 | H23: 1336
A24: shares_diluted | B24: 1294 | C24: 1330 | D24: 1322 | E24: 1316 | F24: 1337 | G24: 1324 | H24: 1449
A25: d_and_a | B25: 2625 | C25: 2597 | D25: 2480 | E25: 2616 | F25: 2564 | G25: 2737 | H25: 3490
A26: sbc | B26: 274 | C26: 382 | D26: 391 | E26: 428 | F26: 430 | G26: 643 | H26: 795
A27: ebitda | B27: 2296 | C27: 3729 | D27: 3262 | E27: 4705 | F27: 4754 | G27: 2300 | H27: 6092
A28: adj_operating_income_analyst | B28: 2245 | C28: 2850 | D28: 2911 | E28: 3159 | F28: 3198 | G28: 2798 | H28: 5336
A29: adj_ebitda_analyst | B29: 4491 | C29: 5093 | D29: 5098 | E29: 5487 | F29: 5495 | G29: 5024 | H29: 7567
A30: non_gaap_gross_profit | B30: 8543 | C30: 9424 | D30: 9667 | E30: 10273 | F30: 9893 | G30: 10805 | H30: 15787
A31: non_gaap_operating_profit | B31: 2282 | C31: 2848 | D31: 3026 | E31: 3145 | F31: 3168 | G31: 3353 | H31: 5767
A32: non_gaap_net_earnings_hpe | B32: 2005 | C32: 2602 | D32: 2664 | E32: 2832 | F32: 2655 | G32: 2753 | H32: 4569
A33: non_gaap_diluted_eps | B33: 1.54 | C33: 1.96 | D33: 2.02 | E33: 2.15 | F33: 1.99 | G33: 1.94 | H33: 3.17

Sheet Balance sheet
A1: HPE — balance sheet ($ millions)
A2: Parsed from SEC filings; see README for conventions
A4: Line item | B4: FY2020 | C4: FY2021 | D4: FY2022 | E4: FY2023 | F4: FY2024 | G4: FY2025 | H4: TTM Q3 FY26
A5: cash | B5: 4233 | C5: 3996 | D5: 4163 | E5: 4270 | F5: 14846 | G5: 5773 | H5: 6216
A6: accounts_receivable | B6: 3386 | C6: 3979 | D6: 4101 | E6: 3481 | F6: 3550 | G6: 5290 | H6: 6185
A7: financing_receivables_current | B7: 3794 | C7: 3932 | D7: 3522 | E7: 3543 | F7: 3870 | G7: 3826 | H7: 3841
A8: inventory | B8: 2674 | C8: 4511 | D8: 5161 | E8: 4607 | F8: 7810 | G8: 6352 | H8: 11823
A9: current_assets | B9: 16556 | C9: 18878 | D9: 20506 | E9: 18948 | F9: 33457 | G9: 24994 | H9: 33865
A10: lt_financing_receivables_other | B10: 10544 | C10: 11670 | D10: 10537 | E10: 11377 | F10: 12616 | G10: 13817 | H10: 14632
A11: equity_investments | B11: 2170 | C11: 2210 | D11: 2160 | E11: 2197 | F11: 929 | G11: 955 | H11: 0
A12: goodwill_and_intangibles | B12: 19120 | C12: 19328 | D12: 18136 | E12: 18642 | F12: 18596 | G12: 30138 | H12: 29454
A13: total_assets | B13: 54015 | C13: 57699 | D13: 57123 | E13: 57153 | F13: 71262 | G13: 75906 | H13: 83596
A14: short_term_debt | B14: 3755 | C14: 3552 | D14: 4612 | E14: 4868 | F14: 4742 | G14: 4609 | H14: 2901
A15: accounts_payable | B15: 5383 | C15: 7004 | D15: 8717 | E15: 7136 | F15: 11064 | G15: 7731 | H15: 13734
A16: deferred_revenue | B16: 3430 | C16: 3408 | D16: 3451 | E16: 3658 | F16: 3904 | G16: 5358 | H16: 5561
... A22: total_equity | B22: 16096 | C22: 20017 | D22: 19909 | E22: 21238 | F22: 24880 | G22: 24754 | H22: 26576

Sheet Cash flow
A1: HPE — cash flow ($ millions)
A2: Parsed from SEC filings; see README for conventions
A4: Line item | B4: FY2020 | C4: FY2021 | D4: FY2022 | E4: FY2023 | F4: FY2024 | G4: FY2025 | H4: TTM Q3 FY26
A5: cfo | B5: 2240 | C5: 5871 | D5: 4593 | E5: 4428 | F5: 4341 | G5: 2919 | H5: 6694
A6: capex_gross | B6: -2383 | C6: -2502 | D6: -3122 | E6: -2828 | F6: -2367 | G6: -2292 | H6: -2538
A7: ppe_proceeds | B7: 703 | C7: 354 | D7: 602 | E7: 602 | F7: 370 | G7: 380 | H7: 414
A8: capex_net | B8: -1680 | C8: -2148 | D8: -2520 | E8: -2226 | F8: -1997 | G8: -1912 | H8: -2124
A9: fx_effect | B9: 0 | C9: 0 | D9: -279 | E9: 36 | F9: -47 | G9: -21 | H9: -69
A10: fcf_hpe_definition | B10: 560 | C10: 3723 | D10: 1794 | E10: 2238 | F10: 2297 | G10: 986 | H10: 4501
A11: free_cash_flow_reported | B11: 560 | C11: 1551 | D11: 1794 | E11: 2238 | F11: 2297 | G11: 986 | H11: 4501
A12: acquisitions | B12: -866 | C12: -505 | D12: 0 | E12: -761 | F12: -147 | G12: -12278 | H12: 0
A13: debt_issued | B13: 7007 | C13: 3022 | D13: 3296 | E13: 4725 | F13: 11245 | G13: 9188 | H13: 6401
A14: debt_repaid | B14: -5099 | C14: -5465 | D14: -3992 | E14: -4887 | F14: -5475 | G14: -6837 | H14: -9860
A15: preferred_issued | D15: 0 | E15: 0 | F15: 1462 | G15: 0 | H15: 0
A16: buybacks | B16: -355 | C16: -213 | D16: -512 | E16: -421 | F16: -150 | G16: -202 | H16: -547
A17: dividends_common | B17: -618 | C17: -625 | D17: -621 | E17: -619 | F17: -676 | G17: -684 | H17: -739
A18: dividends_preferred | E18: 0 | F18: 0 | G18: -112 | H18: -116
A19: wc_receivables | B19: -461 | C19: -591 | D19: -186 | E19: 577 | F19: -83 | G19: -700 | H19: -567
A20: wc_financing_receivables | B20: -487 | C20: -165 | D20: 694 | E20: -607 | F20: -909 | G20: -153 | H20: -374
A21: wc_inventory | B21: -527 | C21: -1959 | D21: -713 | E21: 400 | F21: -3358 | G21: 1783 | H21: -5449
A22: wc_payables | B22: -225 | C22: 1608 | D22: 1707 | E22: -1655 | F22: 3927 | G22: -3468 | H22: 4997

Sheet Ratios
A1: HPE — ratios (live formulas)
A2: Formulas reference the statement sheets
A4: Ratio | B4: FY2020 | C4: FY2021 | D4: FY2022 | E4: FY2023 | F4: FY2024 | G4: FY2025 | H4: TTM Q3 FY26
A5: Revenue growth YoY | C5: ='Income statement'!$C$5/'Income statement'!$B$5-1 | D5: ='Income statement'!$D$5/'Income statement'!$C$5-1 | E5: ='Income statement'!$E$5/'Income statement'!$D$5-1 | F5: ='Income statement'!$F$5/'Income statement'!$E$5-1 | G5: ='Income statement'!$G$5/'Income statement'!$F$5-1
A6: Gross margin (GAAP) | B6: ='Income statement'!$B$10/'Income statement'!$B$5 | C6: ='Income statement'!$C$10/'Income statement'!$C$5 | D6: ='Income statement'!$D$10/'Income statement'!$D$5 | E6: ='Income statement'!$E$10/'Income statement'!$E$5 | F6: ='Income statement'!$F$10/'Income statement'!$F$5 | G6: ='Income statement'!$G$10/'Income statement'!$G$5 | H6: ='Income statement'!$H$10/'Income statement'!$H$5
A7: Gross margin (non-GAAP) | B7: ='Income statement'!$B$30/'Income statement'!$B$5 | C7: ='Income statement'!$C$30/'Income statement'!$C$5 | D7: ='Income statement'!$D$30/'Income statement'!$D$5 | E7: ='Income statement'!$E$30/'Income statement'!$E$5 | F7: ='Income statement'!$F$30/'Income statement'!$F$5 | G7: ='Income statement'!$G$30/'Income statement'!$G$5 | H7: ='Income statement'!$H$30/'Income statement'!$H$5
A8: Operating margin (GAAP) | B8: ='Income statement'!$B$18/'Income statement'!$B$5 | C8: ='Income statement'!$C$18/'Income statement'!$C$5 | D8: ='Income statement'!$D$18/'Income statement'!$D$5 | E8: ='Income statement'!$E$18/'Income statement'!$E$5 | F8: ='Income statement'!$F$18/'Income statement'!$F$5 | G8: ='Income statement'!$G$18/'Income statement'!$G$5 | H8: ='Income statement'!$H$18/'Income statement'!$H$5
A9: Operating margin (non-GAAP) | B9: ='Income statement'!$B$31/'Income statement'!$B$5 | C9: ='Income statement'!$C$31/'Income statement'!$C$5 | D9: ='Income statement'!$D$31/'Income statement'!$D$5 | E9: ='Income statement'!$E$31/'Income statement'!$E$5 | F9: ='Income statement'!$F$31/'Income statement'!$F$5 | G9: ='Income statement'!$G$31/'Income statement'!$G$5 | H9: ='Income statement'!$H$31/'Income statement'!$H$5
A10: Net margin | B10: ='Income statement'!$B$20/'Income statement'!$B$5 | C10: ='Income statement'!$C$20/'Income statement'!$C$5 | D10: ='Income statement'!$D$20/'Income statement'!$D$5 | E10: ='Income statement'!$E$20/'Income statement'!$E$5 | F10: ='Income statement'!$F$20/'Income statement'!$F$5 | G10: ='Income statement'!$G$20/'Income statement'!$G$5 | H10: ='Income statement'!$H$20/'Income statement'!$H$5
A11: EBITDA margin (GAAP OP + D&A) | B11: ='Income statement'!$B$27/'Income statement'!$B$5 | C11: ='Income statement'!$C$27/'Income statement'!$C$5 | D11: ='Income statement'!$D$27/'Income statement'!$D$5 | E11: ='Income statement'!$E$27/'Income statement'!$E$5 | F11: ='Income statement'!$F$27/'Income statement'!$F$5 | G11: ='Income statement'!$G$27/'Income statement'!$G$5 | H11: ='Income statement'!$H$27/'Income statement'!$H$5
A12: FCF margin (HPE definition) | B12: ='Cash flow'!$B$10/'Income statement'!$B$5 | C12: ='Cash flow'!$C$10/'Income statement'!$C$5 | D12: ='Cash flow'!$D$10/'Income statement'!$D$5 | E12: ='Cash flow'!$E$10/'Income statement'!$E$5 | F12: ='Cash flow'!$F$10/'Income statement'!$F$5 | G12: ='Cash flow'!$G$10/'Income statement'!$G$5 | H12: ='Cash flow'!$H$10/'Income statement'!$H$5
A13: SBC % revenue | B13: ='Income statement'!$B$26/'Income statement'!$B$5 | C13: ='Income statement'!$C$26/'Income statement'!$C$5 | D13: ='Income statement'!$D$26/'Income statement'!$D$5 | E13: ='Income statement'!$E$26/'Income statement'!$E$5 | F13: ='Income statement'!$F$26/'Income statement'!$F$5 | G13: ='Income statement'!$G$26/'Income statement'!$G$5 | H13: ='Income statement'!$H$26/'Income statement'!$H$5
A14: R&D % revenue | B14: ='Income statement'!$B$11/'Income statement'!$B$5 | C14: ='Income statement'!$C$11/'Income statement'!$C$5 | D14: ='Income statement'!$D$11/'Income statement'!$D$5 | E14: ='Income statement'!$E$11/'Income statement'!$E$5 | F14: ='Income statement'!$F$11/'Income statement'!$F$5 | G14: ='Income statement'!$G$11/'Income statement'!$G$5 | H14: ='Income statement'!$H$11/'Income statement'!$H$5
A15: Net capex % revenue | B15: =-'Cash flow'!$B$8/'Income statement'!$B$5 | C15: =-'Cash flow'!$C$8/'Income statement'!$C$5 | D15: =-'Cash flow'!$D$8/'Income statement'!$D$5 | E15: =-'Cash flow'!$E$8/'Income statement'!$E$5 | F15: =-'Cash flow'!$F$8/'Income statement'!$F$5 | G15: =-'Cash flow'!$G$8/'Income statement'!$G$5 | H15: =-'Cash flow'!$H$8/'Income statement'!$H$5
A16: Current ratio | B16: ='Balance sheet'!$B$9/'Balance sheet'!$B$17 | C16: ='Balance sheet'!$C$9/'Balance sheet'!$C$17 | D16: ='Balance sheet'!$D$9/'Balance sheet'!$D$17 | E16: ='Balance sheet'!$E$9/'Balance sheet'!$E$17 | F16: ='Balance sheet'!$F$9/'Balance sheet'!$F$17 | G16: ='Balance sheet'!$G$9/'Balance sheet'!$G$17 | H16: ='Balance sheet'!$H$9/'Balance sheet'!$H$17
A17: Debt / equity | B17: ='Balance sheet'!$B$19/'Balance sheet'!$B$22 | C17: ='Balance sheet'!$C$19/'Balance sheet'!$C$22 | D17: ='Balance sheet'!$D$19/'Balance sheet'!$D$22 | E17: ='Balance sheet'!$E$19/'Balance sheet'!$E$22 | F17: ='Balance sheet'!$F$19/'Balance sheet'!$F$22 | G17: ='Balance sheet'!$G$19/'Balance sheet'!$G$22 | H17: ='Balance sheet'!$H$19/'Balance sheet'!$H$22
A18: Net debt / adj. EBITDA (analyst) | B18: ='Balance sheet'!$B$20/'Income statement'!$B$29 | C18: ='Balance sheet'!$C$20/'Income statement'!$C$29 | D18: ='Balance sheet'!$D$20/'Income statement'!$D$29 | E18: ='Balance sheet'!$E$20/'Income statement'!$E$29 | F18: ='Balance sheet'!$F$20/'Income statement'!$F$29 | G18: ='Balance sheet'!$G$20/'Income statement'!$G$29 | H18: ='Balance sheet'!$H$20/'Income statement'!$H$29
A19: DSO (days) | B19: ='Balance sheet'!$B$6/'Income statement'!$B$5*365 | C19: ='Balance sheet'!$C$6/'Income statement'!$C$5*365 | D19: ='Balance sheet'!$D$6/'Income statement'!$D$5*365 | E19: ='Balance sheet'!$E$6/'Income statement'!$E$5*365 | F19: ='Balance sheet'!$F$6/'Income statement'!$F$5*365 | G19: ='Balance sheet'!$G$6/'Income statement'!$G$5*365 | H19: ='Balance sheet'!$H$6/'Income statement'!$H$5*365
A20: DIO (days) | B20: ='Balance sheet'!$B$8/'Income statement'!$B$9*365 | C20: ='Balance sheet'!$C$8/'Income statement'!$C$9*365 | D20: ='Balance sheet'!$D$8/'Income statement'!$D$9*365 | E20: ='Balance sheet'!$E$8/'Income statement'!$E$9*365 | F20: ='Balance sheet'!$F$8/'Income statement'!$F$9*365 | G20: ='Balance sheet'!$G$8/'Income statement'!$G$9*365 | H20: ='Balance sheet'!$H$8/'Income statement'!$H$9*365
A21: DPO (days) | B21: ='Balance sheet'!$B$15/'Income statement'!$B$9*365 | C21: ='Balance sheet'!$C$15/'Income statement'!$C$9*365 | D21: ='Balance sheet'!$D$15/'Income statement'!$D$9*365 | E21: ='Balance sheet'!$E$15/'Income statement'!$E$9*365 | F21: ='Balance sheet'!$F$15/'Income statement'!$F$9*365 | G21: ='Balance sheet'!$G$15/'Income statement'!$G$9*365 | H21: ='Balance sheet'!$H$15/'Income statement'!$H$9*365
A22: FCF / diluted share ($) | B22: ='Cash flow'!$B$10/'Income statement'!$B$24 | C22: ='Cash flow'!$C$10/'Income statement'!$C$24 | D22: ='Cash flow'!$D$10/'Income statement'!$D$24 | E22: ='Cash flow'!$E$10/'Income statement'!$E$24 | F22: ='Cash flow'!$F$10/'Income statement'!$F$24 | G22: ='Cash flow'!$G$10/'Income statement'!$G$24 | H22: ='Cash flow'!$H$10/'Income statement'!$H$24
A23: Goodwill & intangibles % assets | B23: ='Balance sheet'!$B$12/'Balance sheet'!$B$13 | C23: ='Balance sheet'!$C$12/'Balance sheet'!$C$13 | D23: ='Balance sheet'!$D$12/'Balance sheet'!$D$13 | E23: ='Balance sheet'!$E$12/'Balance sheet'!$E$13 | F23: ='Balance sheet'!$F$12/'Balance sheet'!$F$13 | G23: ='Balance sheet'!$G$12/'Balance sheet'!$G$13 | H23: ='Balance sheet'!$H$12/'Balance sheet'!$H$13
A26: Note: TTM growth vs FY2025 is not a like-for-like YoY rate (TTM vs prior TTM = +30.8%).

Sheet Non-GAAP (company)
A1: Company-reported non-GAAP measures
A2: Keyed from Q4 earnings releases and the Q3 FY26 release
B4: metric | C4: value | D4: source_file | E4: note
A5: FY2020 | B5: non_gaap_gross_profit | C5: 8543 | D5: report/earnings_materials/sec_8k_ex99/HPE_8-K_Ex99-1_earnings_2021-11-30.htm
A6: FY2020 | B6: non_gaap_operating_profit | C6: 2282 | D6: report/earnings_materials/sec_8k_ex99/HPE_8-K_Ex99-1_earnings_2021-11-30.htm
A7: FY2020 | B7: non_gaap_net_earnings_hpe | C7: 2005 | D7: report/earnings_materials/sec_8k_ex99/HPE_8-K_Ex99-1_earnings_2021-11-30.htm
A8: FY2020 | B8: non_gaap_diluted_eps | C8: 1.54 | D8: report/earnings_materials/sec_8k_ex99/HPE_8-K_Ex99-1_earnings_2021-11-30.htm
A9: FY2020 | B9: free_cash_flow_reported | C9: 560 | D9: report/earnings_materials/sec_8k_ex99/HPE_8-K_Ex99-1_earnings_2021-11-30.htm
A10: FY2021 | B10: non_gaap_gross_profit | C10: 9424 | D10: report/earnings_materials/sec_8k_ex99/HPE_8-K_Ex99-1_earnings_2022-11-29.htm
A11: FY2021 | B11: non_gaap_operating_profit | C11: 2848 | D11: report/earnings_materials/sec_8k_ex99/HPE_8-K_Ex99-1_earnings_2022-11-29.htm
A12: FY2021 | B12: non_gaap_net_earnings_hpe | C12: 2602 | D12: report/earnings_materials/sec_8k_ex99/HPE_8-K_Ex99-1_earnings_2022-11-29.htm
A13: FY2021 | B13: non_gaap_diluted_eps | C13: 1.96 | D13: report/earnings_materials/sec_8k_ex99/HPE_8-K_Ex99-1_earnings_2022-11-29.htm
A14: FY2021 | B14: free_cash_flow_reported | C14: 1551 | D14: report/earnings_materials/sec_8k_ex99/HPE_8-K_Ex99-1_earnings_2022-11-29.htm | E14: Explained difference: CFO-based FCF is $3,723m; the $2.17bn gap is consistent with FY21 Oracle litigation-judgment cash (GAAP line $2,351m) being excluded from reported FCF (analyst reconciliation)
A15: FY2022 | B15: non_gaap_gross_profit | C15: 9667 | D15: report/earnings_materials/sec_8k_ex99/HPE_8-K_Ex99-1_earnings_2023-11-28.htm
A16: FY2022 | B16: non_gaap_operating_profit | C16: 3026 | D16: report/earnings_materials/sec_8k_ex99/HPE_8-K_Ex99-1_earnings_2023-11-28.htm
A17: FY2022 | B17: non_gaap_net_earnings_hpe | C17: 2664 | D17: report/earnings_materials/sec_8k_ex99/HPE_8-K_Ex99-1_earnings_2023-11-28.htm
A18: FY2022 | B18: non_gaap_diluted_eps | C18: 2.02 | D18: report/earnings_materials/sec_8k_ex99/HPE_8-K_Ex99-1_earnings_2023-11-28.htm
A19: FY2022 | B19: free_cash_flow_reported | C19: 1794 | D19: report/earnings_materials/sec_8k_ex99/HPE_8-K_Ex99-1_earnings_2023-11-28.htm
A20: FY2023 | B20: non_gaap_gross_profit | C20: 10273 | D20: report/earnings_materials/sec_8k_ex99/HPE_8-K_Ex99-1_earnings_2024-12-05.htm
A21: FY2023 | B21: non_gaap_operating_profit | C21: 3145 | D21: report/earnings_materials/sec_8k_ex99/HPE_8-K_Ex99-1_earnings_2024-12-05.htm
A22: FY2023 | B22: non_gaap_net_earnings_hpe | C22: 2832 | D22: report/earnings_materials/sec_8k_ex99/HPE_8-K_Ex99-1_earnings_2024-12-05.htm
A23: FY2023 | B23: non_gaap_diluted_eps | C23: 2.15 | D23: report/earnings_materials/sec_8k_ex99/HPE_8-K_Ex99-1_earnings_2024-12-05.htm
A24: FY2023 | B24: free_cash_flow_reported | C24: 2238 | D24: report/earnings_materials/sec_8k_ex99/HPE_8-K_Ex99-1_earnings_2024-12-05.htm
A25: FY2024 | B25: non_gaap_gross_profit | C25: 9893 | D25: report/earnings_materials/sec_8k_ex99/HPE_8-K_Ex99-1_earnings_2025-12-04.htm
A26: FY2024 | B26: non_gaap_operating_profit | C26: 3168 | D26: report/earnings_materials/sec_8k_ex99/HPE_8-K_Ex99-1_earnings_2025-12-04.htm
... A34: FY2025 | B34: free_cash_flow_reported | C34: 986 | D34: report/earnings_materials/sec_8k_ex99/HPE_8-K_Ex99-1_earnings_2025-12-04.htm
A35: TTM Q3 FY26 | B35: non_gaap_gross_profit | C35: 15787 | D35: report/earnings_materials/FY2026Q3/HPE_Q3FY26_earnings-press-release.pdf | E35: FY25 10805 + 9M FY26 12268 - 9M FY25 7286
A36: TTM Q3 FY26 | B36: non_gaap_operating_profit | C36: 5767 | D36: report/earnings_materials/FY2026Q3/HPE_Q3FY26_earnings-press-release.pdf | E36: FY25 3353 + 9M FY26 4584 - 9M FY25 2170
A37: TTM Q3 FY26 | B37: non_gaap_net_earnings_hpe | C37: 4569 | D37: report/earnings_materials/FY2026Q3/HPE_Q3FY26_earnings-press-release.pdf | E37: FY25 2753 + 9M FY26 3676 - 9M FY25 1860
A38: TTM Q3 FY26 | B38: non_gaap_diluted_eps | C38: 3.17 | D38: report/earnings_materials/FY2026Q3/HPE_Q3FY26_earnings-press-release.pdf | E38: Q4 FY25 0.62 + 9M FY26 2.55
A39: TTM Q3 FY26 | B39: free_cash_flow_reported | C39: 4501 | D39: report/earnings_materials/FY2026Q3/HPE_Q3FY26_earnings-press-release.pdf | E39: FY25 986 + 9M FY26 2581 - 9M FY25 (934)

Sheet Segments
A1: Segments (FY26 structure, recast)
A2: Quarterly; Q2 FY25 derived from nine-month totals
B4: period_end | C4: segment | D4: line | E4: revenue | F4: operating_profit | G4: source
A5: Q1 FY25 | B5: 2025-01-31 | C5: Networking | D5: Total | E5: 1076 | F5: 320 | G5: Q1 FY26 earnings release (recast prior-year column)
A6: Q1 FY25 | B6: 2025-01-31 | C6: Cloud & AI | D6: Total | E6: 6511 | F6: 547 | G6: Q1 FY26 earnings release (recast prior-year column)
A7: Q1 FY25 | B7: 2025-01-31 | C7: Corporate Investments and Other | D7: Total | E7: 267 | F7: -8 | G7: Q1 FY26 earnings release (recast prior-year column)
A8: Q1 FY25 | B8: 2025-01-31 | C8: Networking | D8: Campus & Branch | E8: 864 | G8: Q1 FY26 earnings release
A9: Q1 FY25 | B9: 2025-01-31 | C9: Networking | D9: Data Center Networking | E9: 92 | G9: Q1 FY26 earnings release
A10: Q1 FY25 | B10: 2025-01-31 | C10: Networking | D10: Security | E10: 119 | G10: Q1 FY26 earnings release
A11: Q1 FY25 | B11: 2025-01-31 | C11: Networking | D11: Routing | E11: 1 | G11: Q1 FY26 earnings release
A12: Q1 FY25 | B12: 2025-01-31 | C12: Cloud & AI | D12: Server | E12: 4348 | G12: Q1 FY26 earnings release
A13: Q1 FY25 | B13: 2025-01-31 | C13: Cloud & AI | D13: Storage | E13: 1055 | G13: Q1 FY26 earnings release
A14: Q1 FY25 | B14: 2025-01-31 | C14: Cloud & AI | D14: Financial Services | E14: 873 | G14: Q1 FY26 earnings release
A15: Q1 FY25 | B15: 2025-01-31 | C15: Cloud & AI | D15: Other | E15: 235 | G15: Q1 FY26 earnings release
A16: Q2 FY25 | B16: 2025-04-30 | C16: Networking | D16: Total | E16: 1084 | F16: 271 | G16: Derived: 9M FY25 (Q3 FY26 release) less Q1 and Q3 FY25
A17: Q2 FY25 | B17: 2025-04-30 | C17: Cloud & AI | D17: Total | E17: 6271 | F17: 414 | G17: Derived: 9M FY25 (Q3 FY26 release) less Q1 and Q3 FY25
A18: Q2 FY25 | B18: 2025-04-30 | C18: Corporate Investments and Other | D18: Total | E18: 272 | F18: -7 | G18: Derived: 9M FY25 (Q3 FY26 release) less Q1 and Q3 FY25
A19: Q2 FY25 | B19: 2025-04-30 | C19: Networking | D19: Campus & Branch | E19: 880 | G19: Derived: 9M FY25 less Q1 and Q3 FY25
A20: Q2 FY25 | B20: 2025-04-30 | C20: Networking | D20: Data Center Networking | E20: 96 | G20: Derived: 9M FY25 less Q1 and Q3 FY25
A21: Q2 FY25 | B21: 2025-04-30 | C21: Networking | D21: Security | E21: 107 | G21: Derived: 9M FY25 less Q1 and Q3 FY25
A22: Q2 FY25 | B22: 2025-04-30 | C22: Networking | D22: Routing | E22: 1 | G22: Derived: 9M FY25 less Q1 and Q3 FY25
A23: Q2 FY25 | B23: 2025-04-30 | C23: Cloud & AI | D23: Server | E23: 4109 | G23: Derived: 9M FY25 less Q1 and Q3 FY25
A24: Q2 FY25 | B24: 2025-04-30 | C24: Cloud & AI | D24: Storage | E24: 1148 | G24: Derived: 9M FY25 less Q1 and Q3 FY25
A25: Q2 FY25 | B25: 2025-04-30 | C25: Cloud & AI | D25: Financial Services | E25: 856 | G25: Derived: 9M FY25 less Q1 and Q3 FY25
A26: Q2 FY25 | B26: 2025-04-30 | C26: Cloud & AI | D26: Other | E26: 158 | G26: Derived: 9M FY25 less Q1 and Q3 FY25
A27: Q3 FY25 | B27: 2025-07-31 | C27: Networking | D27: Total | E27: 1654 | F27: 365 | G27: Q3 FY26 earnings release (recast prior-year column)
A28: Q3 FY25 | B28: 2025-07-31 | C28: Cloud & AI | D28: Total | E28: 7212 | F28: 504 | G28: Q3 FY26 earnings release (recast prior-year column)
A29: Q3 FY25 | B29: 2025-07-31 | C29: Corporate Investments and Other | D29: Total | E29: 270 | F29: -19 | G29: Q3 FY26 earnings release (recast prior-year column)
A30: Q3 FY25 | B30: 2025-07-31 | C30: Networking | D30: Campus & Branch | E30: 1101 | G30: Q3 FY26 earnings release
A31: Q3 FY25 | B31: 2025-07-31 | C31: Networking | D31: Data Center Networking | E31: 180 | G31: Q3 FY26 earnings release
A32: Q3 FY25 | B32: 2025-07-31 | C32: Networking | D32: Security | E32: 160 | G32: Q3 FY26 earnings release
A33: Q3 FY25 | B33: 2025-07-31 | C33: Networking | D33: Routing | E33: 213 | G33: Q3 FY26 earnings release
A34: Q3 FY25 | B34: 2025-07-31 | C34: Cloud & AI | D34: Server | E34: 5000 | G34: Q3 FY26 earnings release
A35: Q3 FY25 | B35: 2025-07-31 | C35: Cloud & AI | D35: Storage | E35: 1171 | G35: Q3 FY26 earnings release
A36: Q3 FY25 | B36: 2025-07-31 | C36: Cloud & AI | D36: Financial Services | E36: 886 | G36: Q3 FY26 earnings release
A37: Q3 FY25 | B37: 2025-07-31 | C37: Cloud & AI | D37: Other | E37: 155 | G37: Q3 FY26 earnings release
A38: Q4 FY25 | B38: 2025-10-31 | C38: Networking | D38: Total | E38: 2722 | F38: 638 | G38: Q1 FY26 earnings release (recast sequential column)
A39: Q4 FY25 | B39: 2025-10-31 | C39: Cloud & AI | D39: Total | E39: 6676 | F39: 620 | G39: Q1 FY26 earnings release (recast sequential column)
A40: Q4 FY25 | B40: 2025-10-31 | C40: Corporate Investments and Other | D40: Total | E40: 281 | F40: 5 | G40: Q1 FY26 earnings release (recast sequential column)
A41: Q4 FY25 | B41: 2025-10-31 | C41: Networking | D41: Campus & Branch | E41: 1284 | G41: Q1 FY26 earnings release
...

Sheet Checks
A1: Reconciliation checks
A2: Parsed statements vs SEC XBRL, balance sheet identity, TTM and FCF reconciliations
B4: parsed | C4: reference | D4: diff_pct | E4: passed | F4: note
A5: revenue FY2021: parsed vs XBRL | B5: 27784 | C5: 27784 | D5: 0 | E5: 1
A6: revenue FY2022: parsed vs XBRL | B6: 28496 | C6: 28496 | D6: 0 | E6: 1
A7: revenue FY2023: parsed vs XBRL | B7: 29135 | C7: 29135 | D7: 0 | E7: 1
A8: revenue FY2024: parsed vs XBRL | B8: 30127 | C8: 30127 | D8: 0 | E8: 1
A9: revenue FY2025: parsed vs XBRL | B9: 34296 | C9: 34296 | D9: 0 | E9: 1
A10: operating_income FY2021: parsed vs XBRL | B10: 1132 | C10: 1132 | D10: 0 | E10: 1
A11: operating_income FY2022: parsed vs XBRL | B11: 782 | C11: 782 | D11: 0 | E11: 1
A12: operating_income FY2023: parsed vs XBRL | B12: 2089 | C12: 2089 | D12: 0 | E12: 1
A13: operating_income FY2024: parsed vs XBRL | B13: 2190 | C13: 2190 | D13: 0 | E13: 1
A14: operating_income FY2025: parsed vs XBRL | B14: -437 | C14: -437 | D14: 0 | E14: 1
A15: cfo FY2021: parsed vs XBRL | B15: 5871 | C15: 5871 | D15: 0 | E15: 1
A16: cfo FY2022: parsed vs XBRL | B16: 4593 | C16: 4593 | D16: 0 | E16: 1
... A38: FCF (HPE definition) FY2020 vs company-reported | B38: 560 | C38: 560 | D38: 0 | E38: 1
A39: FCF (HPE definition) FY2021 vs company-reported | B39: 3723 | C39: 1551 | D39: 1.4003868 | E39: 1 | F39: explained difference (see hpe_non_gaap_annual.csv)
A40: FCF (HPE definition) FY2022 vs company-reported | B40: 1794 | C40: 1794 | D40: 0 | E40: 1
A41: FCF (HPE definition) FY2023 vs company-reported | B41: 2238 | C41: 2238 | D41: 0 | E41: 1
A42: FCF (HPE definition) FY2024 vs company-reported | B42: 2297 | C42: 2297 | D42: 0 | E42: 1
A43: FCF (HPE definition) FY2025 vs company-reported | B43: 986 | C43: 986 | D43: 0 | E43: 1
A44: FCF (HPE definition) TTM Q3 FY26 vs company-reported | B44: 4501 | C44: 4501 | D44: 0 | E44: 1

Sheet Statistics
A1: Statistical analysis (statsmodels)
A2: Regressions with Newey-West HAC errors; SARIMA revenue baseline; return diagnostics — see code/statistical_analysis.py
A4: R1: HPE revenue growth (YoY) on cloud capex growth, lags 0–2, Juniper dummy
A5: Unnamed: 0 | B5: coef | C5: std_err_hac | D5: t | E5: p_value | F5: ci_low | G5: ci_high
A6: const | B6: -0.04408906 | C6: 0.030792581 | D6: -1.4318079 | E6: 0.15219881 | F6: -0.10444141 | G6: 0.01626329
A7: capex_yoy_lag0 | B7: 0.098039618 | C7: 0.0654475 | D7: 1.4979887 | E7: 0.13413617 | F7: -0.030235124 | G7: 0.22631436
A8: capex_yoy_lag1 | B8: 0.11911698 | C8: 0.068582407 | D8: 1.7368446 | E8: 0.082414605 | F8: -0.015302065 | G8: 0.25353603
A9: capex_yoy_lag2 | B9: -0.026347439 | C9: 0.036390733 | D9: -0.72401506 | E9: 0.46905649 | F9: -0.097671965 | G9: 0.044977087
A10: juniper_dummy | B10: 0.15427056 | C10: 0.044401856 | D10: 3.474417 | E10: 0.00051196476 | F10: 0.067244524 | G10: 0.2412966
A13: R1b: same, pre-Juniper quarters only
A14: Unnamed: 0 | B14: coef | C14: std_err_hac | D14: t | E14: p_value | F14: ci_low | G14: ci_high
A15: const | B15: -0.041893633 | C15: 0.030422195 | D15: -1.3770746 | E15: 0.16848917 | F15: -0.10152004 | G15: 0.017732773
A16: capex_yoy_lag0 | B16: 0.083835802 | C16: 0.065291128 | D16: 1.2840305 | E16: 0.19913127 | F16: -0.044132458 | G16: 0.21180406
A17: capex_yoy_lag1 | B17: 0.12570318 | C17: 0.069553396 | D17: 1.8072903 | E17: 0.070717029 | F17: -0.010618974 | G17: 0.26202533
A18: capex_yoy_lag2 | B18: -0.026469243 | C18: 0.037388299 | D18: -0.70795527 | E18: 0.47897304 | F18: -0.099748962 | G18: 0.046810476
A21: R2: change in HPE gross margin (pp) on change in Micron gross margin (pp)
A22: Unnamed: 0 | B22: coef | C22: std_err_hac | D22: t | E22: p_value | F22: ci_low | G22: ci_high
A23: const | B23: -0.23492262 | C23: 0.73039789 | D23: -0.3216365 | E23: 0.74772809 | F23: -1.6664762 | G23: 1.1966309
A24: micron_gm_change_lag0 | B24: -0.045946747 | C24: 0.014877895 | D24: -3.0882559 | E24: 0.0020133504 | F24: -0.075106886 | G24: -0.016786608
A25: micron_gm_change_lag1 | B25: 0.0091257435 | C25: 0.02530756 | D25: 0.36059358 | E25: 0.71840329 | F25: -0.040476162 | G25: 0.058727649
A26: micron_gm_change_lag2 | B26: -0.023128387 | C26: 0.030961817 | D26: -0.74699707 | E26: 0.45506533 | F26: -0.083812433 | G26: 0.03755566
A27: juniper_dummy | B27: 6.8131262 | C27: 2.0223087 | D27: 3.3689843 | E27: 0.00075445738 | F27: 2.8494739 | G27: 10.776778
A30: SARIMA model selection by AICc (top 8)
A31: order | B31: seasonal | C31: aicc | D31: aic | E31: converged
A32: (0, 0, 1) | B32: (0, 0, 0) | C32: -80.76052 | D32: -81.683597 | E32: True
A33: (1, 0, 0) | B33: (0, 0, 0) | C33: -79.225069 | D33: -80.148146 | E33: True
A34: (1, 0, 1) | B34: (1, 0, 0) | C34: -79.043316 | D34: -81.543316 | E34: True
A35: (2, 0, 0) | B35: (0, 0, 0) | C35: -78.009795 | D35: -79.609795 | E35: True
A36: (2, 1, 0) | B36: (0, 0, 0) | C36: -77.662297 | D36: -78.585374 | E36: True
A37: (2, 0, 0) | B37: (1, 0, 0) | C37: -77.101927 | D37: -79.601927 | E37: True
A38: (0, 1, 0) | B38: (1, 0, 0) | C38: -76.846081 | D38: -77.290526 | E38: True
A39: (1, 1, 1) | B39: (1, 0, 0) | C39: -76.439021 | D39: -78.039021 | E39: True
A42: One-step rolling backtest, last 8 pre-Juniper quarters ($m)
A43: quarter | B43: actual | C43: arima | D43: random_walk | E43: seasonal_naive
A44: 2023Q2 | B44: 7002 | C44: 6979.3527 | D44: 6973 | E44: 6951
A45: 2023Q3 | B45: 7351 | C45: 7188.7214 | D45: 7002 | E45: 7871
A46: 2023Q4 | B46: 6755 | C46: 7288.7271 | D46: 7351 | E46: 7809
A47: 2024Q1 | B47: 7204 | C47: 6814.3311 | D47: 6755 | E47: 6973
A48: 2024Q2 | B48: 7710 | C48: 7398.1847 | D48: 7204 | E48: 7002
A49: 2024Q3 | B49: 8458 | C49: 7360.646 | D49: 7710 | E49: 7351
...
