Workbook

Sheet HPE notes
A1: HPE — how this Damodaran FCFF Ginzu was completed
A2: Bona Fide Student Investment Society · valuation date 2026-09-11 · template: pages.stern.nyu.edu/~adamodar (fcffsimpleginzu.xlsx)
A4: Result | B4: Damodaran Ginzu | C4: Bona Fide DCF | D4: Why they differ
A5: Unlevered beta | B5: 1.2110393 | C5: 1.1476846 | D5: Ginzu weights industry betas by estimated value (EV/Sales × revenue); Bona Fide weights by segment profit
A6: Levered beta | B6: 1.4175048 | C6: 1.3522319 | D6: Ginzu relevers at market value of debt (maturity-adjusted) vs book debt in the Bona Fide build
A7: Equity risk premium | B7: 0.052662474 | C7: 0.0397 | D7: Ginzu: Damodaran Jan-2026 regional ERPs (mature 4.23% + country risk) weighted by HPE revenue; Bona Fide: US implied ERP 3.97%
A8: Cost of equity | B8: 0.12414931 | C8: 0.10318361
A9: Pre-tax cost of debt | B9: 0.060613 | C9: 0.060613 | D9: Both: risk-free + Baa2/BBB spread 1.11%
A10: Cost of capital | B10: 0.11061227 | C10: 0.093004389 | D10: Mostly the higher, geographically weighted ERP
A11: Value per share ($) | B11: 31.568472 | C11: 38.796741 | D11: Ginzu also moves tax to the 21% marginal rate after year 5 and uses Damodaran's reinvestment and terminal ROIC conventions
A12: Share price ($) | B12: 62.09 | C12: 62.09 | D12: 11-Sep-2026 close
A14: Every input changed from the template
A15: Sheet | B15: Cell | C15: Value | D15: Source / rationale
A16: Input sheet | B16: B3 | C16: 2026-09-11 | D16: Valuation date: 11-Sep-2026 close
A17: Input sheet | B17: B4 | C17: Hewlett Packard Enterprise | D17: Company
A18: Input sheet | B18: B7 | C18: United States | D18: Country of incorporation (10-K)
A19: Input sheet | B19: B8 | C19: Computers/Peripherals | D19: Primary US industry (Damodaran classification)
A20: Input sheet | B20: B9 | C20: Computers/Peripherals | D20: Primary global industry
A21: Input sheet | B21: B11 | C21: 41871 | D21: TTM revenue to 31-Jul-2026 = FY25 + 9M FY26 − 9M FY25 (10-K, 10-Q)
A22: Input sheet | B22: C11 | C22: 34296 | D22: FY2025 revenue (10-K)
A23: Input sheet | B23: D11 | C23: 0.75 | D23: Years since last 10-K (31-Oct-2025 → 31-Jul-2026)
A24: Input sheet | B24: B12 | C24: 4972 | D24: TTM EBIT = company non-GAAP operating profit less SBC (SBC treated as an expense)
A25: Input sheet | B25: C12 | C25: 2710 | D25: FY2025 non-GAAP operating profit less SBC
A26: Input sheet | B26: B13 | C26: 1018 | D26: Interest expense: FY2025 cash interest paid (10-K cash-flow supplement); no quarterly split disclosed
A27: Input sheet | B27: C13 | C27: 1018 | D27: Same as above
A28: Input sheet | B28: B14 | C28: 26576 | D28: Book equity 31-Jul-2026 (Q3 FY26 balance sheet)
A29: Input sheet | B29: C14 | C29: 24754 | D29: Book equity 31-Oct-2025
A30: Input sheet | B30: B15 | C30: 20244 | D30: Gross debt 31-Jul-2026 incl. Financial Services debt
A31: Input sheet | B31: C15 | C31: 22365 | D31: Gross debt 31-Oct-2025
A32: Input sheet | B32: B16 | C32: No | D32: R&D not capitalised (HPE R&D is ~7–9% of revenue and recurring)
A33: Input sheet | B33: B17 | C33: No | D33: Leases already on balance sheet under ASC 842; not re-capitalised
A34: Input sheet | B34: B18 | C34: 6216 | D34: Cash and equivalents 31-Jul-2026
A35: Input sheet | B35: C18 | C35: 5773 | D35: Cash and equivalents 31-Oct-2025
A36: Input sheet | B36: B19 | C36: 0 | D36: No cross-holdings: remaining H3C stake sold May-2026
A37: Input sheet | B37: C19 | C37: 955 | D37: Equity-method investments 31-Oct-2025 (H3C)
A38: Input sheet | B38: B20 | C38: 62 | D38: Non-controlling interests 31-Jul-2026
A39: Input sheet | B39: C20 | C39: 66 | D39: Non-controlling interests 31-Oct-2025
A40: Input sheet | B40: B21 | C40: 1445.21 | D40: Fully diluted shares: basic 1,328m + RSUs 37m + preferred as converted 76.1m + Oracle warrant 4.2m
A41: Input sheet | B41: B22 | C41: 62.09 | D41: Share price, 11-Sep-2026 close
A42: Input sheet | B42: B23 | C42: 0.17 | D42: Effective tax rate: HPE structural non-GAAP rate 14% plus cash-tax leakage (Bona Fide assumption)
...

Sheet Input sheet
C1: Input cell | E1: Calculated cell
A3: Date of valuation | B3: 44814 | C3: Important: Before you run this spreadsheet, go into preferences in Excel and check under Calculation options
A4: Company name | B4: Hewlett Packard Enterprise | C4: There should be a check against the iteration box. If there is not, you will get circular reasoning errors.
A5: Numbers from your base year below ( in consistent units, i.e., if you enter numbers in millions, stay with millions all the way through, including on share count.
A6: If you don't understand an input, turn on comemnts and you should see my suggestions on that input.
A7: Country of incorporation | B7: United States | F7: If you want a guide through this spreadsheet, try this YouTube video that takes you through each input cell: https://youtu.be/kyKfJ_7-mdg?si=FIeHhnLH2_2brag3
A8: Industry (US) | B8: Computers/Peripherals
A9: Industry (Global) | B9: Computers/Peripherals
B10: Most Recent 12 months | C10: Last 10K before LTM | D10: Years since last 10K
A11: Revenues | B11: 41871 | C11: 34296 | D11: 0.75
A12: Operating income or EBIT | B12: 4972 | C12: 2710
A13: Interest expense | B13: 1018 | C13: 1018
A14: Book value of equity | B14: 26576 | C14: 24754
A15: Book value of debt | B15: 20244 | C15: 22365
A16: Do you have R&D expenses to capitalize? | B16: No | C16: If you want to capitalize R&D, you have to input the numbers into the R&D worksheet.
A17: Do you have operating lease commitments? | B17: No | C17: If you lease or other contractual commitments that have not been converteed to debt already, say yes to this option and do the conversion.
A18: Cash and Marketable Securities | B18: 6216 | C18: 5773
A19: Cross holdings and other non-operating assets | B19: 0 | C19: 955
A20: Minority interests | B20: 62 | C20: 66
A21: Number of shares outstanding = | B21: 1445.21 | E21: Computed numbers: Here is what your company's numbers look like, relative to industry.
A22: Current stock price = | B22: 62.09 | E22: If you are not working in US dollars, you should add the inflation differential to the industry averages.
A23: Effective tax rate = | B23: 0.17 | J23: Industry (US) | K23: Industry (Global) | L23: Global Distribution Stats
A24: Marginal tax rate = | B24: 0.21 | I24: Company | J24: Average | K24: Average | L24: 1st Quartile | M24: Median | N24: 3rd Quartile
A25: The value drivers below: | E25: Revenue growth in the most recent year = | I25: =IF(C11>0,(B11/C11)^(1/D11)-1, "NA") -> 0.30484768 | J25: =VLOOKUP(B8,'Industry Averages(US)'!A2:S95,3) -> 0.067108696 | K25: =VLOOKUP(B9,'Industry Averages (Global)'!A2:N95,3) -> 0.032691413 | L25: =VLOOKUP($B$9,'Input Stat Distributioons'!$A$3:$T$96,3,FALSE()) -> 0.042 | M25: =VLOOKUP($B$9,'Input Stat Distributioons'!$A$3:$T$96,4,FALSE()) -> 0.125 | N25: =VLOOKUP($B$9,'Input Stat Distributioons'!$A$3:$T$96,5,FALSE()) -> 0.265
A26: Revenue growth rate for next year | B26: 0.3 | C26: Growth Lever - Next year | E26: Pre-tax operating margin in the most recent year = | I26: ='Valuation output'!B4 -> 0.11874567 | J26: =VLOOKUP(B8,'Industry Averages(US)'!A2:AA95,4) -> 0.22484875 | K26: =VLOOKUP(B9,'Industry Averages (Global)'!A2:N95,4) -> 0.12611613 | L26: =VLOOKUP($B$9,'Input Stat Distributioons'!$A$3:$T$96,6,FALSE()) -> -0.024205915 | M26: =VLOOKUP($B$9,'Input Stat Distributioons'!$A$3:$T$96,7,FALSE()) -> 0.034415584 | N26: =VLOOKUP($B$9,'Input Stat Distributioons'!$A$3:$T$96,8,FALSE()) -> 0.087863248
A27: Operating Margin for next year | B27: 0.127 | C27: Profitability Lever - Next year | E27: Sales to capital ratio in most recent year = | I27: =B11/'Valuation output'!B39 -> 1.0312038 | J27: =VLOOKUP(B8,'Industry Averages(US)'!A2:S95,14) -> 3.6197887 | K27: =VLOOKUP(B9,'Industry Averages (Global)'!A2:N95,14) -> 2.4835357 | L27: =VLOOKUP($B$9,'Input Stat Distributioons'!$A$3:$T$96,9,FALSE()) -> 0.75694751 | M27: =VLOOKUP($B$9,'Input Stat Distributioons'!$A$3:$T$96,10,FALSE()) -> 1.6449198 | N27: =VLOOKUP($B$9,'Input Stat Distributioons'!$A$3:$T$96,11,FALSE()) -> 2.9496944
A28: Compounded annual revenue growth rate - years 2-5 = | B28: 0.05 | C28: Growth Lever - Long term | E28: Marginal sales to capital ratio = | I28: =IF(('Input sheet'!B11-'Input sheet'!C11)/(('Input sheet'!B14+'Input sheet'!B15-'Input sheet'!B18)-('Input sheet'!C14+'Input sheet'!C15-'Input sheet'!C18))>0,('Input sheet'!B11-'Input sheet'!C11)/(('Input sheet'!B14+'Input sheet'!B15-'Input sheet'!B18)-('Input sheet'!C14+'Input sheet'!C15-'Input sheet'!C18)),"NA") -> NA
A29: Target pre-tax operating margin = | B29: 0.107 | C29: Profitability Lever - Long term | E29: Return on invested capital in most recent year= | I29: ='Valuation output'!B7/'Valuation output'!B39 -> 0.10163432 | J29: =VLOOKUP(B8,'Industry Averages(US)'!A2:S95,5) -> 0.44760353 | K29: =VLOOKUP(B9,'Industry Averages (Global)'!A2:N95,5) -> 0.19910185
A30: Year of convergence for margin | B30: 3 | C30: Speed of convergence level | E30: Standard deviation in stock prices = | J30: =VLOOKUP(B8,'Industry Averages(US)'!A2:S95,10) -> 0.54576795 | K30: =VLOOKUP(B8,'Industry Averages (Global)'!A2:Z95,10) -> 0.43558637
A31: Sales to capital ratio (for years 1-5) | B31: 6 | C31: Efficency of Growth Lever (first 5 years) | E31: Cost of capital = | I31: =B35 -> 0.11061227 | J31: =VLOOKUP(B8,'Industry Averages(US)'!A2:S95,13) -> 0.097070731 | K31: =VLOOKUP(B8,'Industry Averages (Global)'!A2:Z95,13) -> 0.11850111 | L31: =VLOOKUP($B$9,'Input Stat Distributioons'!$A$3:$T$96,12,FALSE()) -> 0.10795238 | M31: =VLOOKUP($B$9,'Input Stat Distributioons'!$A$3:$T$96,13,FALSE()) -> 0.11177982 | N31: =VLOOKUP($B$9,'Input Stat Distributioons'!$A$3:$T$96,14,FALSE()) -> 0.11408408
A32: Sales to capital ratio (for years 6-10) | B32: 6 | C32: Efficency of Growth Lever (years 6-10)
A33: Market numbers | E33: Valuation Output Feedback (for you to use to fine tune your inputs, if you want)
A34: Riskfree rate | B34: 0.0495 | E34: Revenues in year 10, based on your revenue growth = | J34: ='Valuation output'!M3 -> 81320.738
A35: Initial cost of capital = | B35: ='Cost of capital worksheet'!B13 -> 0.11061227 | C35: Do not input. Go to cost of capital sheet. | E35: Pre-tax Operating Income in year 10, based on your operating margin = | J35: ='Valuation output'!M5 -> 8701.319
A36: Other inputs | E36: Return on invested capital in year 10, based on your sales/capital ratio = | J36: ='Valuation output'!L40 -> 0.14959005
A37: Do you have employee options outstanding? | B37: No | E37: Check the Diagnostics worksheet for more details.
A38: Number of options outstanding = | B38: 7.72
A39: Average strike price = | B39: 1.29
A40: Average maturity = | B40: 7
A41: Standard deviation on stock price = | B41: 0.45
...

Sheet Valuation output
B1: Base year | C1: 1 | D1: 2 | E1: 3 | F1: 4 | G1: 5 | H1: 6 | I1: 7 | J1: 8 | K1: 9 | L1: 10 | M1: Terminal year
A2: Revenue growth rate | C2: ='Input sheet'!B26 -> 0.3 | D2: ='Input sheet'!B28 -> 0.05 | E2: =D2 -> 0.05 | F2: =E2 -> 0.05 | G2: =F2 -> 0.05 | H2: =G2-((G2-$M$2)/5) -> 0.0455 | I2: =G2-((G2-$M$2)/5)*2 -> 0.041 | J2: =G2-((G2-$M$2)/5)*3 -> 0.0365 | K2: =G2-((G2-$M$2)/5)*4 -> 0.032 | L2: =G2-((G2-$M$2)/5)*5 -> 0.0275 | M2: =IF('Input sheet'!B67="Yes",'Input sheet'!B68,IF('Input sheet'!B64="Yes",'Input sheet'!B65,'Input sheet'!B34)) -> 0.0275
A3: Revenues | B3: ='Input sheet'!B11 -> 41871 | C3: =B3*(1+C2) -> 54432.3 | D3: =C3*(1+D2) -> 57153.915 | E3: =D3*(1+E2) -> 60011.611 | F3: =E3*(1+F2) -> 63012.191 | G3: =F3*(1+G2) -> 66162.801 | H3: =G3*(1+H2) -> 69173.208 | I3: =H3*(1+I2) -> 72009.31 | J3: =I3*(1+J2) -> 74637.65 | ... M3: =L3*(1+M2) -> 81320.738
A4: EBIT (Operating) margin | B4: =B5/B3 -> 0.11874567 | C4: ='Input sheet'!B27 -> 0.127 | D4: =IF(D1>'Input sheet'!$B$30,'Input sheet'!$B$29,'Input sheet'!$B$29-(('Input sheet'!$B$29-$C$4)/'Input sheet'!$B$30)*('Input sheet'!$B$30-D1)) -> 0.11366667 | E4: =IF(E1>'Input sheet'!$B$30,'Input sheet'!$B$29,'Input sheet'!$B$29-(('Input sheet'!$B$29-$C$4)/'Input sheet'!$B$30)*('Input sheet'!$B$30-E1)) -> 0.107 | F4: =IF(F1>'Input sheet'!$B$30,'Input sheet'!$B$29,'Input sheet'!$B$29-(('Input sheet'!$B$29-$C$4)/'Input sheet'!$B$30)*('Input sheet'!$B$30-F1)) -> 0.107 | G4: =IF(G1>'Input sheet'!$B$30,'Input sheet'!$B$29,'Input sheet'!$B$29-(('Input sheet'!$B$29-$C$4)/'Input sheet'!$B$30)*('Input sheet'!$B$30-G1)) -> 0.107 | H4: =IF(H1>'Input sheet'!$B$30,'Input sheet'!$B$29,'Input sheet'!$B$29-(('Input sheet'!$B$29-$C$4)/'Input sheet'!$B$30)*('Input sheet'!$B$30-H1)) -> 0.107 | I4: =IF(I1>'Input sheet'!$B$30,'Input sheet'!$B$29,'Input sheet'!$B$29-(('Input sheet'!$B$29-$C$4)/'Input sheet'!$B$30)*('Input sheet'!$B$30-I1)) -> 0.107 | J4: =IF(J1>'Input sheet'!$B$30,'Input sheet'!$B$29,'Input sheet'!$B$29-(('Input sheet'!$B$29-$C$4)/'Input sheet'!$B$30)*('Input sheet'!$B$30-J1)) -> 0.107 | K4: =IF(K1>'Input sheet'!$B$30,'Input sheet'!$B$29,'Input sheet'!$B$29-(('Input sheet'!$B$29-$C$4)/'Input sheet'!$B$30)*('Input sheet'!$B$30-K1)) -> 0.107 | L4: =IF(L1>'Input sheet'!$B$30,'Input sheet'!$B$29,'Input sheet'!$B$29-(('Input sheet'!$B$29-$C$4)/'Input sheet'!$B$30)*('Input sheet'!$B$30-L1)) -> 0.107 | M4: =L4 -> 0.107
A5: EBIT (Operating income) | B5: =IF('Input sheet'!B17="Yes",IF('Input sheet'!B16="Yes",'Input sheet'!B12+'Operating lease converter'!F32+'R& D converter'!D39,'Input sheet'!B12+'Operating lease converter'!F32),IF('Input sheet'!B16="Yes",'Input sheet'!B12+'R& D converter'!D39,'Input sheet'!B12)) -> 4972 | C5: =C4*C3 -> 6912.9021 | D5: =D4*D3 -> 6496.495 | E5: =E4*E3 -> 6421.2424 | F5: =F4*F3 -> 6742.3045 | G5: =G4*G3 -> 7079.4197 | H5: =H4*H3 -> 7401.5333 | I5: =I4*I3 -> 7704.9962 | J5: =J4*J3 -> 7986.2285 | ... M5: =M4*M3 -> 8701.319 | N5: =M5-B5 -> 3729.319
A6: Tax rate | B6: ='Input sheet'!B23 -> 0.17 | C6: =B6 -> 0.17 | D6: =C6 -> 0.17 | E6: =D6 -> 0.17 | F6: =E6 -> 0.17 | G6: =F6 -> 0.17 | H6: =G6+($M$6-$G$6)/5 -> 0.178 | I6: =H6+($M$6-$G$6)/5 -> 0.186 | J6: =I6+($M$6-$G$6)/5 -> 0.194 | K6: =J6+($M$6-$G$6)/5 -> 0.202 | L6: =K6+($M$6-$G$6)/5 -> 0.21 | M6: =IF('Input sheet'!B59="Yes",'Input sheet'!B23,'Input sheet'!B24) -> 0.21
A7: EBIT(1-t) | B7: =IF(B5>0,B5*(1-B6),B5) -> 4126.76 | C7: =IF(C5>0,IF(C5<B10,C5,C5-(C5-B10)*C6),C5) -> 5737.7087 | D7: =IF(D5>0,IF(D5<C10,D5,D5-(D5-C10)*D6),D5) -> 5392.0909 | E7: =IF(E5>0,IF(E5<D10,E5,E5-(E5-D10)*E6),E5) -> 5329.6312 | F7: =IF(F5>0,IF(F5<E10,F5,F5-(F5-E10)*F6),F5) -> 5596.1127 | G7: =IF(G5>0,IF(G5<F10,G5,G5-(G5-F10)*G6),G5) -> 5875.9183 | H7: =IF(H5>0,IF(H5<G10,H5,H5-(H5-G10)*H6),H5) -> 6084.0604 | I7: =IF(I5>0,IF(I5<H10,I5,I5-(I5-H10)*I6),I5) -> 6271.8669 | J7: =IF(J5>0,IF(J5<I10,J5,J5-(J5-I10)*J6),J5) -> 6436.9002 | ... L7: =IF(L5>0,IF(L5<K10,L5,L5-(L5-K10)*L6),L5) -> 6690.0652 | M7: =M5*(1-M6) -> 6874.042
A8: - Reinvestment | C8: =IF('Input sheet'!$B$56="No",(D3-C3)/C38,IF('Input sheet'!$B$57=0,(C3-B3)/C38,IF('Input sheet'!$B$57=2,(E3-D3)/C38,IF('Input sheet'!$B$57=3,(F3-E3)/C38,(D3-C3)/C38)))) -> 453.6025 | D8: =IF('Input sheet'!$B$56="No",(E3-D3)/D38,IF('Input sheet'!$B$57=0,(D3-C3)/D38,IF('Input sheet'!$B$57=2,(F3-E3)/D38,IF('Input sheet'!$B$57=3,(G3-F3)/D38,(E3-D3)/D38)))) -> 476.28263 | E8: =IF('Input sheet'!$B$56="No",(F3-E3)/E38,IF('Input sheet'!$B$57=0,(E3-D3)/E38,IF('Input sheet'!$B$57=2,(G3-F3)/E38,IF('Input sheet'!$B$57=3,(H3-G3)/E38,(F3-E3)/E38)))) -> 500.09676 | F8: =IF('Input sheet'!$B$56="No",(G3-F3)/F38,IF('Input sheet'!$B$57=0,(F3-E3)/F38,IF('Input sheet'!$B$57=2,(H3-G3)/F38,IF('Input sheet'!$B$57=3,(I3-H3)/F38,(G3-F3)/F38)))) -> 525.10159 | G8: =IF('Input sheet'!$B$56="No",(H3-G3)/G38,IF('Input sheet'!$B$57=0,(G3-F3)/G38,IF('Input sheet'!$B$57=2,(I3-H3)/G38,IF('Input sheet'!$B$57=3,(J3-I3)/G38,(H3-G3)/G38)))) -> 501.73457 | H8: =IF('Input sheet'!$B$56="No",(I3-H3)/H38,IF('Input sheet'!$B$57=0,(H3-G3)/H38,IF('Input sheet'!$B$57=2,(J3-I3)/H38,IF('Input sheet'!$B$57=3,(K3-J3)/H38,(I3-H3)/H38)))) -> 472.68359 | I8: =IF('Input sheet'!$B$56="No",(J3-I3)/I38,IF('Input sheet'!$B$57=0,(I3-H3)/I38,IF('Input sheet'!$B$57=2,(K3-J3)/I38,IF('Input sheet'!$B$57=3,(L3-K3)/I38,(J3-I3)/I38)))) -> 438.05663 | J8: =IF('Input sheet'!$B$56="No",(K3-J3)/J38,IF('Input sheet'!$B$57=0,(J3-I3)/J38,IF('Input sheet'!$B$57=2,(L3-K3)/J38,IF('Input sheet'!$B$57=3,(M3-L3)/J38,(K3-J3)/J38)))) -> 398.06746 | K8: =IF('Input sheet'!$B$56="No",(L3-K3)/K38,IF('Input sheet'!$B$57=0,(K3-J3)/K38,IF('Input sheet'!$B$57=2,L3*L2/K38,IF('Input sheet'!$B$57=3,M3*M2/K38,(L3-K3)/K38)))) -> 353.03608 | L8: =IF('Input sheet'!$B$56="No",(M3-L3)/L38,IF('Input sheet'!$B$57=0,(L3-K3)/L38,IF('Input sheet'!$B$57=2,M3*M2/L38,IF('Input sheet'!$B$57=3,K8*(1+M2),(M3-L3)/L38)))) -> 362.74458 | M8: =IF(M2>0,(M2/M40)*M7,0) -> 2059.2174 | N8: =SUM(C8:M8) -> 6540.6238
A9: FCFF | C9: =C7-C8 -> 5284.1062 | D9: =D7-D8 -> 4915.8082 | E9: =E7-E8 -> 4829.5344 | F9: =F7-F8 -> 5071.0111 | G9: =G7-G8 -> 5374.1838 | H9: =H7-H8 -> 5611.3768 | I9: =I7-I8 -> 5833.8102 | J9: =J7-J8 -> 6038.8327 | ... M9: =M7-M8 -> 4814.8246
A10: NOL | B10: =IF('Input sheet'!B61="Yes",'Input sheet'!B62,0) -> 0 | C10: =IF(C5<0,B10-C5,IF(B10>C5,B10-C5,0)) -> 0 | D10: =IF(D5<0,C10-D5,IF(C10>D5,C10-D5,0)) -> 0 | E10: =IF(E5<0,D10-E5,IF(D10>E5,D10-E5,0)) -> 0 | F10: =IF(F5<0,E10-F5,IF(E10>F5,E10-F5,0)) -> 0 | G10: =IF(G5<0,F10-G5,IF(F10>G5,F10-G5,0)) -> 0 | H10: =IF(H5<0,G10-H5,IF(G10>H5,G10-H5,0)) -> 0 | I10: =IF(I5<0,H10-I5,IF(H10>I5,H10-I5,0)) -> 0 | J10: =IF(J5<0,I10-J5,IF(I10>J5,I10-J5,0)) -> 0 | ... M10: =IF(M5<0,L10-M5,IF(L10>M5,L10-M5,0)) -> 0
A12: Cost of capital | C12: ='Input sheet'!B35 -> 0.11061227 | D12: =C12 -> 0.11061227 | E12: =D12 -> 0.11061227 | F12: =E12 -> 0.11061227 | G12: =F12 -> 0.11061227 | H12: =G12-($G$12-$M$12)/5 -> 0.10684982 | I12: =H12-($G$12-$M$12)/5 -> 0.10308736 | J12: =I12-($G$12-$M$12)/5 -> 0.099324909 | K12: =J12-($G$12-$M$12)/5 -> 0.095562455 | L12: =K12-($G$12-$M$12)/5 -> 0.0918 | M12: =IF('Input sheet'!B45="Yes",'Input sheet'!B46,IF('Input sheet'!B64="Yes",'Input sheet'!B65+'Country equity risk premiums'!B1,'Input sheet'!B34+'Country equity risk premiums'!B1)) -> 0.0918
A13: Cumulated discount factor | C13: =1/(1+C12) -> 0.90040424 | D13: =C13*(1/(1+D12)) -> 0.81072779 | E13: =D13*(1/(1+E12)) -> 0.72998274 | F13: =E13*(1/(1+F12)) -> 0.65727956 | G13: =F13*(1/(1+G12)) -> 0.5918173 | H13: =G13*(1/(1+H12)) -> 0.53468618 | I13: =H13*(1/(1+I12)) -> 0.48471789 | J13: =I13*(1/(1+J12)) -> 0.44092323 | K13: =J13*(1/(1+K12)) -> 0.40246289 | L13: =K13*(1/(1+L12)) -> 0.36862327
A14: PV(FCFF) | C14: =C9*C13 -> 4757.8317 | D14: =D9*D13 -> 3985.3824 | E14: =E9*E13 -> 3525.4768 | F14: =F9*F13 -> 3333.0719 | G14: =G9*G13 -> 3180.5349 | H14: =H9*H13 -> 3000.3256 | I14: =I9*I13 -> 2827.7522 | J14: =J9*J13 -> 2662.6616 | ... L14: =L9*L13 -> 2332.3976
A16: Terminal cash flow | B16: =M9 -> 4814.8246
A17: Terminal cost of capital | B17: =M12 -> 0.0918
A18: Terminal value | B18: =B16/(B17-M2) -> 74880.632
A19: PV(Terminal value) | B19: =B18*L13 -> 27602.744
A20: PV (CF over next 10 years) | B20: =SUM(C14:L14) -> 32110.328
A21: Sum of PV | B21: =B19+B20 -> 59713.071
A22: Probability of failure = | B22: =IF('Input sheet'!B51="Yes",'Input sheet'!B52,0) -> 0
A23: Proceeds if firm fails = | B23: =IF('Input sheet'!B53="B",('Input sheet'!B14+'Input sheet'!B15)*'Input sheet'!B54,'Valuation output'!B21*'Input sheet'!B54) -> 29856.536
A24: Value of operating assets = | B24: =B21*(1-B22)+B23*B22 -> 59713.071
A25: - Debt | B25: =IF('Input sheet'!B17="Yes",'Input sheet'!B15+'Operating lease converter'!C28,'Input sheet'!B15) -> 20244
A26: - Minority interests | B26: ='Input sheet'!B20 -> 62
A27: + Cash | B27: =IF('Input sheet'!B70="YES",'Input sheet'!B18-'Input sheet'!B71*('Input sheet'!B24-'Input sheet'!B72),'Input sheet'!B18) -> 6216 | D27: If you get Value Errors all over, it is usually because your option worksheet has gone haywire. The fix is very low tech. Go into the option value worksheet, and in cell B17 of that worksheet (adjusted S), enter any number (say 5) and then undo what you did. Voila!
A28: + Non-operating assets | B28: ='Input sheet'!B19 -> 0
A29: Value of equity | B29: =B24-B25-B26+B27+B28 -> 45623.071
A30: - Value of options | B30: =IF('Input sheet'!B37="No",0,'Option value'!B29) -> 0
A31: Value of equity in common stock | B31: =B29-B30 -> 45623.071
A32: Number of shares | B32: ='Input sheet'!B21 -> 1445.21
A33: Estimated value /share | B33: =B31/B32 -> 31.568472
A34: Price | B34: ='Input sheet'!B22 -> 62.09
A35: Price as % of value | B35: =B34/B33 -> 1.9668358
A37: Implied variables | M37: After year 10
A38: Sales to capital ratio | C38: ='Input sheet'!B31 -> 6 | D38: ='Input sheet'!B31 -> 6 | E38: =D38 -> 6 | F38: =E38 -> 6 | G38: =F38 -> 6 | H38: ='Input sheet'!B32 -> 6 | I38: =H38 -> 6 | J38: =I38 -> 6 | K38: =J38 -> 6 | L38: =K38 -> 6
A39: Invested capital | B39: =IF('Input sheet'!B17="Yes",IF('Input sheet'!B16="Yes",'Input sheet'!B14+'Input sheet'!B15-'Input sheet'!B18+'Operating lease converter'!F33+'R& D converter'!D35,'Input sheet'!B14+'Input sheet'!B15-'Input sheet'!B18+'Operating lease converter'!F33),IF('Input sheet'!B16="Yes",'Input sheet'!B14+'Input sheet'!B15-'Input sheet'!B18+'R& D converter'!D35,'Input sheet'!B14+'Input sheet'!B15-'Input sheet'!B18)) -> 40604 | C39: =B39+C8 -> 41057.603 | D39: =C39+D8 -> 41533.885 | E39: =D39+E8 -> 42033.982 | F39: =E39+F8 -> 42559.083 | G39: =F39+G8 -> 43060.818 | H39: =G39+H8 -> 43533.502 | I39: =H39+I8 -> 43971.558 | J39: =I39+J8 -> 44369.626 | ... L39: =K39+L8 -> 45085.406
A40: ROIC | B40: =B7/B39 -> 0.10163432 | C40: =C7/B39 -> 0.14130895 | D40: =D7/C39 -> 0.1313299 | E40: =E7/D39 -> 0.12832007 | F40: =F7/E39 -> 0.13313306 | G40: =G7/F39 -> 0.13806496 | H40: =H7/G39 -> 0.14128994 | I40: =I7/H39 -> 0.14406989 | J40: =J7/I39 -> 0.14638781 | ... L40: =L7/K39 -> 0.14959005 | M40: =IF('Input sheet'!B48="Yes",'Input sheet'!B49,'Valuation output'!L12) -> 0.0918

Sheet Stories to Numbers
A1: ='Input sheet'!B4 -> Hewlett Packard Enterprise | G1: ='Input sheet'!B3 -> 44814
A2: From server vendor to networking-led AI infrastructure
A3: HPE converts the AI build-out and the Juniper acquisition into a larger, more networking-heavy company. Revenue rises about 30% over the next twelve months as a record $7.6bn AI backlog converts and FY27 grows 13–17%, then slows to mid-single digits as the cycle matures. Operating margin after stock-based compensation settles near 10.7% because lower-margin AI systems and normalising memory prices offset the richer networking mix. Reinvestment stays modest, and risk converges to that of a mature technology-hardware company. | H3: Tell your story about the company. Keep it focuses on the company's businesses and tie it into the three key levers of value: cash flows, growth and risk
A7: The Assumptions
B8: Base year | C8: Next year | D8: Years 2-5 | E8: Years 6-10 | F8: After year 10 | G8: Link to story
A9: Revenues (a) | B9: ='Valuation output'!B3 -> 41871 | C9: ='Input sheet'!B26 -> 0.3 | D9: ='Input sheet'!B28 -> 0.05 | E9: Changes to | F9: ='Valuation output'!M2 -> 0.0275 | G9: AI backlog conversion, then mid-single-digit growth | H9: Tie each assumption to the part of your story that relates to it.
A10: Operating margin (b) | B10: ='Valuation output'!B4 -> 0.11874567 | C10: ='Input sheet'!B27 -> 0.127 | D10: Moves to | E10: ='Valuation output'!G4 -> 0.107 | F10: ='Valuation output'!M4 -> 0.107 | G10: Networking mix vs AI systems and memory normalisation
A11: Tax rate | B11: ='Valuation output'!B6 -> 0.17 | D11: =B11 -> 0.17 | E11: Changes to | F11: ='Valuation output'!M6 -> 0.21 | G11: Structural 14–17% rate converging to US marginal
A12: Sales to Capital (c ) | C12: ='Input sheet'!B31 -> 6 | D12: ='Input sheet'!B31 -> 6 | E12: ='Input sheet'!B32 -> 6 | F12: ='Valuation output'!M2/'Valuation output'!M40 -> 0.29956427 | G12: Low capital intensity outside Financial Services
A13: Return on capital | B13: ='Valuation output'!B40 -> 0.10163432 | C13: Marginal ROIC = | D13: =Diagnostics!C27 -> 0.57198678 | F13: ='Valuation output'!M40 -> 0.0918 | G13: Returns near the cost of capital: narrow moat in networking only
A14: Cost of capital (d) | D14: ='Valuation output'!C12 -> 0.11061227 | F14: ='Valuation output'!M12 -> 0.0918 | G14: Mature hardware risk profile
A15: The Cash Flows
B16: Revenues | C16: Operating Margin | D16: EBIT | E16: EBIT (1-t) | F16: Reinvestment | G16: FCFF | H16: These are the numbers that come from your assumptions. The revenues over time reflect your revenue growth, the operating margins evolve towards your target margin and your tax rate will change, if you have set it to. The reinvestment is estimated using the sales to capital ratio for the first 10 years and based on a reinvestment rate in stable growth (g/ ROC).
A17: 1 | B17: ='Valuation output'!C3 -> 54432.3 | C17: ='Valuation output'!C4 -> 0.127 | D17: =B17*C17 -> 6912.9021 | E17: ='Valuation output'!C7 -> 5737.7087 | F17: ='Valuation output'!C8 -> 453.6025 | G17: =E17-F17 -> 5284.1062
A18: 2 | B18: ='Valuation output'!D3 -> 57153.915 | C18: ='Valuation output'!D4 -> 0.11366667 | D18: =B18*C18 -> 6496.495 | E18: ='Valuation output'!D7 -> 5392.0909 | F18: ='Valuation output'!D8 -> 476.28263 | G18: =E18-F18 -> 4915.8082
A19: 3 | B19: ='Valuation output'!E3 -> 60011.611 | C19: ='Valuation output'!E4 -> 0.107 | D19: =B19*C19 -> 6421.2424 | E19: ='Valuation output'!E7 -> 5329.6312 | F19: ='Valuation output'!E8 -> 500.09676 | G19: =E19-F19 -> 4829.5344
A20: 4 | B20: ='Valuation output'!F3 -> 63012.191 | C20: ='Valuation output'!F4 -> 0.107 | D20: =B20*C20 -> 6742.3045 | E20: ='Valuation output'!F7 -> 5596.1127 | F20: ='Valuation output'!F8 -> 525.10159 | G20: =E20-F20 -> 5071.0111
A21: 5 | B21: ='Valuation output'!G3 -> 66162.801 | C21: ='Valuation output'!G4 -> 0.107 | D21: =B21*C21 -> 7079.4197 | E21: ='Valuation output'!G7 -> 5875.9183 | F21: ='Valuation output'!G8 -> 501.73457 | G21: =E21-F21 -> 5374.1838
A22: 6 | B22: ='Valuation output'!H3 -> 69173.208 | C22: ='Valuation output'!H4 -> 0.107 | D22: =B22*C22 -> 7401.5333 | E22: ='Valuation output'!H7 -> 6084.0604 | F22: ='Valuation output'!H8 -> 472.68359 | G22: =E22-F22 -> 5611.3768
A23: 7 | B23: ='Valuation output'!I3 -> 72009.31 | C23: ='Valuation output'!I4 -> 0.107 | D23: =B23*C23 -> 7704.9962 | E23: ='Valuation output'!I7 -> 6271.8669 | F23: ='Valuation output'!I8 -> 438.05663 | G23: =E23-F23 -> 5833.8102
A24: 8 | B24: ='Valuation output'!J3 -> 74637.65 | C24: ='Valuation output'!J4 -> 0.107 | D24: =B24*C24 -> 7986.2285 | E24: ='Valuation output'!J7 -> 6436.9002 | F24: ='Valuation output'!J8 -> 398.06746 | G24: =E24-F24 -> 6038.8327
A25: 9 | B25: ='Valuation output'!K3 -> 77026.054 | C25: ='Valuation output'!K4 -> 0.107 | D25: =B25*C25 -> 8241.7878 | E25: ='Valuation output'!K7 -> 6576.9467 | F25: ='Valuation output'!K8 -> 353.03608 | G25: =E25-F25 -> 6223.9106
A26: 10 | B26: ='Valuation output'!L3 -> 79144.271 | C26: ='Valuation output'!L4 -> 0.107 | D26: =B26*C26 -> 8468.437 | E26: ='Valuation output'!L7 -> 6690.0652 | F26: ='Valuation output'!L8 -> 362.74458 | G26: =E26-F26 -> 6327.3206
A27: Terminal year | B27: ='Valuation output'!M3 -> 81320.738 | C27: ='Valuation output'!M4 -> 0.107 | D27: =B27*C27 -> 8701.319 | E27: ='Valuation output'!M7 -> 6874.042 | F27: ='Valuation output'!M8 -> 2059.2174 | G27: =E27-F27 -> 4814.8246
A28: The Value
A29: Terminal value | D29: ='Valuation output'!B18 -> 74880.632 | H29: This is the output from your valuation. It reflects your cash flows being discounted back at the cost of capital to get to your operating asset value, which then gets adjusted for the likelihood that your firm will not make it. We add cash and non-operating assets, subtract out debt and minority interests to get to value of equity.
A30: PV(Terminal value) | D30: ='Valuation output'!B19 -> 27602.744
A31: PV (CF over next 10 years) | D31: ='Valuation output'!B20 -> 32110.328
A32: Value of operating assets = | D32: ='Valuation output'!B21 -> 59713.071
A33: Adjustment for distress | D33: =D32-'Valuation output'!B24 -> 0 | E33: Probability of failure = | G33: ='Valuation output'!B22 -> 0
A34: - Debt & Minority Interests | D34: ='Valuation output'!B25+'Valuation output'!B26 -> 20306
A35: + Cash & Other Non-operating assets | D35: ='Valuation output'!B27+'Valuation output'!B28 -> 6216
A36: Value of equity | D36: =D32-D33-D34+D35 -> 45623.071
A37: - Value of equity options | D37: ='Valuation output'!B30 -> 0
A38: Number of shares | D38: ='Valuation output'!B32 -> 1445.21
A39: Value per share | D39: =(D36-D37)/D38 -> 31.568472 | E39: Stock was trading at = | G39: ='Input sheet'!B22 -> 62.09

Sheet Valuation as picture
A1: You can modify this picture and bring in relevant details to back up your cost of capital and other details that you think flesh out your company's valuation story.
A3: ='Input sheet'!B4 -> Hewlett Packard Enterprise | O3: ='Input sheet'!B3 -> 44814
A5: Base Year and Comparison | E5: Growth Story | H5: Profitability Story | K5: Growth Efficiency Story
B6: Company | C6: Industry | E6: ='Stories to Numbers'!G9 -> AI backlog conversion, then mid-single-digit growth | H6: ='Stories to Numbers'!G10 -> Networking mix vs AI systems and memory normalisation | K6: ='Stories to Numbers'!G12 -> Low capital intensity outside Financial Services | O6: Terminal Value
A7: Revenue Growth | B7: ='Input sheet'!I25 -> 0.30484768 | C7: ='Input sheet'!K25 -> 0.032691413 | O7: Growth Rate | P7: =O16 -> 0.0275
A8: Revenue | B8: ='Valuation output'!B3 -> 41871 | O8: Cost of capital | P8: ='Valuation output'!M12 -> 0.0918
A9: Operating Margin | B9: ='Valuation output'!B4 -> 0.11874567 | C9: ='Input sheet'!K26 -> 0.12611613 | O9: Return on capital | P9: ='Valuation output'!M40 -> 0.0918
A10: Operating Income | B10: ='Valuation output'!B5 -> 4972 | O10: Reinvestment Rate | P10: =P7/P9 -> 0.29956427
A11: EBIT (1-t) | B11: ='Valuation output'!B7 -> 4126.76
A15: ='Valuation output'!A19 -> PV(Terminal value) | B15: ='Valuation output'!B19 -> 27602.744 | E15: ='Valuation output'!C1 -> 1 | F15: ='Valuation output'!D1 -> 2 | G15: ='Valuation output'!E1 -> 3 | H15: ='Valuation output'!F1 -> 4 | I15: ='Valuation output'!G1 -> 5 | J15: ='Valuation output'!H1 -> 6 | K15: ='Valuation output'!I1 -> 7 | L15: ='Valuation output'!J1 -> 8 | ... O15: ='Valuation output'!M1 -> Terminal year
A16: ='Valuation output'!A20 -> PV (CF over next 10 years) | B16: ='Valuation output'!B20 -> 32110.328 | D16: Revenue Growth | E16: ='Valuation output'!C2 -> 0.3 | F16: ='Valuation output'!D2 -> 0.05 | G16: ='Valuation output'!E2 -> 0.05 | H16: ='Valuation output'!F2 -> 0.05 | I16: ='Valuation output'!G2 -> 0.05 | J16: ='Valuation output'!H2 -> 0.0455 | K16: ='Valuation output'!I2 -> 0.041 | L16: ='Valuation output'!J2 -> 0.0365 | ... O16: ='Valuation output'!M2 -> 0.0275
A17: ='Valuation output'!A22 -> Probability of failure = | B17: ='Valuation output'!B22 -> 0 | D17: Revenue | E17: ='Valuation output'!C3 -> 54432.3 | F17: ='Valuation output'!D3 -> 57153.915 | G17: ='Valuation output'!E3 -> 60011.611 | H17: ='Valuation output'!F3 -> 63012.191 | I17: ='Valuation output'!G3 -> 66162.801 | J17: ='Valuation output'!H3 -> 69173.208 | K17: ='Valuation output'!I3 -> 72009.31 | L17: ='Valuation output'!J3 -> 74637.65 | ... O17: ='Valuation output'!M3 -> 81320.738
A18: ='Valuation output'!A24 -> Value of operating assets = | B18: ='Valuation output'!B24 -> 59713.071 | D18: Operating Margin | E18: ='Valuation output'!C4 -> 0.127 | F18: ='Valuation output'!D4 -> 0.11366667 | G18: ='Valuation output'!E4 -> 0.107 | H18: ='Valuation output'!F4 -> 0.107 | I18: ='Valuation output'!G4 -> 0.107 | J18: ='Valuation output'!H4 -> 0.107 | K18: ='Valuation output'!I4 -> 0.107 | L18: ='Valuation output'!J4 -> 0.107 | ... O18: ='Valuation output'!M4 -> 0.107
A19: ='Valuation output'!A25 -> - Debt | B19: ='Valuation output'!B25 -> 20244 | D19: Operating Income | E19: ='Valuation output'!C5 -> 6912.9021 | F19: ='Valuation output'!D5 -> 6496.495 | G19: ='Valuation output'!E5 -> 6421.2424 | H19: ='Valuation output'!F5 -> 6742.3045 | I19: ='Valuation output'!G5 -> 7079.4197 | J19: ='Valuation output'!H5 -> 7401.5333 | K19: ='Valuation output'!I5 -> 7704.9962 | L19: ='Valuation output'!J5 -> 7986.2285 | ... O19: ='Valuation output'!M5 -> 8701.319
A20: ='Valuation output'!A26 -> - Minority interests | B20: ='Valuation output'!B26 -> 62 | D20: EBIT (1-t) | E20: ='Valuation output'!C7 -> 5737.7087 | F20: ='Valuation output'!D7 -> 5392.0909 | G20: ='Valuation output'!E7 -> 5329.6312 | H20: ='Valuation output'!F7 -> 5596.1127 | I20: ='Valuation output'!G7 -> 5875.9183 | J20: ='Valuation output'!H7 -> 6084.0604 | K20: ='Valuation output'!I7 -> 6271.8669 | L20: ='Valuation output'!J7 -> 6436.9002 | ... O20: ='Valuation output'!M7 -> 6874.042
A21: ='Valuation output'!A27 -> + Cash | B21: ='Valuation output'!B27 -> 6216 | D21: Reinvestment | E21: ='Valuation output'!C8 -> 453.6025 | F21: ='Valuation output'!D8 -> 476.28263 | G21: ='Valuation output'!E8 -> 500.09676 | H21: ='Valuation output'!F8 -> 525.10159 | I21: ='Valuation output'!G8 -> 501.73457 | J21: ='Valuation output'!H8 -> 472.68359 | K21: ='Valuation output'!I8 -> 438.05663 | L21: ='Valuation output'!J8 -> 398.06746 | ... O21: ='Valuation output'!M8 -> 2059.2174
A22: ='Valuation output'!A28 -> + Non-operating assets | B22: ='Valuation output'!B28 -> 0 | D22: FCFF | E22: ='Valuation output'!C9 -> 5284.1062 | F22: ='Valuation output'!D9 -> 4915.8082 | G22: ='Valuation output'!E9 -> 4829.5344 | H22: ='Valuation output'!F9 -> 5071.0111 | I22: ='Valuation output'!G9 -> 5374.1838 | J22: ='Valuation output'!H9 -> 5611.3768 | K22: ='Valuation output'!I9 -> 5833.8102 | L22: ='Valuation output'!J9 -> 6038.8327 | ... O22: ='Valuation output'!M9 -> 4814.8246
A23: ='Valuation output'!A29 -> Value of equity | B23: ='Valuation output'!B29 -> 45623.071 | N23: ='Valuation output'!B18 -> 74880.632
A24: ='Valuation output'!A30 -> - Value of options | B24: ='Valuation output'!B30 -> 0
A25: ='Valuation output'!A31 -> Value of equity in common stock | B25: ='Valuation output'!B31 -> 45623.071 | D25: Cost of Capital | E25: ='Valuation output'!C12 -> 0.11061227 | F25: ='Valuation output'!D12 -> 0.11061227 | G25: ='Valuation output'!E12 -> 0.11061227 | H25: ='Valuation output'!F12 -> 0.11061227 | I25: ='Valuation output'!G12 -> 0.11061227 | J25: ='Valuation output'!H12 -> 0.10684982 | K25: ='Valuation output'!I12 -> 0.10308736 | L25: ='Valuation output'!J12 -> 0.099324909 | ... N25: ='Valuation output'!L12 -> 0.0918
A26: ='Valuation output'!A32 -> Number of shares | B26: ='Valuation output'!B32 -> 1445.21 | D26: Cumulated WACC | E26: ='Valuation output'!C13 -> 0.90040424 | F26: ='Valuation output'!D13 -> 0.81072779 | G26: ='Valuation output'!E13 -> 0.72998274 | H26: ='Valuation output'!F13 -> 0.65727956 | I26: ='Valuation output'!G13 -> 0.5918173 | J26: ='Valuation output'!H13 -> 0.53468618 | K26: ='Valuation output'!I13 -> 0.48471789 | L26: ='Valuation output'!J13 -> 0.44092323 | ... N26: ='Valuation output'!L13 -> 0.36862327
A27: ='Valuation output'!A33 -> Estimated value /share | B27: ='Valuation output'!B33 -> 31.568472
D28: Sales to Capital | E28: ='Valuation output'!C38 -> 6 | F28: ='Valuation output'!D38 -> 6 | G28: ='Valuation output'!E38 -> 6 | H28: ='Valuation output'!F38 -> 6 | I28: ='Valuation output'!G38 -> 6 | J28: ='Valuation output'!H38 -> 6 | K28: ='Valuation output'!I38 -> 6 | L28: ='Valuation output'!J38 -> 6 | ... N28: ='Valuation output'!L38 -> 6
A29: Price per share | B29: ='Stories to Numbers'!G39 -> 62.09 | D29: ROIC | E29: ='Valuation output'!C40 -> 0.14130895 | F29: ='Valuation output'!D40 -> 0.1313299 | G29: ='Valuation output'!E40 -> 0.12832007 | H29: ='Valuation output'!F40 -> 0.13313306 | I29: ='Valuation output'!G40 -> 0.13806496 | J29: ='Valuation output'!H40 -> 0.14128994 | K29: ='Valuation output'!I40 -> 0.14406989 | L29: ='Valuation output'!J40 -> 0.14638781 | ... O29: ='Valuation output'!M40 -> 0.0918
A30: % Under or Over Valued | B30: =B29/B27-1 -> 0.96683578
D32: Risk Story | G32: Competitive Advantages
D33: ='Stories to Numbers'!G14 -> Mature hardware risk profile | G33: ='Stories to Numbers'!G13 -> Returns near the cost of capital: narrow moat in networking only

Sheet Diagnostics
A1: Step 1: Check revenue growth rate | D1: Your forecasts | G1: Questions to ask
B2: Industry Average | C2: Most Recent year | D2: Next year | E2: Years 2-5 | G2: 1. If you are forecasting a revenue growth rate > industry average, is your company small?
A3: Annual Revenue Growth Rate | B3: ='Input sheet'!J25 -> 0.067108696 | C3: ='Input sheet'!I25 -> 0.30484768 | D3: ='Valuation output'!C2 -> 0.3 | E3: ='Valuation output'!D2 -> 0.05 | G3: 2. If your forecasted revenue growth rate is very different from your company's most recent year of growth, what is the reason?
A5: Step 2: Check dollar revenues
B6: Most Recent year | C6: Next year | D6: Year 5 | E6: Year 10 | G6: 1. How big is the total market today?
A7: Revenues | B7: ='Valuation output'!B3 -> 41871 | C7: ='Valuation output'!C3 -> 54432.3 | D7: ='Valuation output'!G3 -> 66162.801 | E7: ='Valuation output'!L3 -> 79144.271 | G7: 2. How much revenues do the biggest companies in that market make today?
G8: 3. How much growth is there in the total market?
G9: 4. What type of market share are you forecasting for your company in year 10?
A11: Step 3: Check your margins | B11: Most Recent year | C11: Next year | D11: Year 5 | E11: Year 10 | G11: 1. What are the margins of the industry that the company is in?
A12: Operating Margin | B12: ='Valuation output'!B4 -> 0.11874567 | C12: ='Valuation output'!C4 -> 0.127 | D12: ='Valuation output'!G4 -> 0.107 | E12: ='Valuation output'!M4 -> 0.107 | G12: 2. What are the unit economics of the business? (How much does it cost you to make the extra unit that you sell?
G13: 3. What does the competition in this business look like?
A15: Step 4: Check how much you are reinvesting
B16: Most Recent year | C16: Next year | D16: Year 5 | E16: Year 10 | G16: 1. is the growth that you are forecasting bounce-back growth or new growth?
A17: Sales to Capital | B17: ='Input sheet'!I27 -> 1.0312038 | C17: ='Valuation output'!C38 -> 6 | D17: ='Valuation output'!G38 -> 6 | E17: ='Valuation output'!L38 -> 6 | G17: 2. How much excess capacity do you have to service near term growth?
G18: 3. Does investment efficiency in this business change as companies get bigger?
A19: Reinvestment effect on cash flows
B20: $ Value | C20: As % of value
A21: PV of after-tax operating income for next 10 yearas | B21: ='Valuation output'!C7*'Valuation output'!C13+'Valuation output'!D7*'Valuation output'!D13+'Valuation output'!E7*'Valuation output'!E13+'Valuation output'!F7*'Valuation output'!F13+'Valuation output'!G7*'Valuation output'!G13+'Valuation output'!H7*'Valuation output'!H13+'Valuation output'!I7*'Valuation output'!I13+'Valuation output'!J7*'Valuation output'!J13+'Valuation output'!K7*'Valuation output'!K13+'Valuation output'!L7*'Valuation output'!L13 -> 34828.413 | C21: =B21/B21 -> 1 | G21: 1. Is your reinvestment consitent with your revenue growth forecast?
A22: Value effect of reinvestment for next 10 years | B22: =B21-B23 -> 2718.0854 | C22: =B22/B21 -> 0.078042183 | G22: 2. Are you comfortable with your return on capital in year 10?
A23: PV of FCFF for next ten years | B23: ='Valuation output'!B20 -> 32110.328 | C23: =C21-C22 -> 0.92195782
A25: Return on capital effects
B26: Most recent year | C26: Marginal (1-10) | D26: ROC in year 10 | E26: Stable ROC
A27: Return on capital | B27: ='Valuation output'!B40 -> 0.10163432 | C27: =('Valuation output'!L7-'Valuation output'!B7)/('Valuation output'!L39-'Valuation output'!B39) -> 0.57198678 | D27: ='Valuation output'!L40 -> 0.14959005 | E27: ='Valuation output'!M40 -> 0.0918
A29: Step 5: Risk Metrics
B30: Industry Average | C30: Compounded | D30: Year 1-5 | E30: Stable Growth | G30: 1. How does your cost of capital compare to the industry average?
A31: Cost of capital | B31: ='Input sheet'!J31 -> 0.097070731 | C31: =(1/'Valuation output'!L13)^(1/10)-1 -> 0.10494771 | D31: ='Valuation output'!C12 -> 0.11061227 | E31: ='Valuation output'!M12 -> 0.0918 | G31: 2. What is happenign to your cost of capital over time? Why?
G32: 3. Is your failure rate consistent with your company's characteristics?
A33: Failure Rate | B33: ='Valuation output'!B22 -> 0
A35: Step 6: Price versus Value
A36: Your calculated value as a percent of current price | B36: ='Valuation output'!B33/'Valuation output'!B34 -> 0.50843086
B37: =IF(B36="NA","Value is negative. See below",IF(B36>2,"Value seems high. See below",IF(B36<0.5,"Value seems low. See below"," ")))
A38: Inputs | B38: If calculated value is negative or looks too low | C38: If calculated value looks too high
A39: Revenue growth rate (input cell B25, B27) | B39: Increase revenue growth rate | C39: Decrease revenue growth rate
A40: Operating margin (B26, B28) | B40: Increase the target pre-tax operating margin | C40: Decrease the target pre-tax operating margin
A41: Sales to Capital (B30-B32) | B41: Increase the sales/capital ratio | C41: Decrease the sales/capital ratio
A42: Return on capital in perpetuity (B48, B49) | B42: Increase relative to your cost of capital | C42: If higher than your cost of capital, lower towards your cost of capital | D42: T

Sheet Option value
A1: Note: This worksheet is the most finicky of all of the worksheets in this spreadsheet. If you start to get errors, here is a quick fix. Go into cell B12 and replace the contents with a number (say 5), and then undo your action. The spreadsheet will fix itself magically.
A3: Valuing Options or Warrants
A4: Enter the current stock price = | B4: ='Input sheet'!B22 -> 62.09
A5: Enter the strike price on the option = | B5: ='Input sheet'!B39 -> 1.29
A6: Enter the expiration of the option = | B6: ='Input sheet'!B40 -> 7
A7: Enter the standard deviation in stock prices = | B7: ='Input sheet'!B41 -> 0.45 | C7: (volatility)
A8: Enter the annualized dividend yield on stock = | B8: 0
A9: Enter the treasury bond rate = | B9: ='Input sheet'!B34 -> 0.0495
A10: Enter the number of warrants (options) outstanding = | B10: ='Input sheet'!B38 -> 7.72
A11: Enter the number of shares outstanding = | B11: ='Input sheet'!B21 -> 1445.21
A13: Do not input any numbers below this line
A14: Dilution-adjusted Black-Scholes
A15: Stock Price= | B15: =B4 -> 62.09 | C15: # Warrants issued= | D15: =B10 -> 7.72
A16: Strike Price= | B16: =B5 -> 1.29 | C16: # Shares outstanding= | D16: =B11 -> 1445.21
A17: Adjusted S = | B17: =(B15*D16+B28*D15)/(D16+D15) -> 62.085129 | C17: T.Bond rate= | D17: =B9 -> 0.0495
A18: Adjusted K = | B18: =B16 -> 1.29 | C18: Variance= | D18: =B7^2 -> 0.2025
A19: Expiration (in years) = | B19: =B6 -> 7 | C19: Annualized dividend yield= | D19: =B8 -> 0
C20: Div. Adj. interest rate= | D20: =D17-D19 -> 0.0495
A22: d1 = | B22: =(LN(B17/B18)+(D20+(D18/2))*B19)/(((D18)^(0.5))*(B19^0.5)) -> 4.135658
A23: N (d1) = | B23: =NORMSDIST(B22) -> 0.9999823
A25: d2 = | B25: =B22-((D18^0.5)*(B19^(0.5))) -> 2.9450699
A26: N (d2) = | B26: =NORMSDIST(B25) -> 0.99838559
A28: Value per option = | B28: =((EXP((0-D19)*B19))*B17*B23-B18*(EXP((0-D17)*B19))*B26) -> 61.173268
A29: Value of all options outstanding = | B29: =B28*B10 -> 472.25763

Sheet Synthetic rating
A1: If you have negative operating income, this spreadsheet will offer you a D rating. Do not use that rating as your cost of debt for a going concern. Insread give your company a low, but going concern rating like BB and use that cost of debt.
A4: Inputs for synthetic rating estimation
A5: Please read the special cases worksheet (see below) before you use this spreadsheet.
A6: Before you use this spreadsheet, make sure that the iteration box (under calculation options in excel) is checked.
A7: Enter the type of firm = | C7: ='Cost of capital worksheet'!B36 -> 2
A8: Enter current Earnings before interest and taxes (EBIT) = | F8: =IF('Input sheet'!B17="Yes",'Input sheet'!B12+'Operating lease converter'!F32,'Input sheet'!B12) -> 4972 | G8: (Add back only long term interest expense for financial firms)
A9: Enter current interest expenses = | F9: =IF('Input sheet'!B17="Yes",'Cost of capital worksheet'!B31+'Operating lease converter'!C28*'Operating lease converter'!C15,'Cost of capital worksheet'!B31) -> 1018 | G9: (Use only long term interest expense for financial firms)
A10: Enter long term risk free rate = | F10: ='Input sheet'!B34 -> 0.0495
A11: Output
A12: Interest coverage ratio = | D12: =IF(F9=0,1000000,IF(F8<0,-100000,F8/F9)) -> 4.8840864
A13: Estimated Bond Rating = | D13: =IF(C7=1,VLOOKUP(D12,A22:D36,3),(IF(C7=2,VLOOKUP(D12,A41:D55,3),VLOOKUP(D12,F22:I36,3)))) -> A3/A- | F13: Note: If you get REF! All over the place, set the operating lease commitment question in cell F5
A14: Estimated Company Default Spread = | D14: =IF(C7=1,VLOOKUP(D12,A22:D36,4),(IF(C7=2,VLOOKUP(D12,A41:D55,4),VLOOKUP(D12,F22:I36,4)))) -> 0.008872 | F14: to No, and then reset it to Yes. It should work.
A15: Estimated County Default Spread (if any) = | D15: =VLOOKUP('Input sheet'!B7,'Country equity risk premiums'!A5:C196,3) -> 0.0023
A16: Estimated Cost of Debt = | D16: =F10+D14+D15 -> 0.060672
A18: If you want to update the spreads listed below, please visit http://www.bondsonline.com
A19: For large manufacturing firms | J19: Default Probabilities over time (1 - 10 year time horizons)
A20: If interest coverage ratio is | J20: Rating | K20: 1 | L20: 2 | M20: 3 | N20: 4 | O20: 5 | P20: 6 | Q20: 7 | R20: 8 | S20: 9 | T20: 10
A21: > | B21: ≤ to | C21: Rating is | D21: Spread is | J21: AAA | K21: 0 | L21: 0.0003 | M21: 0.0013 | N21: 0.0024 | O21: 0.0035 | P21: 0.0045 | Q21: 0.0051 | R21: 0.0059 | S21: 0.0064 | T21: 0.007
A22: -100000 | B22: 0.199999 | C22: D2/D | D22: 0.19 | J22: AA | K22: 0.0002 | L22: 0.0006 | M22: 0.0012 | N22: 0.0021 | O22: 0.0031 | P22: 0.0042 | Q22: 0.005 | R22: 0.0058 | S22: 0.0065 | T22: 0.0072
A23: 0.2 | B23: 0.649999 | C23: C2/C | D23: 0.16 | J23: A | K23: 0.0005 | L23: 0.0014 | M23: 0.0023 | N23: 0.0035 | O23: 0.0047 | P23: 0.0062 | Q23: 0.0079 | R23: 0.0093 | S23: 0.0108 | T23: 0.0124
A24: 0.65 | B24: 0.799999 | C24: Ca2/CC | D24: 0.126101 | J24: BBB | K24: 0.0016 | L24: 0.0045 | M24: 0.0078 | N24: 0.0117 | O24: 0.0158 | P24: 0.0198 | Q24: 0.0233 | R24: 0.0267 | S24: 0.03 | T24: 0.0332
A25: 0.8 | B25: 1.249999 | C25: Caa/CCC | D25: 0.0885 | J25: BB | K25: 0.0061 | L25: 0.0192 | M25: 0.0348 | N25: 0.0505 | O25: 0.0652 | P25: 0.0785 | Q25: 0.0901 | R25: 0.1004 | S25: 0.1097 | T25: 0.1178
A26: 1.25 | B26: 1.499999 | C26: B3/B- | D26: 0.050899 | J26: B | K26: 0.0333 | L26: 0.0771 | M26: 0.1155 | N26: 0.1458 | O26: 0.1693 | P26: 0.1883 | Q26: 0.2036 | R26: 0.216 | S26: 0.227 | T26: 0.2374
A27: 1.5 | B27: 1.749999 | C27: B2/B | D27: 0.032098 | J27: CCC/C | K27: 0.2708 | L27: 0.3664 | M27: 0.4141 | N27: 0.441 | O27: 0.4619 | P27: 0.4709 | Q27: 0.4826 | R27: 0.4905 | S27: 0.4976 | T27: 0.5038
A28: 1.75 | B28: 1.999999 | C28: B1/B+ | D28: 0.027531
A29: 2 | B29: 2.2499999 | C29: Ba2/BB | D29: 0.018395
A30: 2.25 | B30: 2.49999 | C30: Ba1/BB+ | D30: 0.013828
A31: 2.5 | B31: 2.999999 | C31: Baa2/BBB | D31: 0.011113
A32: 3 | B32: 4.249999 | C32: A3/A- | D32: 0.008872
A33: 4.25 | B33: 5.499999 | C33: A2/A | D33: 0.007751
A34: 5.5 | B34: 6.499999 | C34: A1/A+ | D34: 0.007003
A35: 6.5 | B35: 8.499999 | C35: Aa2/AA | D35: 0.005506
A36: 8.5 | B36: 100000 | C36: Aaa/AAA | D36: 0.004
A38: For smaller and riskier firms
A39: If interest coverage ratio is
A40: greater than | B40: ≤ to | C40: Rating is | D40: Spread is
A41: -100000 | B41: 0.499999 | C41: D2/D | D41: 0.19 | G41: Rating is | H41: Spread is
A42: 0.5 | B42: 0.799999 | C42: C2/C | D42: 0.16 | G42: A1/A+ | H42: 0.007003
A43: 0.8 | B43: 1.249999 | C43: Ca2/CC | D43: 0.126101 | G43: A2/A | H43: 0.007751
A44: 1.25 | B44: 1.499999 | C44: Caa/CCC | D44: 0.0885 | G44: A3/A- | H44: 0.008872
...

Sheet R& D converter
A1: R & D Converter
A2: This spreadsheet converts R&D expenses from operating to capital expenses. It makes the appropriate adjustments to operating income, net
A3: income, the book value of assets and the book value of equity.
A5: Inputs
A6: Over how many years do you want to amortize R&D expenses | F6: 3 | G6: ! If in doubt, use the lookup table below
A7: Enter the current year's R&D expense = | F7: 85622 | G7: The maximum allowed is ten years
A8: Enter R& D expenses for past years: the number of years that you will need to enter will be determined by the amortization period
A9: Do not input numbers in the first column (Year). It will get automatically updated based on the input above.
A10: Year | B10: R& D Expenses
A11: -1 | B11: 73213 | C11: ! Year -1 is the year prior to the most recent 12 months
A12: =IF((0-A11)<$F$6,IF(A11>-1,,A11-1),) -> -2 | B12: 56052 | C12: ! Year -2 is the two years prior to the most recent 12 months
A13: =IF((0-A12)<$F$6,IF(A12>-1,,A12-1),) -> -3 | B13: 42740
A14: =IF((0-A13)<$F$6,IF(A13>-1,,A13-1),) -> 0
A15: =IF((0-A14)<$F$6,IF(A14>-1,,A14-1),) -> 0
A16: =IF((0-A15)<$F$6,IF(A15>-1,,A15-1),) -> 0
A17: =IF((0-A16)<$F$6,IF(A16>-1,,A16-1),) -> 0
A18: =IF((0-A17)<$F$6,IF(A17>-1,,A17-1),) -> 0
A19: =IF((0-A18)<$F$6,IF(A18>-1,,A18-1),) -> 0
A20: =IF((0-A19)<$F$6,IF(A19>-1,,A19-1),) -> 0
A22: Output
A23: Year | B23: R&D Expense | C23: Unamortized portion | E23: Amortization this year
A24: Current | B24: =F7 -> 85622 | C24: =1 -> 1 | D24: =B24*C24 -> 85622
A25: =A11 -> -1 | B25: =B11 -> 73213 | C25: =IF(A25<0,($F$6+A25)/$F$6,0) -> 0.66666667 | D25: =B25*C25 -> 48808.667 | E25: =IF(A25<0,B25/$F$6,0) -> 24404.333
A26: =A12 -> -2 | B26: =B12 -> 56052 | C26: =IF(A26<0,($F$6+A26)/$F$6,0) -> 0.33333333 | D26: =B26*C26 -> 18684 | E26: =IF(A26<0,B26/$F$6,0) -> 18684
A27: =A13 -> -3 | B27: =B13 -> 42740 | C27: =IF(A27<0,($F$6+A27)/$F$6,0) -> 0 | D27: =B27*C27 -> 0 | E27: =IF(A27<0,B27/$F$6,0) -> 14246.667
A28: =A14 -> 0 | B28: =B14 -> 0 | C28: =IF(A28<0,($F$6+A28)/$F$6,0) -> 0 | D28: =B28*C28 -> 0 | E28: =IF(A28<0,B28/$F$6,0) -> 0
A29: =A15 -> 0 | B29: =B15 -> 0 | C29: =IF(A29<0,($F$6+A29)/$F$6,0) -> 0 | D29: =B29*C29 -> 0 | E29: =IF(A29<0,B29/$F$6,0) -> 0
A30: =A16 -> 0 | B30: =B16 -> 0 | C30: =IF(A30<0,($F$6+A30)/$F$6,0) -> 0 | D30: =B30*C30 -> 0 | E30: =IF(A30<0,B30/$F$6,0) -> 0
A31: =A17 -> 0 | B31: =B17 -> 0 | C31: =IF(A31<0,($F$6+A31)/$F$6,0) -> 0 | D31: =B31*C31 -> 0 | E31: =IF(A31<0,B31/$F$6,0) -> 0
A32: =A18 -> 0 | B32: =B18 -> 0 | C32: =IF(A32<0,($F$6+A32)/$F$6,0) -> 0 | D32: =B32*C32 -> 0 | E32: =IF(A32<0,B32/$F$6,0) -> 0
A33: =A19 -> 0 | B33: =B19 -> 0 | C33: =IF(A33<0,($F$6+A33)/$F$6,0) -> 0 | D33: =B33*C33 -> 0 | E33: =IF(A33<0,B33/$F$6,0) -> 0
A34: =A20 -> 0 | B34: =B20 -> 0 | C34: =IF(A34<0,($F$6+A34)/$F$6,0) -> 0 | D34: =B34*C34 -> 0 | E34: =IF(A34<0,B34/$F$6,0) -> 0
A35: Value of Research Asset = | D35: =SUM(D24:D34) -> 153114.67 | E35: =SUM(E25:E34) -> 57335
A37: Amortization of asset for current year = | D37: =E35 -> 57335
A39: Adjustment to Operating Income = | D39: =F7-D37 -> 28287 | E39: ! A positive number indicates an increase in operating income (add to reported EBIT)
A40: Tax Effect of R&D Expensing | D40: =D39*'Input sheet'!B24 -> 5940.27
A42: Lookup Table for Amortizable Lives
A43: Industry Name | B43: Amortization Period
A44: Advertising | B44: 2
A45: Aerospace/Defense | B45: 10
...

Sheet Operating lease converter
A1: Operating Lease Converter
A2: The yellow cells are input cells. Please enter them.
A3: Inputs | H3: Until 2019, this worksheet had to be used for every firm with operating lease commitments, since accountants treated operating lease expenses as operating expenses. In 2019, IFRS and GAAP made the long-overdue change to treat leases as debt, and for firms that follow these standards, the conversion that I am doing on this spreadsheet is being done by accountants, with lease debt and operating income already adjusted. If that is the case, and you showed the lease debt as part of debt in the input page, please do not use this spreadsheet, since you will be double counting.
A4: Operating lease expense in current year = | E4: 295
A5: Operating Lease Commitments (From footnote to financials)
A6: Year | B6: Commitment | C6: ! Year 1 is next year, ….
A7: 1 | B7: 287
A8: 2 | B8: 235
A9: 3 | B9: 194
A10: 4 | B10: 151
A11: 5 | B11: 98
A12: 6 and beyond | B12: 605
A14: Output
A15: Pre-tax Cost of Debt = | C15: ='Cost of capital worksheet'!B37 -> 0.060613 | D15: ! If you do not have a cost of debt, use the synthetic rating estimator
A18: Number of years embedded in yr 6 estimate = | D18: =IF(B12>0,ROUND(B12/AVERAGE(B7:B11),0),0) -> 3 | E18: ! I use the average lease expense over the first five years
E19: to estimate the number of years of expenses in yr 6
A20: Converting Operating Leases into debt
A21: Year | B21: Commitment | C21: Present Value
A22: =A7 -> 1 | B22: =B7 -> 287 | C22: =B22/(1+$C$15)^A22 -> 270.59823
A23: =A8 -> 2 | B23: =B8 -> 235 | C23: =B23/(1+$C$15)^A23 -> 208.90747
A24: =A9 -> 3 | B24: =B9 -> 194 | C24: =B24/(1+$C$15)^A24 -> 162.60388
A25: =A10 -> 4 | B25: =B10 -> 151 | C25: =B25/(1+$C$15)^A25 -> 119.32987
A26: =A11 -> 5 | B26: =B11 -> 98 | C26: =B26/(1+$C$15)^A26 -> 73.019919
A27: =A12 -> 6 and beyond | B27: =IF(B12>0,IF(D18>0,B12/D18,B12),0) -> 201.66667 | C27: =IF(D18>0,(B27*(1-(1+C15)^(-D18))/C15)/(1+$C$15)^5,B27/(1+C15)^6) -> 401.19723 | D27: ! Commitment beyond year 6 converted into an annuity for ten years
A28: Debt Value of leases = | C28: =SUM(C22:C27) -> 1235.6566
A30: Restated Financials
A31: Depreciation on Operating Lease Asset = | F31: =C28/(5+D18) -> 154.45707 | G31: ! I use straight line depreciation
A32: Adjustment to Operating Earnings = | F32: =E4-F31 -> 140.54293 | G32: ! Add this amount to pre-tax operating income
A33: Adjustment to Total Debt outstanding = | F33: =C28 -> 1235.6566 | G33: ! Add this amount to debt
A34: Adjustment to Depreciation = | F34: =C28/(5+D18) -> 154.45707

Sheet Cost of capital worksheet
A1: You can use this spreadsheet to compute your cost of capital. You can either use the built-in data to compute key inputs (beta, equity risk premium, default spread) or enter them directly. If you choose to use the built in ERP data, you can update the ERP numbers to reflect a more current mature market premuum (since the spreadsheet uses the start of the year numbers).
A3: Estimation of Current Cost of Capital | G3: Operating Countries ERP calculator
A4: There are four ways in whch you can estimate your cost of capital. In the first, you can directly input a cost of captial. In the second, you can work through your company's cost of capital inputs in detail, entering business, geogaphical mix and debt, and I will help you estimate a cost of capital. In the third, you can look up the cost of capital for the industry or industries your firm belongs to and in the fourth, you can use a crosssectional distribution of costs of capital for companies at the start of the year to make your estimate. | G4: Country | H4: Revenues | I4: ERP | J4: Weight | K4: Weighted ERP
G5: United States | H5: 193636 | I5: =IF(H5=0,0,VLOOKUP(G5,'Country equity risk premiums'!$A$5:$D$196,4)) -> 0.0446 | J5: =IF(H5>0,H5/$H$18,) -> 0.85880668 | K5: =IF(J5=0,0,I5*J5) -> 0.038302778 | M5: The last two rows in each of country/region risk premium tables is set aside for your input to provide you with flexibility to enter some numbers directly. For instance, assume that you have a company that breaks its revenues down into three countries and then puts the rest into "Rest of the World". You can enter the "Rest of the World" in one of these two rows and enter an equity risk premium for the rest of the world. The easiest way to do that is to go into the country equity risk premium worksheet and change the GDP for the three countries that you have data for to zero and compute the global weighted average ERP for the remaining countries. With the regional worksheet, you can use the last two rows to enter the data for an individual country (usually the domestic country) that might be broken out though the rest of the revenues are broken down by region. You can look up the ERP for the country in the country ERP worksheet.
G6: China | H6: 500 | I6: =IF(H6=0,0,VLOOKUP(G6,'Country equity risk premiums'!$A$5:$D$196,4)) -> 0.0514 | J6: =IF(H6>0,H6/$H$18,) -> 0.0022175801 | K6: =IF(J6=0,0,I6*J6) -> 0.00011398362
I7: =IF(H7=0,0,VLOOKUP(G7,'Country equity risk premiums'!$A$5:$D$196,4)) -> 0 | J7: =IF(H7>0,H7/$H$18,) -> 0 | K7: =IF(J7=0,0,I7*J7) -> 0
I8: =IF(H8=0,0,VLOOKUP(G8,'Country equity risk premiums'!$A$5:$D$196,4)) -> 0 | J8: =IF(H8>0,H8/$H$18,) -> 0 | K8: =IF(J8=0,0,I8*J8) -> 0
I9: =IF(H9=0,0,VLOOKUP(G9,'Country equity risk premiums'!$A$5:$D$196,4)) -> 0 | J9: =IF(H9>0,H9/$H$18,) -> 0 | K9: =IF(J9=0,0,I9*J9) -> 0
I10: =IF(H10=0,0,VLOOKUP(G10,'Country equity risk premiums'!$A$5:$D$196,4)) -> 0 | J10: =IF(H10>0,H10/$H$18,) -> 0 | K10: =IF(J10=0,0,I10*J10) -> 0
A11: Which approach will you be using? | B11: Detailed | I11: =IF(H11=0,0,VLOOKUP(G11,'Country equity risk premiums'!$A$5:$D$196,4)) -> 0 | J11: =IF(H11>0,H11/$H$18,) -> 0 | K11: =IF(J11=0,0,I11*J11) -> 0
A12: If direct input, enter cost of capital to use | B12: 0.09 | I12: =IF(H12=0,0,VLOOKUP(G12,'Country equity risk premiums'!$A$5:$D$196,4)) -> 0 | J12: =IF(H12>0,H12/$H$18,) -> 0 | K12: =IF(J12=0,0,I12*J12) -> 0
A13: Cost of capital based upon approach = | B13: =IF(B11="I will input",B12,IF(B11="Detailed",E62,IF(B11="Industry Average",B67,B72))) -> 0.11061227 | I13: =IF(H13=0,0,VLOOKUP(G13,'Country equity risk premiums'!$A$5:$D$196,4)) -> 0 | J13: =IF(H13>0,H13/$H$18,) -> 0 | K13: =IF(J13=0,0,I13*J13) -> 0
I14: =IF(H14=0,0,VLOOKUP(G14,'Country equity risk premiums'!$A$5:$D$196,4)) -> 0 | J14: =IF(H14>0,H14/$H$18,) -> 0 | K14: =IF(J14=0,0,I14*J14) -> 0
A15: Approach 1: Detailed Cost of Capital | I15: =IF(H15=0,0,VLOOKUP(G15,'Country equity risk premiums'!$A$5:$D$196,4)) -> 0 | J15: =IF(H15>0,H15/$H$18,) -> 0 | K15: =IF(J15=0,0,I15*J15) -> 0
A16: Inputs | G16: Rest of the World | H16: 31335 | I16: 0.0641 | J16: =IF(H16>0,H16/$H$18,) -> 0.13897574 | K16: =IF(J16=0,0,I16*J16) -> 0.0089083452
A17: Equity | J17: =IF(H17>0,H17/$H$18,) -> 0 | K17: =IF(J17=0,0,I17*J17) -> 0
A18: Number of Shares outstanding = | B18: ='Input sheet'!B21 -> 1445.21 | G18: Total | H18: =SUM(H5:H17) -> 225471 | J18: =SUM(J5:J17) -> 1 | K18: =SUM(K5:K17) -> 0.047325107
A19: Current Market Price per share = | B19: ='Input sheet'!B22 -> 62.09 | G19: Operating Regions ERP calculator
G20: Region | H20: Revenues | I20: ERP | J20: Weight | K20: Weighted ERP
A21: Approach for estimating beta | B21: Multibusiness(US) | G21: ='Country equity risk premiums'!A201 -> Africa | H21: 0 | I21: ='Country equity risk premiums'!B201 -> 0.11949308 | J21: =H21/$H$32 -> 0 | K21: =I21*J21 -> 0
A22: If direct input, enter levered beta (or regression beta) | B22: 1.2 | G22: ='Country equity risk premiums'!A202 -> Asia | H22: 6938 | I22: ='Country equity risk premiums'!B202 -> 0.057223236 | J22: =H22/$H$32 -> 0.20229764 | K22: =I22*J22 -> 0.011576126
A23: Unlevered beta = | B23: =IF(B21="Single Business(US)",VLOOKUP('Input sheet'!B8,'Industry Averages(US)'!A2:G95,7),IF(B21="Multibusiness(US)",K48,IF(B21="Single Business(Global)",VLOOKUP('Input sheet'!B9,'Industry Averages (Global)'!A2:G95,7),'Cost of capital worksheet'!K64))) -> 1.2110393 | G23: ='Country equity risk premiums'!A203 -> Australia & New Zealand | H23: 0 | I23: ='Country equity risk premiums'!B203 -> 0.042340822 | J23: =H23/$H$32 -> 0 | K23: =I23*J23 -> 0
A24: Riskfree Rate = | B24: ='Input sheet'!B34 -> 0.0495 | G24: ='Country equity risk premiums'!A204 -> Caribbean | H24: 0 | I24: ='Country equity risk premiums'!B204 -> 0.11717682 | J24: =H24/$H$32 -> 0 | K24: =I24*J24 -> 0
A25: What approach do you want to use to input ERP? | B25: Operating regions | G25: ='Country equity risk premiums'!A205 -> Central and South America | H25: 2446 | I25: ='Country equity risk premiums'!B205 -> 0.084628496 | J25: =H25/$H$32 -> 0.071320271 | K25: =I25*J25 -> 0.0060357272
